Workbook

Sheet 1.1 Produksi Bersih Padi 2025
A1: DATA PRODUKSI PADI TAHUN 2025 | I1: Kab/Kota: | K1: =IF('[1]0.1 Produksi Pangan & Penduduk'!$C$3="","",'[1]0.1 Produksi Pangan & Penduduk'!$C$3)
A2: No. | B2: Nama Kecamatan | C2: Nama Desa/Kelurahan | D2: Kode Desa/Kelurahan Kemendagri | E2: Kode Desa/Kelurahan BPS | F2: Produksi Kotor Padi (ton) | G2: Susut Gabah | K2: Produksi Bersih Ketersediaan Padi (ton) | L2: Konversi Padi Ke Beras | M2: Produksi Beras (ton) | N2: Susut Beras | Q2: Produksi Bersih Beras Konsumsi (ton)
G3: Benih (0,9%) | H3: Pakan (0,44%) | I3: Tercecer (4,92%) | J3: Industri Non Makanan (0.56%) | N3: Pakan (0,17%) | O3: Tercecer (2,5%) | P3: Industri Non Makanan (0.66%)
F4: P | G4: s | H4: f | I4: w | J4: i | K4: Pnet | L4: c | M4: Rnet | N4: fr | O4: wr | P4: Ir | Q4: Rc
A5: =IF('[1]0.1 Produksi Pangan & Penduduk'!A6="","",'[1]0.1 Produksi Pangan & Penduduk'!A6) | B5: =IF('[1]0.1 Produksi Pangan & Penduduk'!B6="","",'[1]0.1 Produksi Pangan & Penduduk'!B6) | C5: =IF('[1]0.1 Produksi Pangan & Penduduk'!F6="","",'[1]0.1 Produksi Pangan & Penduduk'!F6) | D5: =IF('[1]0.1 Produksi Pangan & Penduduk'!D6="","",'[1]0.1 Produksi Pangan & Penduduk'!D6) | E5: =IF('[1]0.1 Produksi Pangan & Penduduk'!E6="","",'[1]0.1 Produksi Pangan & Penduduk'!E6) | F5: =IF(D5="","",VLOOKUP(D5,'[1]0.1 Produksi Pangan & Penduduk'!$D$5:$J$860,7,0)) | G5: =IF(F5="","",F5*0.9%) | H5: =IF(F5="","",F5*0.44%) | I5: =IF(F5="","",F5*4.92%) | J5: =IF(F5="","",F5*0.56%) | K5: =IF(F5="","",F5-(G5+H5+I5+J5)) | L5: =IF(D5="","",VLOOKUP(D5,'[1]0.1 Produksi Pangan & Penduduk'!$D$5:$M$860,10,0)) | M5: =IFERROR(K5*L5,"") | N5: =IF(M5="","",M5*0.17%) | O5: =IF(M5="","",M5*2.5%) | P5: =IF(M5="","",M5*0.66%) | Q5: =IF(M5="","",M5-(N5+O5+P5))
A6: =IF('[1]0.1 Produksi Pangan & Penduduk'!A7="","",'[1]0.1 Produksi Pangan & Penduduk'!A7) | B6: =IF('[1]0.1 Produksi Pangan & Penduduk'!B7="","",'[1]0.1 Produksi Pangan & Penduduk'!B7) | C6: =IF('[1]0.1 Produksi Pangan & Penduduk'!F7="","",'[1]0.1 Produksi Pangan & Penduduk'!F7) | D6: =IF('[1]0.1 Produksi Pangan & Penduduk'!D7="","",'[1]0.1 Produksi Pangan & Penduduk'!D7) | E6: =IF('[1]0.1 Produksi Pangan & Penduduk'!E7="","",'[1]0.1 Produksi Pangan & Penduduk'!E7) | F6: =IF(D6="","",VLOOKUP(D6,'[1]0.1 Produksi Pangan & Penduduk'!$D$5:$J$860,7,0)) | G6: =IF(F6="","",F6*0.9%) | H6: =IF(F6="","",F6*0.44%) | I6: =IF(F6="","",F6*4.92%) | J6: =IF(F6="","",F6*0.56%) | K6: =IF(F6="","",F6-(G6+H6+I6+J6)) | L6: =IF(D6="","",VLOOKUP(D6,'[1]0.1 Produksi Pangan & Penduduk'!$D$5:$M$860,10,0)) | M6: =IFERROR(K6*L6,"") | N6: =IF(M6="","",M6*0.17%) | O6: =IF(M6="","",M6*2.5%) | P6: =IF(M6="","",M6*0.66%) | Q6: =IF(M6="","",M6-(N6+O6+P6))
A7: =IF('[1]0.1 Produksi Pangan & Penduduk'!A8="","",'[1]0.1 Produksi Pangan & Penduduk'!A8) | B7: =IF('[1]0.1 Produksi Pangan & Penduduk'!B8="","",'[1]0.1 Produksi Pangan & Penduduk'!B8) | C7: =IF('[1]0.1 Produksi Pangan & Penduduk'!F8="","",'[1]0.1 Produksi Pangan & Penduduk'!F8) | D7: =IF('[1]0.1 Produksi Pangan & Penduduk'!D8="","",'[1]0.1 Produksi Pangan & Penduduk'!D8) | E7: =IF('[1]0.1 Produksi Pangan & Penduduk'!E8="","",'[1]0.1 Produksi Pangan & Penduduk'!E8) | F7: =IF(D7="","",VLOOKUP(D7,'[1]0.1 Produksi Pangan & Penduduk'!$D$5:$J$860,7,0)) | G7: =IF(F7="","",F7*0.9%) | H7: =IF(F7="","",F7*0.44%) | I7: =IF(F7="","",F7*4.92%) | J7: =IF(F7="","",F7*0.56%) | K7: =IF(F7="","",F7-(G7+H7+I7+J7)) | L7: =IF(D7="","",VLOOKUP(D7,'[1]0.1 Produksi Pangan & Penduduk'!$D$5:$M$860,10,0)) | M7: =IFERROR(K7*L7,"") | N7: =IF(M7="","",M7*0.17%) | O7: =IF(M7="","",M7*2.5%) | P7: =IF(M7="","",M7*0.66%) | Q7: =IF(M7="","",M7-(N7+O7+P7))
A8: =IF('[1]0.1 Produksi Pangan & Penduduk'!A9="","",'[1]0.1 Produksi Pangan & Penduduk'!A9) | B8: =IF('[1]0.1 Produksi Pangan & Penduduk'!B9="","",'[1]0.1 Produksi Pangan & Penduduk'!B9) | C8: =IF('[1]0.1 Produksi Pangan & Penduduk'!F9="","",'[1]0.1 Produksi Pangan & Penduduk'!F9) | D8: =IF('[1]0.1 Produksi Pangan & Penduduk'!D9="","",'[1]0.1 Produksi Pangan & Penduduk'!D9) | E8: =IF('[1]0.1 Produksi Pangan & Penduduk'!E9="","",'[1]0.1 Produksi Pangan & Penduduk'!E9) | F8: =IF(D8="","",VLOOKUP(D8,'[1]0.1 Produksi Pangan & Penduduk'!$D$5:$J$860,7,0)) | G8: =IF(F8="","",F8*0.9%) | H8: =IF(F8="","",F8*0.44%) | I8: =IF(F8="","",F8*4.92%) | J8: =IF(F8="","",F8*0.56%) | K8: =IF(F8="","",F8-(G8+H8+I8+J8)) | L8: =IF(D8="","",VLOOKUP(D8,'[1]0.1 Produksi Pangan & Penduduk'!$D$5:$M$860,10,0)) | M8: =IFERROR(K8*L8,"") | N8: =IF(M8="","",M8*0.17%) | O8: =IF(M8="","",M8*2.5%) | P8: =IF(M8="","",M8*0.66%) | Q8: =IF(M8="","",M8-(N8+O8+P8))
A9: =IF('[1]0.1 Produksi Pangan & Penduduk'!A10="","",'[1]0.1 Produksi Pangan & Penduduk'!A10) | B9: =IF('[1]0.1 Produksi Pangan & Penduduk'!B10="","",'[1]0.1 Produksi Pangan & Penduduk'!B10) | C9: =IF('[1]0.1 Produksi Pangan & Penduduk'!F10="","",'[1]0.1 Produksi Pangan & Penduduk'!F10) | D9: =IF('[1]0.1 Produksi Pangan & Penduduk'!D10="","",'[1]0.1 Produksi Pangan & Penduduk'!D10) | E9: =IF('[1]0.1 Produksi Pangan & Penduduk'!E10="","",'[1]0.1 Produksi Pangan & Penduduk'!E10) | F9: =IF(D9="","",VLOOKUP(D9,'[1]0.1 Produksi Pangan & Penduduk'!$D$5:$J$860,7,0)) | G9: =IF(F9="","",F9*0.9%) | H9: =IF(F9="","",F9*0.44%) | I9: =IF(F9="","",F9*4.92%) | J9: =IF(F9="","",F9*0.56%) | K9: =IF(F9="","",F9-(G9+H9+I9+J9)) | L9: =IF(D9="","",VLOOKUP(D9,'[1]0.1 Produksi Pangan & Penduduk'!$D$5:$M$860,10,0)) | M9: =IFERROR(K9*L9,"") | N9: =IF(M9="","",M9*0.17%) | O9: =IF(M9="","",M9*2.5%) | P9: =IF(M9="","",M9*0.66%) | Q9: =IF(M9="","",M9-(N9+O9+P9))
A10: =IF('[1]0.1 Produksi Pangan & Penduduk'!A11="","",'[1]0.1 Produksi Pangan & Penduduk'!A11) | B10: =IF('[1]0.1 Produksi Pangan & Penduduk'!B11="","",'[1]0.1 Produksi Pangan & Penduduk'!B11) | C10: =IF('[1]0.1 Produksi Pangan & Penduduk'!F11="","",'[1]0.1 Produksi Pangan & Penduduk'!F11) | D10: =IF('[1]0.1 Produksi Pangan & Penduduk'!D11="","",'[1]0.1 Produksi Pangan & Penduduk'!D11) | E10: =IF('[1]0.1 Produksi Pangan & Penduduk'!E11="","",'[1]0.1 Produksi Pangan & Penduduk'!E11) | F10: =IF(D10="","",VLOOKUP(D10,'[1]0.1 Produksi Pangan & Penduduk'!$D$5:$J$860,7,0)) | G10: =IF(F10="","",F10*0.9%) | H10: =IF(F10="","",F10*0.44%) | I10: =IF(F10="","",F10*4.92%) | J10: =IF(F10="","",F10*0.56%) | K10: =IF(F10="","",F10-(G10+H10+I10+J10)) | L10: =IF(D10="","",VLOOKUP(D10,'[1]0.1 Produksi Pangan & Penduduk'!$D$5:$M$860,10,0)) | M10: =IFERROR(K10*L10,"") | N10: =IF(M10="","",M10*0.17%) | O10: =IF(M10="","",M10*2.5%) | P10: =IF(M10="","",M10*0.66%) | Q10: =IF(M10="","",M10-(N10+O10+P10))
A11: =IF('[1]0.1 Produksi Pangan & Penduduk'!A12="","",'[1]0.1 Produksi Pangan & Penduduk'!A12) | B11: =IF('[1]0.1 Produksi Pangan & Penduduk'!B12="","",'[1]0.1 Produksi Pangan & Penduduk'!B12) | C11: =IF('[1]0.1 Produksi Pangan & Penduduk'!F12="","",'[1]0.1 Produksi Pangan & Penduduk'!F12) | D11: =IF('[1]0.1 Produksi Pangan & Penduduk'!D12="","",'[1]0.1 Produksi Pangan & Penduduk'!D12) | E11: =IF('[1]0.1 Produksi Pangan & Penduduk'!E12="","",'[1]0.1 Produksi Pangan & Penduduk'!E12) | F11: =IF(D11="","",VLOOKUP(D11,'[1]0.1 Produksi Pangan & Penduduk'!$D$5:$J$860,7,0)) | G11: =IF(F11="","",F11*0.9%) | H11: =IF(F11="","",F11*0.44%) | I11: =IF(F11="","",F11*4.92%) | J11: =IF(F11="","",F11*0.56%) | K11: =IF(F11="","",F11-(G11+H11+I11+J11)) | L11: =IF(D11="","",VLOOKUP(D11,'[1]0.1 Produksi Pangan & Penduduk'!$D$5:$M$860,10,0)) | M11: =IFERROR(K11*L11,"") | N11: =IF(M11="","",M11*0.17%) | O11: =IF(M11="","",M11*2.5%) | P11: =IF(M11="","",M11*0.66%) | Q11: =IF(M11="","",M11-(N11+O11+P11))
A12: =IF('[1]0.1 Produksi Pangan & Penduduk'!A13="","",'[1]0.1 Produksi Pangan & Penduduk'!A13) | B12: =IF('[1]0.1 Produksi Pangan & Penduduk'!B13="","",'[1]0.1 Produksi Pangan & Penduduk'!B13) | C12: =IF('[1]0.1 Produksi Pangan & Penduduk'!F13="","",'[1]0.1 Produksi Pangan & Penduduk'!F13) | D12: =IF('[1]0.1 Produksi Pangan & Penduduk'!D13="","",'[1]0.1 Produksi Pangan & Penduduk'!D13) | E12: =IF('[1]0.1 Produksi Pangan & Penduduk'!E13="","",'[1]0.1 Produksi Pangan & Penduduk'!E13) | F12: =IF(D12="","",VLOOKUP(D12,'[1]0.1 Produksi Pangan & Penduduk'!$D$5:$J$860,7,0)) | G12: =IF(F12="","",F12*0.9%) | H12: =IF(F12="","",F12*0.44%) | I12: =IF(F12="","",F12*4.92%) | J12: =IF(F12="","",F12*0.56%) | K12: =IF(F12="","",F12-(G12+H12+I12+J12)) | L12: =IF(D12="","",VLOOKUP(D12,'[1]0.1 Produksi Pangan & Penduduk'!$D$5:$M$860,10,0)) | M12: =IFERROR(K12*L12,"") | N12: =IF(M12="","",M12*0.17%) | O12: =IF(M12="","",M12*2.5%) | P12: =IF(M12="","",M12*0.66%) | Q12: =IF(M12="","",M12-(N12+O12+P12))
A13: =IF('[1]0.1 Produksi Pangan & Penduduk'!A14="","",'[1]0.1 Produksi Pangan & Penduduk'!A14) | B13: =IF('[1]0.1 Produksi Pangan & Penduduk'!B14="","",'[1]0.1 Produksi Pangan & Penduduk'!B14) | C13: =IF('[1]0.1 Produksi Pangan & Penduduk'!F14="","",'[1]0.1 Produksi Pangan & Penduduk'!F14) | D13: =IF('[1]0.1 Produksi Pangan & Penduduk'!D14="","",'[1]0.1 Produksi Pangan & Penduduk'!D14) | E13: =IF('[1]0.1 Produksi Pangan & Penduduk'!E14="","",'[1]0.1 Produksi Pangan & Penduduk'!E14) | F13: =IF(D13="","",VLOOKUP(D13,'[1]0.1 Produksi Pangan & Penduduk'!$D$5:$J$860,7,0)) | G13: =IF(F13="","",F13*0.9%) | H13: =IF(F13="","",F13*0.44%) | I13: =IF(F13="","",F13*4.92%) | J13: =IF(F13="","",F13*0.56%) | K13: =IF(F13="","",F13-(G13+H13+I13+J13)) | L13: =IF(D13="","",VLOOKUP(D13,'[1]0.1 Produksi Pangan & Penduduk'!$D$5:$M$860,10,0)) | M13: =IFERROR(K13*L13,"") | N13: =IF(M13="","",M13*0.17%) | O13: =IF(M13="","",M13*2.5%) | P13: =IF(M13="","",M13*0.66%) | Q13: =IF(M13="","",M13-(N13+O13+P13))
A14: =IF('[1]0.1 Produksi Pangan & Penduduk'!A15="","",'[1]0.1 Produksi Pangan & Penduduk'!A15) | B14: =IF('[1]0.1 Produksi Pangan & Penduduk'!B15="","",'[1]0.1 Produksi Pangan & Penduduk'!B15) | C14: =IF('[1]0.1 Produksi Pangan & Penduduk'!F15="","",'[1]0.1 Produksi Pangan & Penduduk'!F15) | D14: =IF('[1]0.1 Produksi Pangan & Penduduk'!D15="","",'[1]0.1 Produksi Pangan & Penduduk'!D15) | E14: =IF('[1]0.1 Produksi Pangan & Penduduk'!E15="","",'[1]0.1 Produksi Pangan & Penduduk'!E15) | F14: =IF(D14="","",VLOOKUP(D14,'[1]0.1 Produksi Pangan & Penduduk'!$D$5:$J$860,7,0)) | G14: =IF(F14="","",F14*0.9%) | H14: =IF(F14="","",F14*0.44%) | I14: =IF(F14="","",F14*4.92%) | J14: =IF(F14="","",F14*0.56%) | K14: =IF(F14="","",F14-(G14+H14+I14+J14)) | L14: =IF(D14="","",VLOOKUP(D14,'[1]0.1 Produksi Pangan & Penduduk'!$D$5:$M$860,10,0)) | M14: =IFERROR(K14*L14,"") | N14: =IF(M14="","",M14*0.17%) | O14: =IF(M14="","",M14*2.5%) | P14: =IF(M14="","",M14*0.66%) | Q14: =IF(M14="","",M14-(N14+O14+P14))
A15: =IF('[1]0.1 Produksi Pangan & Penduduk'!A16="","",'[1]0.1 Produksi Pangan & Penduduk'!A16) | B15: =IF('[1]0.1 Produksi Pangan & Penduduk'!B16="","",'[1]0.1 Produksi Pangan & Penduduk'!B16) | C15: =IF('[1]0.1 Produksi Pangan & Penduduk'!F16="","",'[1]0.1 Produksi Pangan & Penduduk'!F16) | D15: =IF('[1]0.1 Produksi Pangan & Penduduk'!D16="","",'[1]0.1 Produksi Pangan & Penduduk'!D16) | E15: =IF('[1]0.1 Produksi Pangan & Penduduk'!E16="","",'[1]0.1 Produksi Pangan & Penduduk'!E16) | F15: =IF(D15="","",VLOOKUP(D15,'[1]0.1 Produksi Pangan & Penduduk'!$D$5:$J$860,7,0)) | G15: =IF(F15="","",F15*0.9%) | H15: =IF(F15="","",F15*0.44%) | I15: =IF(F15="","",F15*4.92%) | J15: =IF(F15="","",F15*0.56%) | K15: =IF(F15="","",F15-(G15+H15+I15+J15)) | L15: =IF(D15="","",VLOOKUP(D15,'[1]0.1 Produksi Pangan & Penduduk'!$D$5:$M$860,10,0)) | M15: =IFERROR(K15*L15,"") | N15: =IF(M15="","",M15*0.17%) | O15: =IF(M15="","",M15*2.5%) | P15: =IF(M15="","",M15*0.66%) | Q15: =IF(M15="","",M15-(N15+O15+P15))
A16: =IF('[1]0.1 Produksi Pangan & Penduduk'!A17="","",'[1]0.1 Produksi Pangan & Penduduk'!A17) | B16: =IF('[1]0.1 Produksi Pangan & Penduduk'!B17="","",'[1]0.1 Produksi Pangan & Penduduk'!B17) | C16: =IF('[1]0.1 Produksi Pangan & Penduduk'!F17="","",'[1]0.1 Produksi Pangan & Penduduk'!F17) | D16: =IF('[1]0.1 Produksi Pangan & Penduduk'!D17="","",'[1]0.1 Produksi Pangan & Penduduk'!D17) | E16: =IF('[1]0.1 Produksi Pangan & Penduduk'!E17="","",'[1]0.1 Produksi Pangan & Penduduk'!E17) | F16: =IF(D16="","",VLOOKUP(D16,'[1]0.1 Produksi Pangan & Penduduk'!$D$5:$J$860,7,0)) | G16: =IF(F16="","",F16*0.9%) | H16: =IF(F16="","",F16*0.44%) | I16: =IF(F16="","",F16*4.92%) | J16: =IF(F16="","",F16*0.56%) | K16: =IF(F16="","",F16-(G16+H16+I16+J16)) | L16: =IF(D16="","",VLOOKUP(D16,'[1]0.1 Produksi Pangan & Penduduk'!$D$5:$M$860,10,0)) | M16: =IFERROR(K16*L16,"") | N16: =IF(M16="","",M16*0.17%) | O16: =IF(M16="","",M16*2.5%) | P16: =IF(M16="","",M16*0.66%) | Q16: =IF(M16="","",M16-(N16+O16+P16))
... A859: =IF('[1]0.1 Produksi Pangan & Penduduk'!A860="","",'[1]0.1 Produksi Pangan & Penduduk'!A860) | B859: =IF('[1]0.1 Produksi Pangan & Penduduk'!B860="","",'[1]0.1 Produksi Pangan & Penduduk'!B860) | C859: =IF('[1]0.1 Produksi Pangan & Penduduk'!F860="","",'[1]0.1 Produksi Pangan & Penduduk'!F860) | D859: =IF('[1]0.1 Produksi Pangan & Penduduk'!D860="","",'[1]0.1 Produksi Pangan & Penduduk'!D860) | E859: =IF('[1]0.1 Produksi Pangan & Penduduk'!E860="","",'[1]0.1 Produksi Pangan & Penduduk'!E860) | F859: =IF(D859="","",VLOOKUP(D859,'[1]0.1 Produksi Pangan & Penduduk'!$D$5:$J$860,7,0)) | G859: =IF(F859="","",F859*0.9%) | H859: =IF(F859="","",F859*0.44%) | I859: =IF(F859="","",F859*4.92%) | J859: =IF(F859="","",F859*0.56%) | K859: =IF(F859="","",F859-(G859+H859+I859+J859)) | L859: =IF(D859="","",VLOOKUP(D859,'[1]0.1 Produksi Pangan & Penduduk'!$D$5:$M$860,10,0)) | M859: =IFERROR(K859*L859,"") | N859: =IF(M859="","",M859*0.17%) | O859: =IF(M859="","",M859*2.5%) | P859: =IF(M859="","",M859*0.66%) | Q859: =IF(M859="","",M859-(N859+O859+P859))

Sheet 1.2 Produksi Bersih Jagung 2025
A1: DATA PRODUKSI JAGUNG TAHUN 2025 | I1: Kab/Kota: | J1: =IF('[1]0.1 Produksi Pangan & Penduduk'!$C$3="","",'[1]0.1 Produksi Pangan & Penduduk'!$C$3)
A2: No. | B2: Nama Kecamatan | C2: Nama Desa/Kelurahan | D2: Kode Desa/Kelurahan Kemendagri | E2: Kode Desa/Kelurahan BPS | F2: Produksi Jagung (ton) | G2: Produksi Jagung Siap Pakai (73,9252%) (ton) | H2: Susut Jagung | K2: Produksi Bersih jagung | L2: Produksi Bersih Jagung setara Beras (1,017)
H3: Benih (0,345%) | I3: Pakan (78,806%) | J3: Tercecer (4,62%)
F4: P | G4: M | H4: s | I4: f | J4: w | K4: Mnet | L4: Mr
A5: =IF('1.1 Produksi Bersih Padi 2025'!A5="","",'1.1 Produksi Bersih Padi 2025'!A5) | B5: =IF('1.1 Produksi Bersih Padi 2025'!B5="","",'1.1 Produksi Bersih Padi 2025'!B5) | C5: =IF('1.1 Produksi Bersih Padi 2025'!C5="","",'1.1 Produksi Bersih Padi 2025'!C5) | D5: =IF('1.1 Produksi Bersih Padi 2025'!D5="","",'1.1 Produksi Bersih Padi 2025'!D5) | E5: =IF('1.1 Produksi Bersih Padi 2025'!E5="","",'1.1 Produksi Bersih Padi 2025'!E5) | F5: =IF(D5="","",VLOOKUP(D5,'[1]0.1 Produksi Pangan & Penduduk'!$D$5:$S$860,16,0)) | G5: =IF(F5="","",F5*73.9252%) | H5: =IF(G5="","",G5*0.345%) | I5: =IF(G5="","",G5*78.806%) | J5: =IF(G5="","",G5*4.62%) | K5: =IF(G5="","",G5-(H5+I5+J5)) | L5: =IF(K5="","",K5*1.017)
A6: =IF('1.1 Produksi Bersih Padi 2025'!A6="","",'1.1 Produksi Bersih Padi 2025'!A6) | B6: =IF('1.1 Produksi Bersih Padi 2025'!B6="","",'1.1 Produksi Bersih Padi 2025'!B6) | C6: =IF('1.1 Produksi Bersih Padi 2025'!C6="","",'1.1 Produksi Bersih Padi 2025'!C6) | D6: =IF('1.1 Produksi Bersih Padi 2025'!D6="","",'1.1 Produksi Bersih Padi 2025'!D6) | E6: =IF('1.1 Produksi Bersih Padi 2025'!E6="","",'1.1 Produksi Bersih Padi 2025'!E6) | F6: =IF(D6="","",VLOOKUP(D6,'[1]0.1 Produksi Pangan & Penduduk'!$D$5:$S$860,16,0)) | G6: =IF(F6="","",F6*73.9252%) | H6: =IF(G6="","",G6*0.345%) | I6: =IF(G6="","",G6*78.806%) | J6: =IF(G6="","",G6*4.62%) | K6: =IF(G6="","",G6-(H6+I6+J6)) | L6: =IF(K6="","",K6*1.017)
A7: =IF('1.1 Produksi Bersih Padi 2025'!A7="","",'1.1 Produksi Bersih Padi 2025'!A7) | B7: =IF('1.1 Produksi Bersih Padi 2025'!B7="","",'1.1 Produksi Bersih Padi 2025'!B7) | C7: =IF('1.1 Produksi Bersih Padi 2025'!C7="","",'1.1 Produksi Bersih Padi 2025'!C7) | D7: =IF('1.1 Produksi Bersih Padi 2025'!D7="","",'1.1 Produksi Bersih Padi 2025'!D7) | E7: =IF('1.1 Produksi Bersih Padi 2025'!E7="","",'1.1 Produksi Bersih Padi 2025'!E7) | F7: =IF(D7="","",VLOOKUP(D7,'[1]0.1 Produksi Pangan & Penduduk'!$D$5:$S$860,16,0)) | G7: =IF(F7="","",F7*73.9252%) | H7: =IF(G7="","",G7*0.345%) | I7: =IF(G7="","",G7*78.806%) | J7: =IF(G7="","",G7*4.62%) | K7: =IF(G7="","",G7-(H7+I7+J7)) | L7: =IF(K7="","",K7*1.017)
A8: =IF('1.1 Produksi Bersih Padi 2025'!A8="","",'1.1 Produksi Bersih Padi 2025'!A8) | B8: =IF('1.1 Produksi Bersih Padi 2025'!B8="","",'1.1 Produksi Bersih Padi 2025'!B8) | C8: =IF('1.1 Produksi Bersih Padi 2025'!C8="","",'1.1 Produksi Bersih Padi 2025'!C8) | D8: =IF('1.1 Produksi Bersih Padi 2025'!D8="","",'1.1 Produksi Bersih Padi 2025'!D8) | E8: =IF('1.1 Produksi Bersih Padi 2025'!E8="","",'1.1 Produksi Bersih Padi 2025'!E8) | F8: =IF(D8="","",VLOOKUP(D8,'[1]0.1 Produksi Pangan & Penduduk'!$D$5:$S$860,16,0)) | G8: =IF(F8="","",F8*73.9252%) | H8: =IF(G8="","",G8*0.345%) | I8: =IF(G8="","",G8*78.806%) | J8: =IF(G8="","",G8*4.62%) | K8: =IF(G8="","",G8-(H8+I8+J8)) | L8: =IF(K8="","",K8*1.017)
A9: =IF('1.1 Produksi Bersih Padi 2025'!A9="","",'1.1 Produksi Bersih Padi 2025'!A9) | B9: =IF('1.1 Produksi Bersih Padi 2025'!B9="","",'1.1 Produksi Bersih Padi 2025'!B9) | C9: =IF('1.1 Produksi Bersih Padi 2025'!C9="","",'1.1 Produksi Bersih Padi 2025'!C9) | D9: =IF('1.1 Produksi Bersih Padi 2025'!D9="","",'1.1 Produksi Bersih Padi 2025'!D9) | E9: =IF('1.1 Produksi Bersih Padi 2025'!E9="","",'1.1 Produksi Bersih Padi 2025'!E9) | F9: =IF(D9="","",VLOOKUP(D9,'[1]0.1 Produksi Pangan & Penduduk'!$D$5:$S$860,16,0)) | G9: =IF(F9="","",F9*73.9252%) | H9: =IF(G9="","",G9*0.345%) | I9: =IF(G9="","",G9*78.806%) | J9: =IF(G9="","",G9*4.62%) | K9: =IF(G9="","",G9-(H9+I9+J9)) | L9: =IF(K9="","",K9*1.017)
A10: =IF('1.1 Produksi Bersih Padi 2025'!A10="","",'1.1 Produksi Bersih Padi 2025'!A10) | B10: =IF('1.1 Produksi Bersih Padi 2025'!B10="","",'1.1 Produksi Bersih Padi 2025'!B10) | C10: =IF('1.1 Produksi Bersih Padi 2025'!C10="","",'1.1 Produksi Bersih Padi 2025'!C10) | D10: =IF('1.1 Produksi Bersih Padi 2025'!D10="","",'1.1 Produksi Bersih Padi 2025'!D10) | E10: =IF('1.1 Produksi Bersih Padi 2025'!E10="","",'1.1 Produksi Bersih Padi 2025'!E10) | F10: =IF(D10="","",VLOOKUP(D10,'[1]0.1 Produksi Pangan & Penduduk'!$D$5:$S$860,16,0)) | G10: =IF(F10="","",F10*73.9252%) | H10: =IF(G10="","",G10*0.345%) | I10: =IF(G10="","",G10*78.806%) | J10: =IF(G10="","",G10*4.62%) | K10: =IF(G10="","",G10-(H10+I10+J10)) | L10: =IF(K10="","",K10*1.017)
A11: =IF('1.1 Produksi Bersih Padi 2025'!A11="","",'1.1 Produksi Bersih Padi 2025'!A11) | B11: =IF('1.1 Produksi Bersih Padi 2025'!B11="","",'1.1 Produksi Bersih Padi 2025'!B11) | C11: =IF('1.1 Produksi Bersih Padi 2025'!C11="","",'1.1 Produksi Bersih Padi 2025'!C11) | D11: =IF('1.1 Produksi Bersih Padi 2025'!D11="","",'1.1 Produksi Bersih Padi 2025'!D11) | E11: =IF('1.1 Produksi Bersih Padi 2025'!E11="","",'1.1 Produksi Bersih Padi 2025'!E11) | F11: =IF(D11="","",VLOOKUP(D11,'[1]0.1 Produksi Pangan & Penduduk'!$D$5:$S$860,16,0)) | G11: =IF(F11="","",F11*73.9252%) | H11: =IF(G11="","",G11*0.345%) | I11: =IF(G11="","",G11*78.806%) | J11: =IF(G11="","",G11*4.62%) | K11: =IF(G11="","",G11-(H11+I11+J11)) | L11: =IF(K11="","",K11*1.017)
A12: =IF('1.1 Produksi Bersih Padi 2025'!A12="","",'1.1 Produksi Bersih Padi 2025'!A12) | B12: =IF('1.1 Produksi Bersih Padi 2025'!B12="","",'1.1 Produksi Bersih Padi 2025'!B12) | C12: =IF('1.1 Produksi Bersih Padi 2025'!C12="","",'1.1 Produksi Bersih Padi 2025'!C12) | D12: =IF('1.1 Produksi Bersih Padi 2025'!D12="","",'1.1 Produksi Bersih Padi 2025'!D12) | E12: =IF('1.1 Produksi Bersih Padi 2025'!E12="","",'1.1 Produksi Bersih Padi 2025'!E12) | F12: =IF(D12="","",VLOOKUP(D12,'[1]0.1 Produksi Pangan & Penduduk'!$D$5:$S$860,16,0)) | G12: =IF(F12="","",F12*73.9252%) | H12: =IF(G12="","",G12*0.345%) | I12: =IF(G12="","",G12*78.806%) | J12: =IF(G12="","",G12*4.62%) | K12: =IF(G12="","",G12-(H12+I12+J12)) | L12: =IF(K12="","",K12*1.017)
A13: =IF('1.1 Produksi Bersih Padi 2025'!A13="","",'1.1 Produksi Bersih Padi 2025'!A13) | B13: =IF('1.1 Produksi Bersih Padi 2025'!B13="","",'1.1 Produksi Bersih Padi 2025'!B13) | C13: =IF('1.1 Produksi Bersih Padi 2025'!C13="","",'1.1 Produksi Bersih Padi 2025'!C13) | D13: =IF('1.1 Produksi Bersih Padi 2025'!D13="","",'1.1 Produksi Bersih Padi 2025'!D13) | E13: =IF('1.1 Produksi Bersih Padi 2025'!E13="","",'1.1 Produksi Bersih Padi 2025'!E13) | F13: =IF(D13="","",VLOOKUP(D13,'[1]0.1 Produksi Pangan & Penduduk'!$D$5:$S$860,16,0)) | G13: =IF(F13="","",F13*73.9252%) | H13: =IF(G13="","",G13*0.345%) | I13: =IF(G13="","",G13*78.806%) | J13: =IF(G13="","",G13*4.62%) | K13: =IF(G13="","",G13-(H13+I13+J13)) | L13: =IF(K13="","",K13*1.017)
A14: =IF('1.1 Produksi Bersih Padi 2025'!A14="","",'1.1 Produksi Bersih Padi 2025'!A14) | B14: =IF('1.1 Produksi Bersih Padi 2025'!B14="","",'1.1 Produksi Bersih Padi 2025'!B14) | C14: =IF('1.1 Produksi Bersih Padi 2025'!C14="","",'1.1 Produksi Bersih Padi 2025'!C14) | D14: =IF('1.1 Produksi Bersih Padi 2025'!D14="","",'1.1 Produksi Bersih Padi 2025'!D14) | E14: =IF('1.1 Produksi Bersih Padi 2025'!E14="","",'1.1 Produksi Bersih Padi 2025'!E14) | F14: =IF(D14="","",VLOOKUP(D14,'[1]0.1 Produksi Pangan & Penduduk'!$D$5:$S$860,16,0)) | G14: =IF(F14="","",F14*73.9252%) | H14: =IF(G14="","",G14*0.345%) | I14: =IF(G14="","",G14*78.806%) | J14: =IF(G14="","",G14*4.62%) | K14: =IF(G14="","",G14-(H14+I14+J14)) | L14: =IF(K14="","",K14*1.017)
A15: =IF('1.1 Produksi Bersih Padi 2025'!A15="","",'1.1 Produksi Bersih Padi 2025'!A15) | B15: =IF('1.1 Produksi Bersih Padi 2025'!B15="","",'1.1 Produksi Bersih Padi 2025'!B15) | C15: =IF('1.1 Produksi Bersih Padi 2025'!C15="","",'1.1 Produksi Bersih Padi 2025'!C15) | D15: =IF('1.1 Produksi Bersih Padi 2025'!D15="","",'1.1 Produksi Bersih Padi 2025'!D15) | E15: =IF('1.1 Produksi Bersih Padi 2025'!E15="","",'1.1 Produksi Bersih Padi 2025'!E15) | F15: =IF(D15="","",VLOOKUP(D15,'[1]0.1 Produksi Pangan & Penduduk'!$D$5:$S$860,16,0)) | G15: =IF(F15="","",F15*73.9252%) | H15: =IF(G15="","",G15*0.345%) | I15: =IF(G15="","",G15*78.806%) | J15: =IF(G15="","",G15*4.62%) | K15: =IF(G15="","",G15-(H15+I15+J15)) | L15: =IF(K15="","",K15*1.017)
A16: =IF('1.1 Produksi Bersih Padi 2025'!A16="","",'1.1 Produksi Bersih Padi 2025'!A16) | B16: =IF('1.1 Produksi Bersih Padi 2025'!B16="","",'1.1 Produksi Bersih Padi 2025'!B16) | C16: =IF('1.1 Produksi Bersih Padi 2025'!C16="","",'1.1 Produksi Bersih Padi 2025'!C16) | D16: =IF('1.1 Produksi Bersih Padi 2025'!D16="","",'1.1 Produksi Bersih Padi 2025'!D16) | E16: =IF('1.1 Produksi Bersih Padi 2025'!E16="","",'1.1 Produksi Bersih Padi 2025'!E16) | F16: =IF(D16="","",VLOOKUP(D16,'[1]0.1 Produksi Pangan & Penduduk'!$D$5:$S$860,16,0)) | G16: =IF(F16="","",F16*73.9252%) | H16: =IF(G16="","",G16*0.345%) | I16: =IF(G16="","",G16*78.806%) | J16: =IF(G16="","",G16*4.62%) | K16: =IF(G16="","",G16-(H16+I16+J16)) | L16: =IF(K16="","",K16*1.017)
... A859: =IF('1.1 Produksi Bersih Padi 2025'!A859="","",'1.1 Produksi Bersih Padi 2025'!A859) | B859: =IF('1.1 Produksi Bersih Padi 2025'!B859="","",'1.1 Produksi Bersih Padi 2025'!B859) | C859: =IF('1.1 Produksi Bersih Padi 2025'!C859="","",'1.1 Produksi Bersih Padi 2025'!C859) | D859: =IF('1.1 Produksi Bersih Padi 2025'!D859="","",'1.1 Produksi Bersih Padi 2025'!D859) | E859: =IF('1.1 Produksi Bersih Padi 2025'!E859="","",'1.1 Produksi Bersih Padi 2025'!E859) | F859: =IF(D859="","",VLOOKUP(D859,'[1]0.1 Produksi Pangan & Penduduk'!$D$5:$S$860,16,0)) | G859: =IF(F859="","",F859*73.9252%) | H859: =IF(G859="","",G859*0.345%) | I859: =IF(G859="","",G859*78.806%) | J859: =IF(G859="","",G859*4.62%) | K859: =IF(G859="","",G859-(H859+I859+J859)) | L859: =IF(K859="","",K859*1.017)

Sheet 1.3 Prod Bersih Ubi Kayu 2025
A1: DATA PRODUKSI UBI KAYU TAHUN 2025 | I1: Kab/Kota: | J1: =IF('[1]0.1 Produksi Pangan & Penduduk'!$C$3="","",'[1]0.1 Produksi Pangan & Penduduk'!$C$3)
A2: No. | B2: Nama Kecamatan | C2: Nama Desa/Kelurahan | D2: Kode Desa/Kelurahan Kemendagri | E2: Kode Desa/Kelurahan BPS | F2: Produksi Kotor Ubi Kayu (ton) | G2: Susut Ubi Kayu | J2: Produksi Bersih Ubi Kayu | K2: Produksi Bersih Ubi Kayu setara Beras (0,363)
G3: Benih (0 %) | H3: Pakan (0.43%) | I3: Tercecer (4,23%)
F4: C | G4: s | H4: f | I4: w | J4: (Cnet) | K4: (Cr)
A5: =IF('1.1 Produksi Bersih Padi 2025'!A5="","",'1.1 Produksi Bersih Padi 2025'!A5) | B5: =IF('1.1 Produksi Bersih Padi 2025'!B5="","",'1.1 Produksi Bersih Padi 2025'!B5) | C5: =IF('1.1 Produksi Bersih Padi 2025'!C5="","",'1.1 Produksi Bersih Padi 2025'!C5) | D5: =IF('1.1 Produksi Bersih Padi 2025'!D5="","",'1.1 Produksi Bersih Padi 2025'!D5) | E5: =IF('1.1 Produksi Bersih Padi 2025'!E5="","",'1.1 Produksi Bersih Padi 2025'!E5) | F5: =IF(D5="","",VLOOKUP(D5,'[1]0.1 Produksi Pangan & Penduduk'!$D$5:$Y$860,22,0)) | G5: =IF(F5="","",F5*0%) | H5: =IF(F5="","",F5*0.43%) | I5: =IF(F5="","",F5*4.23%) | J5: =IF(F5="","",F5-(G5+H5+I5)) | K5: =IF(J5="","",J5*0.363)
A6: =IF('1.1 Produksi Bersih Padi 2025'!A6="","",'1.1 Produksi Bersih Padi 2025'!A6) | B6: =IF('1.1 Produksi Bersih Padi 2025'!B6="","",'1.1 Produksi Bersih Padi 2025'!B6) | C6: =IF('1.1 Produksi Bersih Padi 2025'!C6="","",'1.1 Produksi Bersih Padi 2025'!C6) | D6: =IF('1.1 Produksi Bersih Padi 2025'!D6="","",'1.1 Produksi Bersih Padi 2025'!D6) | E6: =IF('1.1 Produksi Bersih Padi 2025'!E6="","",'1.1 Produksi Bersih Padi 2025'!E6) | F6: =IF(D6="","",VLOOKUP(D6,'[1]0.1 Produksi Pangan & Penduduk'!$D$5:$Y$860,22,0)) | G6: =IF(F6="","",F6*0%) | H6: =IF(F6="","",F6*0.43%) | I6: =IF(F6="","",F6*4.23%) | J6: =IF(F6="","",F6-(G6+H6+I6)) | K6: =IF(J6="","",J6*0.363)
A7: =IF('1.1 Produksi Bersih Padi 2025'!A7="","",'1.1 Produksi Bersih Padi 2025'!A7) | B7: =IF('1.1 Produksi Bersih Padi 2025'!B7="","",'1.1 Produksi Bersih Padi 2025'!B7) | C7: =IF('1.1 Produksi Bersih Padi 2025'!C7="","",'1.1 Produksi Bersih Padi 2025'!C7) | D7: =IF('1.1 Produksi Bersih Padi 2025'!D7="","",'1.1 Produksi Bersih Padi 2025'!D7) | E7: =IF('1.1 Produksi Bersih Padi 2025'!E7="","",'1.1 Produksi Bersih Padi 2025'!E7) | F7: =IF(D7="","",VLOOKUP(D7,'[1]0.1 Produksi Pangan & Penduduk'!$D$5:$Y$860,22,0)) | G7: =IF(F7="","",F7*0%) | H7: =IF(F7="","",F7*0.43%) | I7: =IF(F7="","",F7*4.23%) | J7: =IF(F7="","",F7-(G7+H7+I7)) | K7: =IF(J7="","",J7*0.363)
A8: =IF('1.1 Produksi Bersih Padi 2025'!A8="","",'1.1 Produksi Bersih Padi 2025'!A8) | B8: =IF('1.1 Produksi Bersih Padi 2025'!B8="","",'1.1 Produksi Bersih Padi 2025'!B8) | C8: =IF('1.1 Produksi Bersih Padi 2025'!C8="","",'1.1 Produksi Bersih Padi 2025'!C8) | D8: =IF('1.1 Produksi Bersih Padi 2025'!D8="","",'1.1 Produksi Bersih Padi 2025'!D8) | E8: =IF('1.1 Produksi Bersih Padi 2025'!E8="","",'1.1 Produksi Bersih Padi 2025'!E8) | F8: =IF(D8="","",VLOOKUP(D8,'[1]0.1 Produksi Pangan & Penduduk'!$D$5:$Y$860,22,0)) | G8: =IF(F8="","",F8*0%) | H8: =IF(F8="","",F8*0.43%) | I8: =IF(F8="","",F8*4.23%) | J8: =IF(F8="","",F8-(G8+H8+I8)) | K8: =IF(J8="","",J8*0.363)
A9: =IF('1.1 Produksi Bersih Padi 2025'!A9="","",'1.1 Produksi Bersih Padi 2025'!A9) | B9: =IF('1.1 Produksi Bersih Padi 2025'!B9="","",'1.1 Produksi Bersih Padi 2025'!B9) | C9: =IF('1.1 Produksi Bersih Padi 2025'!C9="","",'1.1 Produksi Bersih Padi 2025'!C9) | D9: =IF('1.1 Produksi Bersih Padi 2025'!D9="","",'1.1 Produksi Bersih Padi 2025'!D9) | E9: =IF('1.1 Produksi Bersih Padi 2025'!E9="","",'1.1 Produksi Bersih Padi 2025'!E9) | F9: =IF(D9="","",VLOOKUP(D9,'[1]0.1 Produksi Pangan & Penduduk'!$D$5:$Y$860,22,0)) | G9: =IF(F9="","",F9*0%) | H9: =IF(F9="","",F9*0.43%) | I9: =IF(F9="","",F9*4.23%) | J9: =IF(F9="","",F9-(G9+H9+I9)) | K9: =IF(J9="","",J9*0.363)
A10: =IF('1.1 Produksi Bersih Padi 2025'!A10="","",'1.1 Produksi Bersih Padi 2025'!A10) | B10: =IF('1.1 Produksi Bersih Padi 2025'!B10="","",'1.1 Produksi Bersih Padi 2025'!B10) | C10: =IF('1.1 Produksi Bersih Padi 2025'!C10="","",'1.1 Produksi Bersih Padi 2025'!C10) | D10: =IF('1.1 Produksi Bersih Padi 2025'!D10="","",'1.1 Produksi Bersih Padi 2025'!D10) | E10: =IF('1.1 Produksi Bersih Padi 2025'!E10="","",'1.1 Produksi Bersih Padi 2025'!E10) | F10: =IF(D10="","",VLOOKUP(D10,'[1]0.1 Produksi Pangan & Penduduk'!$D$5:$Y$860,22,0)) | G10: =IF(F10="","",F10*0%) | H10: =IF(F10="","",F10*0.43%) | I10: =IF(F10="","",F10*4.23%) | J10: =IF(F10="","",F10-(G10+H10+I10)) | K10: =IF(J10="","",J10*0.363)
A11: =IF('1.1 Produksi Bersih Padi 2025'!A11="","",'1.1 Produksi Bersih Padi 2025'!A11) | B11: =IF('1.1 Produksi Bersih Padi 2025'!B11="","",'1.1 Produksi Bersih Padi 2025'!B11) | C11: =IF('1.1 Produksi Bersih Padi 2025'!C11="","",'1.1 Produksi Bersih Padi 2025'!C11) | D11: =IF('1.1 Produksi Bersih Padi 2025'!D11="","",'1.1 Produksi Bersih Padi 2025'!D11) | E11: =IF('1.1 Produksi Bersih Padi 2025'!E11="","",'1.1 Produksi Bersih Padi 2025'!E11) | F11: =IF(D11="","",VLOOKUP(D11,'[1]0.1 Produksi Pangan & Penduduk'!$D$5:$Y$860,22,0)) | G11: =IF(F11="","",F11*0%) | H11: =IF(F11="","",F11*0.43%) | I11: =IF(F11="","",F11*4.23%) | J11: =IF(F11="","",F11-(G11+H11+I11)) | K11: =IF(J11="","",J11*0.363)
A12: =IF('1.1 Produksi Bersih Padi 2025'!A12="","",'1.1 Produksi Bersih Padi 2025'!A12) | B12: =IF('1.1 Produksi Bersih Padi 2025'!B12="","",'1.1 Produksi Bersih Padi 2025'!B12) | C12: =IF('1.1 Produksi Bersih Padi 2025'!C12="","",'1.1 Produksi Bersih Padi 2025'!C12) | D12: =IF('1.1 Produksi Bersih Padi 2025'!D12="","",'1.1 Produksi Bersih Padi 2025'!D12) | E12: =IF('1.1 Produksi Bersih Padi 2025'!E12="","",'1.1 Produksi Bersih Padi 2025'!E12) | F12: =IF(D12="","",VLOOKUP(D12,'[1]0.1 Produksi Pangan & Penduduk'!$D$5:$Y$860,22,0)) | G12: =IF(F12="","",F12*0%) | H12: =IF(F12="","",F12*0.43%) | I12: =IF(F12="","",F12*4.23%) | J12: =IF(F12="","",F12-(G12+H12+I12)) | K12: =IF(J12="","",J12*0.363)
A13: =IF('1.1 Produksi Bersih Padi 2025'!A13="","",'1.1 Produksi Bersih Padi 2025'!A13) | B13: =IF('1.1 Produksi Bersih Padi 2025'!B13="","",'1.1 Produksi Bersih Padi 2025'!B13) | C13: =IF('1.1 Produksi Bersih Padi 2025'!C13="","",'1.1 Produksi Bersih Padi 2025'!C13) | D13: =IF('1.1 Produksi Bersih Padi 2025'!D13="","",'1.1 Produksi Bersih Padi 2025'!D13) | E13: =IF('1.1 Produksi Bersih Padi 2025'!E13="","",'1.1 Produksi Bersih Padi 2025'!E13) | F13: =IF(D13="","",VLOOKUP(D13,'[1]0.1 Produksi Pangan & Penduduk'!$D$5:$Y$860,22,0)) | G13: =IF(F13="","",F13*0%) | H13: =IF(F13="","",F13*0.43%) | I13: =IF(F13="","",F13*4.23%) | J13: =IF(F13="","",F13-(G13+H13+I13)) | K13: =IF(J13="","",J13*0.363)
A14: =IF('1.1 Produksi Bersih Padi 2025'!A14="","",'1.1 Produksi Bersih Padi 2025'!A14) | B14: =IF('1.1 Produksi Bersih Padi 2025'!B14="","",'1.1 Produksi Bersih Padi 2025'!B14) | C14: =IF('1.1 Produksi Bersih Padi 2025'!C14="","",'1.1 Produksi Bersih Padi 2025'!C14) | D14: =IF('1.1 Produksi Bersih Padi 2025'!D14="","",'1.1 Produksi Bersih Padi 2025'!D14) | E14: =IF('1.1 Produksi Bersih Padi 2025'!E14="","",'1.1 Produksi Bersih Padi 2025'!E14) | F14: =IF(D14="","",VLOOKUP(D14,'[1]0.1 Produksi Pangan & Penduduk'!$D$5:$Y$860,22,0)) | G14: =IF(F14="","",F14*0%) | H14: =IF(F14="","",F14*0.43%) | I14: =IF(F14="","",F14*4.23%) | J14: =IF(F14="","",F14-(G14+H14+I14)) | K14: =IF(J14="","",J14*0.363)
A15: =IF('1.1 Produksi Bersih Padi 2025'!A15="","",'1.1 Produksi Bersih Padi 2025'!A15) | B15: =IF('1.1 Produksi Bersih Padi 2025'!B15="","",'1.1 Produksi Bersih Padi 2025'!B15) | C15: =IF('1.1 Produksi Bersih Padi 2025'!C15="","",'1.1 Produksi Bersih Padi 2025'!C15) | D15: =IF('1.1 Produksi Bersih Padi 2025'!D15="","",'1.1 Produksi Bersih Padi 2025'!D15) | E15: =IF('1.1 Produksi Bersih Padi 2025'!E15="","",'1.1 Produksi Bersih Padi 2025'!E15) | F15: =IF(D15="","",VLOOKUP(D15,'[1]0.1 Produksi Pangan & Penduduk'!$D$5:$Y$860,22,0)) | G15: =IF(F15="","",F15*0%) | H15: =IF(F15="","",F15*0.43%) | I15: =IF(F15="","",F15*4.23%) | J15: =IF(F15="","",F15-(G15+H15+I15)) | K15: =IF(J15="","",J15*0.363)
A16: =IF('1.1 Produksi Bersih Padi 2025'!A16="","",'1.1 Produksi Bersih Padi 2025'!A16) | B16: =IF('1.1 Produksi Bersih Padi 2025'!B16="","",'1.1 Produksi Bersih Padi 2025'!B16) | C16: =IF('1.1 Produksi Bersih Padi 2025'!C16="","",'1.1 Produksi Bersih Padi 2025'!C16) | D16: =IF('1.1 Produksi Bersih Padi 2025'!D16="","",'1.1 Produksi Bersih Padi 2025'!D16) | E16: =IF('1.1 Produksi Bersih Padi 2025'!E16="","",'1.1 Produksi Bersih Padi 2025'!E16) | F16: =IF(D16="","",VLOOKUP(D16,'[1]0.1 Produksi Pangan & Penduduk'!$D$5:$Y$860,22,0)) | G16: =IF(F16="","",F16*0%) | H16: =IF(F16="","",F16*0.43%) | I16: =IF(F16="","",F16*4.23%) | J16: =IF(F16="","",F16-(G16+H16+I16)) | K16: =IF(J16="","",J16*0.363)
... A859: =IF('1.1 Produksi Bersih Padi 2025'!A859="","",'1.1 Produksi Bersih Padi 2025'!A859) | B859: =IF('1.1 Produksi Bersih Padi 2025'!B859="","",'1.1 Produksi Bersih Padi 2025'!B859) | C859: =IF('1.1 Produksi Bersih Padi 2025'!C859="","",'1.1 Produksi Bersih Padi 2025'!C859) | D859: =IF('1.1 Produksi Bersih Padi 2025'!D859="","",'1.1 Produksi Bersih Padi 2025'!D859) | E859: =IF('1.1 Produksi Bersih Padi 2025'!E859="","",'1.1 Produksi Bersih Padi 2025'!E859) | F859: =IF(D859="","",VLOOKUP(D859,'[1]0.1 Produksi Pangan & Penduduk'!$D$5:$Y$860,22,0)) | G859: =IF(F859="","",F859*0%) | H859: =IF(F859="","",F859*0.43%) | I859: =IF(F859="","",F859*4.23%) | J859: =IF(F859="","",F859-(G859+H859+I859)) | K859: =IF(J859="","",J859*0.363)

Sheet 1.4 Prod Bersih Ubi Jalar 2025
A1: DATA PRODUKSI UBI JALAR TAHUN 2025 | I1: Kab/Kota: | J1: =IF('[1]0.1 Produksi Pangan & Penduduk'!$C$3="","",'[1]0.1 Produksi Pangan & Penduduk'!$C$3)
A2: No. | B2: Nama Kecamatan | C2: Nama Desa/Kelurahan | D2: Kode Desa/Kelurahan Kemendagri | E2: Kode Desa/Kelurahan BPS | F2: Produksi Kotor Ubi Jalar (ton) | G2: Susut Ubi Jalar | J2: Produksi Bersih Ubi Jalar | K2: Produksi Bersih Ubi Jalar setara Beras (0,259)
G3: Benih (0%) | H3: Pakan (0,77%) | I3: Tercecer (4,9%)
F4: J | G4: s | H4: f | I4: w | J4: (Jnet) | K4: (Jr)
A5: =IF('1.1 Produksi Bersih Padi 2025'!A5="","",'1.1 Produksi Bersih Padi 2025'!A5) | B5: =IF('1.1 Produksi Bersih Padi 2025'!B5="","",'1.1 Produksi Bersih Padi 2025'!B5) | C5: =IF('1.1 Produksi Bersih Padi 2025'!C5="","",'1.1 Produksi Bersih Padi 2025'!C5) | D5: =IF('1.1 Produksi Bersih Padi 2025'!D5="","",'1.1 Produksi Bersih Padi 2025'!D5) | E5: =IF('1.1 Produksi Bersih Padi 2025'!E5="","",'1.1 Produksi Bersih Padi 2025'!E5) | F5: =IF(D5="","",VLOOKUP(D5,'[1]0.1 Produksi Pangan & Penduduk'!$D$5:$AE$860,28,0)) | G5: =IF(F5="","",F5*0%) | H5: =IF(F5="","",F5*0.77%) | I5: =IF(F5="","",F5*4.9%) | J5: =IF(F5="","",F5-(G5+H5+I5)) | K5: =IF(J5="","",J5*0.259)
A6: =IF('1.1 Produksi Bersih Padi 2025'!A6="","",'1.1 Produksi Bersih Padi 2025'!A6) | B6: =IF('1.1 Produksi Bersih Padi 2025'!B6="","",'1.1 Produksi Bersih Padi 2025'!B6) | C6: =IF('1.1 Produksi Bersih Padi 2025'!C6="","",'1.1 Produksi Bersih Padi 2025'!C6) | D6: =IF('1.1 Produksi Bersih Padi 2025'!D6="","",'1.1 Produksi Bersih Padi 2025'!D6) | E6: =IF('1.1 Produksi Bersih Padi 2025'!E6="","",'1.1 Produksi Bersih Padi 2025'!E6) | F6: =IF(D6="","",VLOOKUP(D6,'[1]0.1 Produksi Pangan & Penduduk'!$D$5:$AE$860,28,0)) | G6: =IF(F6="","",F6*0%) | H6: =IF(F6="","",F6*0.77%) | I6: =IF(F6="","",F6*4.9%) | J6: =IF(F6="","",F6-(G6+H6+I6)) | K6: =IF(J6="","",J6*0.259)
A7: =IF('1.1 Produksi Bersih Padi 2025'!A7="","",'1.1 Produksi Bersih Padi 2025'!A7) | B7: =IF('1.1 Produksi Bersih Padi 2025'!B7="","",'1.1 Produksi Bersih Padi 2025'!B7) | C7: =IF('1.1 Produksi Bersih Padi 2025'!C7="","",'1.1 Produksi Bersih Padi 2025'!C7) | D7: =IF('1.1 Produksi Bersih Padi 2025'!D7="","",'1.1 Produksi Bersih Padi 2025'!D7) | E7: =IF('1.1 Produksi Bersih Padi 2025'!E7="","",'1.1 Produksi Bersih Padi 2025'!E7) | F7: =IF(D7="","",VLOOKUP(D7,'[1]0.1 Produksi Pangan & Penduduk'!$D$5:$AE$860,28,0)) | G7: =IF(F7="","",F7*0%) | H7: =IF(F7="","",F7*0.77%) | I7: =IF(F7="","",F7*4.9%) | J7: =IF(F7="","",F7-(G7+H7+I7)) | K7: =IF(J7="","",J7*0.259)
A8: =IF('1.1 Produksi Bersih Padi 2025'!A8="","",'1.1 Produksi Bersih Padi 2025'!A8) | B8: =IF('1.1 Produksi Bersih Padi 2025'!B8="","",'1.1 Produksi Bersih Padi 2025'!B8) | C8: =IF('1.1 Produksi Bersih Padi 2025'!C8="","",'1.1 Produksi Bersih Padi 2025'!C8) | D8: =IF('1.1 Produksi Bersih Padi 2025'!D8="","",'1.1 Produksi Bersih Padi 2025'!D8) | E8: =IF('1.1 Produksi Bersih Padi 2025'!E8="","",'1.1 Produksi Bersih Padi 2025'!E8) | F8: =IF(D8="","",VLOOKUP(D8,'[1]0.1 Produksi Pangan & Penduduk'!$D$5:$AE$860,28,0)) | G8: =IF(F8="","",F8*0%) | H8: =IF(F8="","",F8*0.77%) | I8: =IF(F8="","",F8*4.9%) | J8: =IF(F8="","",F8-(G8+H8+I8)) | K8: =IF(J8="","",J8*0.259)
A9: =IF('1.1 Produksi Bersih Padi 2025'!A9="","",'1.1 Produksi Bersih Padi 2025'!A9) | B9: =IF('1.1 Produksi Bersih Padi 2025'!B9="","",'1.1 Produksi Bersih Padi 2025'!B9) | C9: =IF('1.1 Produksi Bersih Padi 2025'!C9="","",'1.1 Produksi Bersih Padi 2025'!C9) | D9: =IF('1.1 Produksi Bersih Padi 2025'!D9="","",'1.1 Produksi Bersih Padi 2025'!D9) | E9: =IF('1.1 Produksi Bersih Padi 2025'!E9="","",'1.1 Produksi Bersih Padi 2025'!E9) | F9: =IF(D9="","",VLOOKUP(D9,'[1]0.1 Produksi Pangan & Penduduk'!$D$5:$AE$860,28,0)) | G9: =IF(F9="","",F9*0%) | H9: =IF(F9="","",F9*0.77%) | I9: =IF(F9="","",F9*4.9%) | J9: =IF(F9="","",F9-(G9+H9+I9)) | K9: =IF(J9="","",J9*0.259)
A10: =IF('1.1 Produksi Bersih Padi 2025'!A10="","",'1.1 Produksi Bersih Padi 2025'!A10) | B10: =IF('1.1 Produksi Bersih Padi 2025'!B10="","",'1.1 Produksi Bersih Padi 2025'!B10) | C10: =IF('1.1 Produksi Bersih Padi 2025'!C10="","",'1.1 Produksi Bersih Padi 2025'!C10) | D10: =IF('1.1 Produksi Bersih Padi 2025'!D10="","",'1.1 Produksi Bersih Padi 2025'!D10) | E10: =IF('1.1 Produksi Bersih Padi 2025'!E10="","",'1.1 Produksi Bersih Padi 2025'!E10) | F10: =IF(D10="","",VLOOKUP(D10,'[1]0.1 Produksi Pangan & Penduduk'!$D$5:$AE$860,28,0)) | G10: =IF(F10="","",F10*0%) | H10: =IF(F10="","",F10*0.77%) | I10: =IF(F10="","",F10*4.9%) | J10: =IF(F10="","",F10-(G10+H10+I10)) | K10: =IF(J10="","",J10*0.259)
A11: =IF('1.1 Produksi Bersih Padi 2025'!A11="","",'1.1 Produksi Bersih Padi 2025'!A11) | B11: =IF('1.1 Produksi Bersih Padi 2025'!B11="","",'1.1 Produksi Bersih Padi 2025'!B11) | C11: =IF('1.1 Produksi Bersih Padi 2025'!C11="","",'1.1 Produksi Bersih Padi 2025'!C11) | D11: =IF('1.1 Produksi Bersih Padi 2025'!D11="","",'1.1 Produksi Bersih Padi 2025'!D11) | E11: =IF('1.1 Produksi Bersih Padi 2025'!E11="","",'1.1 Produksi Bersih Padi 2025'!E11) | F11: =IF(D11="","",VLOOKUP(D11,'[1]0.1 Produksi Pangan & Penduduk'!$D$5:$AE$860,28,0)) | G11: =IF(F11="","",F11*0%) | H11: =IF(F11="","",F11*0.77%) | I11: =IF(F11="","",F11*4.9%) | J11: =IF(F11="","",F11-(G11+H11+I11)) | K11: =IF(J11="","",J11*0.259)
A12: =IF('1.1 Produksi Bersih Padi 2025'!A12="","",'1.1 Produksi Bersih Padi 2025'!A12) | B12: =IF('1.1 Produksi Bersih Padi 2025'!B12="","",'1.1 Produksi Bersih Padi 2025'!B12) | C12: =IF('1.1 Produksi Bersih Padi 2025'!C12="","",'1.1 Produksi Bersih Padi 2025'!C12) | D12: =IF('1.1 Produksi Bersih Padi 2025'!D12="","",'1.1 Produksi Bersih Padi 2025'!D12) | E12: =IF('1.1 Produksi Bersih Padi 2025'!E12="","",'1.1 Produksi Bersih Padi 2025'!E12) | F12: =IF(D12="","",VLOOKUP(D12,'[1]0.1 Produksi Pangan & Penduduk'!$D$5:$AE$860,28,0)) | G12: =IF(F12="","",F12*0%) | H12: =IF(F12="","",F12*0.77%) | I12: =IF(F12="","",F12*4.9%) | J12: =IF(F12="","",F12-(G12+H12+I12)) | K12: =IF(J12="","",J12*0.259)
A13: =IF('1.1 Produksi Bersih Padi 2025'!A13="","",'1.1 Produksi Bersih Padi 2025'!A13) | B13: =IF('1.1 Produksi Bersih Padi 2025'!B13="","",'1.1 Produksi Bersih Padi 2025'!B13) | C13: =IF('1.1 Produksi Bersih Padi 2025'!C13="","",'1.1 Produksi Bersih Padi 2025'!C13) | D13: =IF('1.1 Produksi Bersih Padi 2025'!D13="","",'1.1 Produksi Bersih Padi 2025'!D13) | E13: =IF('1.1 Produksi Bersih Padi 2025'!E13="","",'1.1 Produksi Bersih Padi 2025'!E13) | F13: =IF(D13="","",VLOOKUP(D13,'[1]0.1 Produksi Pangan & Penduduk'!$D$5:$AE$860,28,0)) | G13: =IF(F13="","",F13*0%) | H13: =IF(F13="","",F13*0.77%) | I13: =IF(F13="","",F13*4.9%) | J13: =IF(F13="","",F13-(G13+H13+I13)) | K13: =IF(J13="","",J13*0.259)
A14: =IF('1.1 Produksi Bersih Padi 2025'!A14="","",'1.1 Produksi Bersih Padi 2025'!A14) | B14: =IF('1.1 Produksi Bersih Padi 2025'!B14="","",'1.1 Produksi Bersih Padi 2025'!B14) | C14: =IF('1.1 Produksi Bersih Padi 2025'!C14="","",'1.1 Produksi Bersih Padi 2025'!C14) | D14: =IF('1.1 Produksi Bersih Padi 2025'!D14="","",'1.1 Produksi Bersih Padi 2025'!D14) | E14: =IF('1.1 Produksi Bersih Padi 2025'!E14="","",'1.1 Produksi Bersih Padi 2025'!E14) | F14: =IF(D14="","",VLOOKUP(D14,'[1]0.1 Produksi Pangan & Penduduk'!$D$5:$AE$860,28,0)) | G14: =IF(F14="","",F14*0%) | H14: =IF(F14="","",F14*0.77%) | I14: =IF(F14="","",F14*4.9%) | J14: =IF(F14="","",F14-(G14+H14+I14)) | K14: =IF(J14="","",J14*0.259)
A15: =IF('1.1 Produksi Bersih Padi 2025'!A15="","",'1.1 Produksi Bersih Padi 2025'!A15) | B15: =IF('1.1 Produksi Bersih Padi 2025'!B15="","",'1.1 Produksi Bersih Padi 2025'!B15) | C15: =IF('1.1 Produksi Bersih Padi 2025'!C15="","",'1.1 Produksi Bersih Padi 2025'!C15) | D15: =IF('1.1 Produksi Bersih Padi 2025'!D15="","",'1.1 Produksi Bersih Padi 2025'!D15) | E15: =IF('1.1 Produksi Bersih Padi 2025'!E15="","",'1.1 Produksi Bersih Padi 2025'!E15) | F15: =IF(D15="","",VLOOKUP(D15,'[1]0.1 Produksi Pangan & Penduduk'!$D$5:$AE$860,28,0)) | G15: =IF(F15="","",F15*0%) | H15: =IF(F15="","",F15*0.77%) | I15: =IF(F15="","",F15*4.9%) | J15: =IF(F15="","",F15-(G15+H15+I15)) | K15: =IF(J15="","",J15*0.259)
A16: =IF('1.1 Produksi Bersih Padi 2025'!A16="","",'1.1 Produksi Bersih Padi 2025'!A16) | B16: =IF('1.1 Produksi Bersih Padi 2025'!B16="","",'1.1 Produksi Bersih Padi 2025'!B16) | C16: =IF('1.1 Produksi Bersih Padi 2025'!C16="","",'1.1 Produksi Bersih Padi 2025'!C16) | D16: =IF('1.1 Produksi Bersih Padi 2025'!D16="","",'1.1 Produksi Bersih Padi 2025'!D16) | E16: =IF('1.1 Produksi Bersih Padi 2025'!E16="","",'1.1 Produksi Bersih Padi 2025'!E16) | F16: =IF(D16="","",VLOOKUP(D16,'[1]0.1 Produksi Pangan & Penduduk'!$D$5:$AE$860,28,0)) | G16: =IF(F16="","",F16*0%) | H16: =IF(F16="","",F16*0.77%) | I16: =IF(F16="","",F16*4.9%) | J16: =IF(F16="","",F16-(G16+H16+I16)) | K16: =IF(J16="","",J16*0.259)
... A859: =IF('1.1 Produksi Bersih Padi 2025'!A859="","",'1.1 Produksi Bersih Padi 2025'!A859) | B859: =IF('1.1 Produksi Bersih Padi 2025'!B859="","",'1.1 Produksi Bersih Padi 2025'!B859) | C859: =IF('1.1 Produksi Bersih Padi 2025'!C859="","",'1.1 Produksi Bersih Padi 2025'!C859) | D859: =IF('1.1 Produksi Bersih Padi 2025'!D859="","",'1.1 Produksi Bersih Padi 2025'!D859) | E859: =IF('1.1 Produksi Bersih Padi 2025'!E859="","",'1.1 Produksi Bersih Padi 2025'!E859) | F859: =IF(D859="","",VLOOKUP(D859,'[1]0.1 Produksi Pangan & Penduduk'!$D$5:$AE$860,28,0)) | G859: =IF(F859="","",F859*0%) | H859: =IF(F859="","",F859*0.77%) | I859: =IF(F859="","",F859*4.9%) | J859: =IF(F859="","",F859-(G859+H859+I859)) | K859: =IF(J859="","",J859*0.259)

Sheet 1.5 Prod Bersih Sagu 2025
A1: DATA PRODUKSI SAGU TAHUN 2025 | I1: Kab/Kota: | J1: =IF('[1]0.1 Produksi Pangan & Penduduk'!$C$3="","",'[1]0.1 Produksi Pangan & Penduduk'!$C$3)
A2: No. | B2: Nama Kecamatan | C2: Nama Desa/Kelurahan | D2: Kode Desa/Kelurahan Kemendagri | E2: Kode Desa/Kelurahan BPS | F2: Produksi Kotor Sagu (ton) | G2: Susut Sagu | J2: Produksi Bersih Sagu | K2: Produksi Bersih Sagu setara Beras (0,640)
G3: Benih (0%) | H3: Pakan (0%) | I3: Tercecer (0,72%)
F4: S | G4: s | H4: f | I4: w | J4: (Snet) | K4: (Sr)
A5: =IF('1.1 Produksi Bersih Padi 2025'!A5="","",'1.1 Produksi Bersih Padi 2025'!A5) | B5: =IF('1.1 Produksi Bersih Padi 2025'!B5="","",'1.1 Produksi Bersih Padi 2025'!B5) | C5: =IF('1.1 Produksi Bersih Padi 2025'!C5="","",'1.1 Produksi Bersih Padi 2025'!C5) | D5: =IF('1.1 Produksi Bersih Padi 2025'!D5="","",'1.1 Produksi Bersih Padi 2025'!D5) | E5: =IF('1.1 Produksi Bersih Padi 2025'!E5="","",'1.1 Produksi Bersih Padi 2025'!E5) | F5: =IF(D5="","",VLOOKUP(D5,'[1]0.1 Produksi Pangan & Penduduk'!$D$5:$AK$860,34,0)) | G5: =IF(F5="","",F5*0%) | H5: =IF(F5="","",F5*0%) | I5: =IF(F5="","",F5*0.72%) | J5: =IF(F5="","",F5-(G5+H5+I5)) | K5: =IF(J5="","",J5*0.64)
A6: =IF('1.1 Produksi Bersih Padi 2025'!A6="","",'1.1 Produksi Bersih Padi 2025'!A6) | B6: =IF('1.1 Produksi Bersih Padi 2025'!B6="","",'1.1 Produksi Bersih Padi 2025'!B6) | C6: =IF('1.1 Produksi Bersih Padi 2025'!C6="","",'1.1 Produksi Bersih Padi 2025'!C6) | D6: =IF('1.1 Produksi Bersih Padi 2025'!D6="","",'1.1 Produksi Bersih Padi 2025'!D6) | E6: =IF('1.1 Produksi Bersih Padi 2025'!E6="","",'1.1 Produksi Bersih Padi 2025'!E6) | F6: =IF(D6="","",VLOOKUP(D6,'[1]0.1 Produksi Pangan & Penduduk'!$D$5:$AK$860,34,0)) | G6: =IF(F6="","",F6*0%) | H6: =IF(F6="","",F6*0%) | I6: =IF(F6="","",F6*0.72%) | J6: =IF(F6="","",F6-(G6+H6+I6)) | K6: =IF(J6="","",J6*0.64)
A7: =IF('1.1 Produksi Bersih Padi 2025'!A7="","",'1.1 Produksi Bersih Padi 2025'!A7) | B7: =IF('1.1 Produksi Bersih Padi 2025'!B7="","",'1.1 Produksi Bersih Padi 2025'!B7) | C7: =IF('1.1 Produksi Bersih Padi 2025'!C7="","",'1.1 Produksi Bersih Padi 2025'!C7) | D7: =IF('1.1 Produksi Bersih Padi 2025'!D7="","",'1.1 Produksi Bersih Padi 2025'!D7) | E7: =IF('1.1 Produksi Bersih Padi 2025'!E7="","",'1.1 Produksi Bersih Padi 2025'!E7) | F7: =IF(D7="","",VLOOKUP(D7,'[1]0.1 Produksi Pangan & Penduduk'!$D$5:$AK$860,34,0)) | G7: =IF(F7="","",F7*0%) | H7: =IF(F7="","",F7*0%) | I7: =IF(F7="","",F7*0.72%) | J7: =IF(F7="","",F7-(G7+H7+I7)) | K7: =IF(J7="","",J7*0.64)
A8: =IF('1.1 Produksi Bersih Padi 2025'!A8="","",'1.1 Produksi Bersih Padi 2025'!A8) | B8: =IF('1.1 Produksi Bersih Padi 2025'!B8="","",'1.1 Produksi Bersih Padi 2025'!B8) | C8: =IF('1.1 Produksi Bersih Padi 2025'!C8="","",'1.1 Produksi Bersih Padi 2025'!C8) | D8: =IF('1.1 Produksi Bersih Padi 2025'!D8="","",'1.1 Produksi Bersih Padi 2025'!D8) | E8: =IF('1.1 Produksi Bersih Padi 2025'!E8="","",'1.1 Produksi Bersih Padi 2025'!E8) | F8: =IF(D8="","",VLOOKUP(D8,'[1]0.1 Produksi Pangan & Penduduk'!$D$5:$AK$860,34,0)) | G8: =IF(F8="","",F8*0%) | H8: =IF(F8="","",F8*0%) | I8: =IF(F8="","",F8*0.72%) | J8: =IF(F8="","",F8-(G8+H8+I8)) | K8: =IF(J8="","",J8*0.64)
A9: =IF('1.1 Produksi Bersih Padi 2025'!A9="","",'1.1 Produksi Bersih Padi 2025'!A9) | B9: =IF('1.1 Produksi Bersih Padi 2025'!B9="","",'1.1 Produksi Bersih Padi 2025'!B9) | C9: =IF('1.1 Produksi Bersih Padi 2025'!C9="","",'1.1 Produksi Bersih Padi 2025'!C9) | D9: =IF('1.1 Produksi Bersih Padi 2025'!D9="","",'1.1 Produksi Bersih Padi 2025'!D9) | E9: =IF('1.1 Produksi Bersih Padi 2025'!E9="","",'1.1 Produksi Bersih Padi 2025'!E9) | F9: =IF(D9="","",VLOOKUP(D9,'[1]0.1 Produksi Pangan & Penduduk'!$D$5:$AK$860,34,0)) | G9: =IF(F9="","",F9*0%) | H9: =IF(F9="","",F9*0%) | I9: =IF(F9="","",F9*0.72%) | J9: =IF(F9="","",F9-(G9+H9+I9)) | K9: =IF(J9="","",J9*0.64)
A10: =IF('1.1 Produksi Bersih Padi 2025'!A10="","",'1.1 Produksi Bersih Padi 2025'!A10) | B10: =IF('1.1 Produksi Bersih Padi 2025'!B10="","",'1.1 Produksi Bersih Padi 2025'!B10) | C10: =IF('1.1 Produksi Bersih Padi 2025'!C10="","",'1.1 Produksi Bersih Padi 2025'!C10) | D10: =IF('1.1 Produksi Bersih Padi 2025'!D10="","",'1.1 Produksi Bersih Padi 2025'!D10) | E10: =IF('1.1 Produksi Bersih Padi 2025'!E10="","",'1.1 Produksi Bersih Padi 2025'!E10) | F10: =IF(D10="","",VLOOKUP(D10,'[1]0.1 Produksi Pangan & Penduduk'!$D$5:$AK$860,34,0)) | G10: =IF(F10="","",F10*0%) | H10: =IF(F10="","",F10*0%) | I10: =IF(F10="","",F10*0.72%) | J10: =IF(F10="","",F10-(G10+H10+I10)) | K10: =IF(J10="","",J10*0.64)
A11: =IF('1.1 Produksi Bersih Padi 2025'!A11="","",'1.1 Produksi Bersih Padi 2025'!A11) | B11: =IF('1.1 Produksi Bersih Padi 2025'!B11="","",'1.1 Produksi Bersih Padi 2025'!B11) | C11: =IF('1.1 Produksi Bersih Padi 2025'!C11="","",'1.1 Produksi Bersih Padi 2025'!C11) | D11: =IF('1.1 Produksi Bersih Padi 2025'!D11="","",'1.1 Produksi Bersih Padi 2025'!D11) | E11: =IF('1.1 Produksi Bersih Padi 2025'!E11="","",'1.1 Produksi Bersih Padi 2025'!E11) | F11: =IF(D11="","",VLOOKUP(D11,'[1]0.1 Produksi Pangan & Penduduk'!$D$5:$AK$860,34,0)) | G11: =IF(F11="","",F11*0%) | H11: =IF(F11="","",F11*0%) | I11: =IF(F11="","",F11*0.72%) | J11: =IF(F11="","",F11-(G11+H11+I11)) | K11: =IF(J11="","",J11*0.64)
A12: =IF('1.1 Produksi Bersih Padi 2025'!A12="","",'1.1 Produksi Bersih Padi 2025'!A12) | B12: =IF('1.1 Produksi Bersih Padi 2025'!B12="","",'1.1 Produksi Bersih Padi 2025'!B12) | C12: =IF('1.1 Produksi Bersih Padi 2025'!C12="","",'1.1 Produksi Bersih Padi 2025'!C12) | D12: =IF('1.1 Produksi Bersih Padi 2025'!D12="","",'1.1 Produksi Bersih Padi 2025'!D12) | E12: =IF('1.1 Produksi Bersih Padi 2025'!E12="","",'1.1 Produksi Bersih Padi 2025'!E12) | F12: =IF(D12="","",VLOOKUP(D12,'[1]0.1 Produksi Pangan & Penduduk'!$D$5:$AK$860,34,0)) | G12: =IF(F12="","",F12*0%) | H12: =IF(F12="","",F12*0%) | I12: =IF(F12="","",F12*0.72%) | J12: =IF(F12="","",F12-(G12+H12+I12)) | K12: =IF(J12="","",J12*0.64)
A13: =IF('1.1 Produksi Bersih Padi 2025'!A13="","",'1.1 Produksi Bersih Padi 2025'!A13) | B13: =IF('1.1 Produksi Bersih Padi 2025'!B13="","",'1.1 Produksi Bersih Padi 2025'!B13) | C13: =IF('1.1 Produksi Bersih Padi 2025'!C13="","",'1.1 Produksi Bersih Padi 2025'!C13) | D13: =IF('1.1 Produksi Bersih Padi 2025'!D13="","",'1.1 Produksi Bersih Padi 2025'!D13) | E13: =IF('1.1 Produksi Bersih Padi 2025'!E13="","",'1.1 Produksi Bersih Padi 2025'!E13) | F13: =IF(D13="","",VLOOKUP(D13,'[1]0.1 Produksi Pangan & Penduduk'!$D$5:$AK$860,34,0)) | G13: =IF(F13="","",F13*0%) | H13: =IF(F13="","",F13*0%) | I13: =IF(F13="","",F13*0.72%) | J13: =IF(F13="","",F13-(G13+H13+I13)) | K13: =IF(J13="","",J13*0.64)
A14: =IF('1.1 Produksi Bersih Padi 2025'!A14="","",'1.1 Produksi Bersih Padi 2025'!A14) | B14: =IF('1.1 Produksi Bersih Padi 2025'!B14="","",'1.1 Produksi Bersih Padi 2025'!B14) | C14: =IF('1.1 Produksi Bersih Padi 2025'!C14="","",'1.1 Produksi Bersih Padi 2025'!C14) | D14: =IF('1.1 Produksi Bersih Padi 2025'!D14="","",'1.1 Produksi Bersih Padi 2025'!D14) | E14: =IF('1.1 Produksi Bersih Padi 2025'!E14="","",'1.1 Produksi Bersih Padi 2025'!E14) | F14: =IF(D14="","",VLOOKUP(D14,'[1]0.1 Produksi Pangan & Penduduk'!$D$5:$AK$860,34,0)) | G14: =IF(F14="","",F14*0%) | H14: =IF(F14="","",F14*0%) | I14: =IF(F14="","",F14*0.72%) | J14: =IF(F14="","",F14-(G14+H14+I14)) | K14: =IF(J14="","",J14*0.64)
A15: =IF('1.1 Produksi Bersih Padi 2025'!A15="","",'1.1 Produksi Bersih Padi 2025'!A15) | B15: =IF('1.1 Produksi Bersih Padi 2025'!B15="","",'1.1 Produksi Bersih Padi 2025'!B15) | C15: =IF('1.1 Produksi Bersih Padi 2025'!C15="","",'1.1 Produksi Bersih Padi 2025'!C15) | D15: =IF('1.1 Produksi Bersih Padi 2025'!D15="","",'1.1 Produksi Bersih Padi 2025'!D15) | E15: =IF('1.1 Produksi Bersih Padi 2025'!E15="","",'1.1 Produksi Bersih Padi 2025'!E15) | F15: =IF(D15="","",VLOOKUP(D15,'[1]0.1 Produksi Pangan & Penduduk'!$D$5:$AK$860,34,0)) | G15: =IF(F15="","",F15*0%) | H15: =IF(F15="","",F15*0%) | I15: =IF(F15="","",F15*0.72%) | J15: =IF(F15="","",F15-(G15+H15+I15)) | K15: =IF(J15="","",J15*0.64)
A16: =IF('1.1 Produksi Bersih Padi 2025'!A16="","",'1.1 Produksi Bersih Padi 2025'!A16) | B16: =IF('1.1 Produksi Bersih Padi 2025'!B16="","",'1.1 Produksi Bersih Padi 2025'!B16) | C16: =IF('1.1 Produksi Bersih Padi 2025'!C16="","",'1.1 Produksi Bersih Padi 2025'!C16) | D16: =IF('1.1 Produksi Bersih Padi 2025'!D16="","",'1.1 Produksi Bersih Padi 2025'!D16) | E16: =IF('1.1 Produksi Bersih Padi 2025'!E16="","",'1.1 Produksi Bersih Padi 2025'!E16) | F16: =IF(D16="","",VLOOKUP(D16,'[1]0.1 Produksi Pangan & Penduduk'!$D$5:$AK$860,34,0)) | G16: =IF(F16="","",F16*0%) | H16: =IF(F16="","",F16*0%) | I16: =IF(F16="","",F16*0.72%) | J16: =IF(F16="","",F16-(G16+H16+I16)) | K16: =IF(J16="","",J16*0.64)
... A859: =IF('1.1 Produksi Bersih Padi 2025'!A859="","",'1.1 Produksi Bersih Padi 2025'!A859) | B859: =IF('1.1 Produksi Bersih Padi 2025'!B859="","",'1.1 Produksi Bersih Padi 2025'!B859) | C859: =IF('1.1 Produksi Bersih Padi 2025'!C859="","",'1.1 Produksi Bersih Padi 2025'!C859) | D859: =IF('1.1 Produksi Bersih Padi 2025'!D859="","",'1.1 Produksi Bersih Padi 2025'!D859) | E859: =IF('1.1 Produksi Bersih Padi 2025'!E859="","",'1.1 Produksi Bersih Padi 2025'!E859) | F859: =IF(D859="","",VLOOKUP(D859,'[1]0.1 Produksi Pangan & Penduduk'!$D$5:$AK$860,34,0)) | G859: =IF(F859="","",F859*0%) | H859: =IF(F859="","",F859*0%) | I859: =IF(F859="","",F859*0.72%) | J859: =IF(F859="","",F859-(G859+H859+I859)) | K859: =IF(J859="","",J859*0.64)

Sheet 1.6 Prod Bersih Pisang 2025
A1: DATA PRODUKSI PISANG TAHUN 2025 | I1: Kab/Kota: | J1: =IF('[1]0.1 Produksi Pangan & Penduduk'!$C$3="","",'[1]0.1 Produksi Pangan & Penduduk'!$C$3)
A2: No. | B2: Nama Kecamatan | C2: Nama Desa/Kelurahan | D2: Kode Desa/Kelurahan Kemendagri | E2: Kode Desa/Kelurahan BPS | F2: Produksi Kotor Pisang (ton) | G2: Susut Pisang | J2: Produksi Bersih Pisang | K2: Produksi Bersih Pisang setara Beras (0,134)
G3: Benih (0%) | H3: Pakan (0%) | I3: Tercecer (1,11%)
F4: B | G4: s | H4: f | I4: w | J4: (Bnet) | K4: (Br)
A5: =IF('1.1 Produksi Bersih Padi 2025'!A5="","",'1.1 Produksi Bersih Padi 2025'!A5) | B5: =IF('1.1 Produksi Bersih Padi 2025'!B5="","",'1.1 Produksi Bersih Padi 2025'!B5) | C5: =IF('1.1 Produksi Bersih Padi 2025'!C5="","",'1.1 Produksi Bersih Padi 2025'!C5) | D5: =IF('1.1 Produksi Bersih Padi 2025'!D5="","",'1.1 Produksi Bersih Padi 2025'!D5) | E5: =IF('1.1 Produksi Bersih Padi 2025'!E5="","",'1.1 Produksi Bersih Padi 2025'!E5) | F5: =IF(D5="","",VLOOKUP(D5,'[1]0.1 Produksi Pangan & Penduduk'!$D$5:$AQ$860,40,0)) | G5: =IF(F5="","",F5*0%) | H5: =IF(F5="","",F5*0%) | I5: =IF(F5="","",F5*1.11%) | J5: =IF(F5="","",F5-(G5+H5+I5)) | K5: =IF(J5="","",J5*0.134)
A6: =IF('1.1 Produksi Bersih Padi 2025'!A6="","",'1.1 Produksi Bersih Padi 2025'!A6) | B6: =IF('1.1 Produksi Bersih Padi 2025'!B6="","",'1.1 Produksi Bersih Padi 2025'!B6) | C6: =IF('1.1 Produksi Bersih Padi 2025'!C6="","",'1.1 Produksi Bersih Padi 2025'!C6) | D6: =IF('1.1 Produksi Bersih Padi 2025'!D6="","",'1.1 Produksi Bersih Padi 2025'!D6) | E6: =IF('1.1 Produksi Bersih Padi 2025'!E6="","",'1.1 Produksi Bersih Padi 2025'!E6) | F6: =IF(D6="","",VLOOKUP(D6,'[1]0.1 Produksi Pangan & Penduduk'!$D$5:$AQ$860,40,0)) | G6: =IF(F6="","",F6*0%) | H6: =IF(F6="","",F6*0%) | I6: =IF(F6="","",F6*1.11%) | J6: =IF(F6="","",F6-(G6+H6+I6)) | K6: =IF(J6="","",J6*0.134)
A7: =IF('1.1 Produksi Bersih Padi 2025'!A7="","",'1.1 Produksi Bersih Padi 2025'!A7) | B7: =IF('1.1 Produksi Bersih Padi 2025'!B7="","",'1.1 Produksi Bersih Padi 2025'!B7) | C7: =IF('1.1 Produksi Bersih Padi 2025'!C7="","",'1.1 Produksi Bersih Padi 2025'!C7) | D7: =IF('1.1 Produksi Bersih Padi 2025'!D7="","",'1.1 Produksi Bersih Padi 2025'!D7) | E7: =IF('1.1 Produksi Bersih Padi 2025'!E7="","",'1.1 Produksi Bersih Padi 2025'!E7) | F7: =IF(D7="","",VLOOKUP(D7,'[1]0.1 Produksi Pangan & Penduduk'!$D$5:$AQ$860,40,0)) | G7: =IF(F7="","",F7*0%) | H7: =IF(F7="","",F7*0%) | I7: =IF(F7="","",F7*1.11%) | J7: =IF(F7="","",F7-(G7+H7+I7)) | K7: =IF(J7="","",J7*0.134)
A8: =IF('1.1 Produksi Bersih Padi 2025'!A8="","",'1.1 Produksi Bersih Padi 2025'!A8) | B8: =IF('1.1 Produksi Bersih Padi 2025'!B8="","",'1.1 Produksi Bersih Padi 2025'!B8) | C8: =IF('1.1 Produksi Bersih Padi 2025'!C8="","",'1.1 Produksi Bersih Padi 2025'!C8) | D8: =IF('1.1 Produksi Bersih Padi 2025'!D8="","",'1.1 Produksi Bersih Padi 2025'!D8) | E8: =IF('1.1 Produksi Bersih Padi 2025'!E8="","",'1.1 Produksi Bersih Padi 2025'!E8) | F8: =IF(D8="","",VLOOKUP(D8,'[1]0.1 Produksi Pangan & Penduduk'!$D$5:$AQ$860,40,0)) | G8: =IF(F8="","",F8*0%) | H8: =IF(F8="","",F8*0%) | I8: =IF(F8="","",F8*1.11%) | J8: =IF(F8="","",F8-(G8+H8+I8)) | K8: =IF(J8="","",J8*0.134)
A9: =IF('1.1 Produksi Bersih Padi 2025'!A9="","",'1.1 Produksi Bersih Padi 2025'!A9) | B9: =IF('1.1 Produksi Bersih Padi 2025'!B9="","",'1.1 Produksi Bersih Padi 2025'!B9) | C9: =IF('1.1 Produksi Bersih Padi 2025'!C9="","",'1.1 Produksi Bersih Padi 2025'!C9) | D9: =IF('1.1 Produksi Bersih Padi 2025'!D9="","",'1.1 Produksi Bersih Padi 2025'!D9) | E9: =IF('1.1 Produksi Bersih Padi 2025'!E9="","",'1.1 Produksi Bersih Padi 2025'!E9) | F9: =IF(D9="","",VLOOKUP(D9,'[1]0.1 Produksi Pangan & Penduduk'!$D$5:$AQ$860,40,0)) | G9: =IF(F9="","",F9*0%) | H9: =IF(F9="","",F9*0%) | I9: =IF(F9="","",F9*1.11%) | J9: =IF(F9="","",F9-(G9+H9+I9)) | K9: =IF(J9="","",J9*0.134)
A10: =IF('1.1 Produksi Bersih Padi 2025'!A10="","",'1.1 Produksi Bersih Padi 2025'!A10) | B10: =IF('1.1 Produksi Bersih Padi 2025'!B10="","",'1.1 Produksi Bersih Padi 2025'!B10) | C10: =IF('1.1 Produksi Bersih Padi 2025'!C10="","",'1.1 Produksi Bersih Padi 2025'!C10) | D10: =IF('1.1 Produksi Bersih Padi 2025'!D10="","",'1.1 Produksi Bersih Padi 2025'!D10) | E10: =IF('1.1 Produksi Bersih Padi 2025'!E10="","",'1.1 Produksi Bersih Padi 2025'!E10) | F10: =IF(D10="","",VLOOKUP(D10,'[1]0.1 Produksi Pangan & Penduduk'!$D$5:$AQ$860,40,0)) | G10: =IF(F10="","",F10*0%) | H10: =IF(F10="","",F10*0%) | I10: =IF(F10="","",F10*1.11%) | J10: =IF(F10="","",F10-(G10+H10+I10)) | K10: =IF(J10="","",J10*0.134)
A11: =IF('1.1 Produksi Bersih Padi 2025'!A11="","",'1.1 Produksi Bersih Padi 2025'!A11) | B11: =IF('1.1 Produksi Bersih Padi 2025'!B11="","",'1.1 Produksi Bersih Padi 2025'!B11) | C11: =IF('1.1 Produksi Bersih Padi 2025'!C11="","",'1.1 Produksi Bersih Padi 2025'!C11) | D11: =IF('1.1 Produksi Bersih Padi 2025'!D11="","",'1.1 Produksi Bersih Padi 2025'!D11) | E11: =IF('1.1 Produksi Bersih Padi 2025'!E11="","",'1.1 Produksi Bersih Padi 2025'!E11) | F11: =IF(D11="","",VLOOKUP(D11,'[1]0.1 Produksi Pangan & Penduduk'!$D$5:$AQ$860,40,0)) | G11: =IF(F11="","",F11*0%) | H11: =IF(F11="","",F11*0%) | I11: =IF(F11="","",F11*1.11%) | J11: =IF(F11="","",F11-(G11+H11+I11)) | K11: =IF(J11="","",J11*0.134)
A12: =IF('1.1 Produksi Bersih Padi 2025'!A12="","",'1.1 Produksi Bersih Padi 2025'!A12) | B12: =IF('1.1 Produksi Bersih Padi 2025'!B12="","",'1.1 Produksi Bersih Padi 2025'!B12) | C12: =IF('1.1 Produksi Bersih Padi 2025'!C12="","",'1.1 Produksi Bersih Padi 2025'!C12) | D12: =IF('1.1 Produksi Bersih Padi 2025'!D12="","",'1.1 Produksi Bersih Padi 2025'!D12) | E12: =IF('1.1 Produksi Bersih Padi 2025'!E12="","",'1.1 Produksi Bersih Padi 2025'!E12) | F12: =IF(D12="","",VLOOKUP(D12,'[1]0.1 Produksi Pangan & Penduduk'!$D$5:$AQ$860,40,0)) | G12: =IF(F12="","",F12*0%) | H12: =IF(F12="","",F12*0%) | I12: =IF(F12="","",F12*1.11%) | J12: =IF(F12="","",F12-(G12+H12+I12)) | K12: =IF(J12="","",J12*0.134)
A13: =IF('1.1 Produksi Bersih Padi 2025'!A13="","",'1.1 Produksi Bersih Padi 2025'!A13) | B13: =IF('1.1 Produksi Bersih Padi 2025'!B13="","",'1.1 Produksi Bersih Padi 2025'!B13) | C13: =IF('1.1 Produksi Bersih Padi 2025'!C13="","",'1.1 Produksi Bersih Padi 2025'!C13) | D13: =IF('1.1 Produksi Bersih Padi 2025'!D13="","",'1.1 Produksi Bersih Padi 2025'!D13) | E13: =IF('1.1 Produksi Bersih Padi 2025'!E13="","",'1.1 Produksi Bersih Padi 2025'!E13) | F13: =IF(D13="","",VLOOKUP(D13,'[1]0.1 Produksi Pangan & Penduduk'!$D$5:$AQ$860,40,0)) | G13: =IF(F13="","",F13*0%) | H13: =IF(F13="","",F13*0%) | I13: =IF(F13="","",F13*1.11%) | J13: =IF(F13="","",F13-(G13+H13+I13)) | K13: =IF(J13="","",J13*0.134)
A14: =IF('1.1 Produksi Bersih Padi 2025'!A14="","",'1.1 Produksi Bersih Padi 2025'!A14) | B14: =IF('1.1 Produksi Bersih Padi 2025'!B14="","",'1.1 Produksi Bersih Padi 2025'!B14) | C14: =IF('1.1 Produksi Bersih Padi 2025'!C14="","",'1.1 Produksi Bersih Padi 2025'!C14) | D14: =IF('1.1 Produksi Bersih Padi 2025'!D14="","",'1.1 Produksi Bersih Padi 2025'!D14) | E14: =IF('1.1 Produksi Bersih Padi 2025'!E14="","",'1.1 Produksi Bersih Padi 2025'!E14) | F14: =IF(D14="","",VLOOKUP(D14,'[1]0.1 Produksi Pangan & Penduduk'!$D$5:$AQ$860,40,0)) | G14: =IF(F14="","",F14*0%) | H14: =IF(F14="","",F14*0%) | I14: =IF(F14="","",F14*1.11%) | J14: =IF(F14="","",F14-(G14+H14+I14)) | K14: =IF(J14="","",J14*0.134)
