Workbook

Sheet 2.1 Data FSVA 2025 & Bobot
A1: Data Indikator FSVA | H1: MIN/MAX | J1: MIN/MAX | L1: MIN/MAX | N1: MIN/MAX | P1: MIN/MAX | R1: MIN/MAX | T1: MIN/MAX | V1: MIN/MAX | X1: MIN/MAX | Z1: MIN/MAX | AB1: MIN/MAX | AD1: MIN/MAX
A2: Food Security and Vulnerability Atlas 2026 | F2: ASPEK | G2: KETERSEDIAAN | O2: KETERJANGKAUAN | U2: PEMANFAATAN
F3: Min | H3: ='2.2 Cut Off Individu & Komposit'!C8 -> 0 | J3: ='2.2 Cut Off Individu & Komposit'!D8 -> 50 | L3: ='2.2 Cut Off Individu & Komposit'!E8 -> 28 | N3: ='2.2 Cut Off Individu & Komposit'!F8 -> 0 | P3: ='2.2 Cut Off Individu & Komposit'!G8 -> 0 | R3: ='2.2 Cut Off Individu & Komposit'!H8 -> 2 | T3: ='2.2 Cut Off Individu & Komposit'!I8 -> 0 | V3: ='2.2 Cut Off Individu & Komposit'!J8 -> 1 | X3: ='2.2 Cut Off Individu & Komposit'!K8 -> 0 | Z3: ='2.2 Cut Off Individu & Komposit'!L8 -> 0 | AB3: ='2.2 Cut Off Individu & Komposit'!M8 -> 40 | AD3: ='2.2 Cut Off Individu & Komposit'!N8 -> 0
F4: Max | H4: ='2.2 Cut Off Individu & Komposit'!C9 -> 10 | J4: ='2.2 Cut Off Individu & Komposit'!D9 -> 120 | L4: ='2.2 Cut Off Individu & Komposit'!E9 -> 120 | N4: ='2.2 Cut Off Individu & Komposit'!F9 -> 3.5 | P4: ='2.2 Cut Off Individu & Komposit'!G9 -> 50 | R4: ='2.2 Cut Off Individu & Komposit'!H9 -> 20 | T4: ='2.2 Cut Off Individu & Komposit'!I9 -> 75 | V4: ='2.2 Cut Off Individu & Komposit'!J9 -> 12 | X4: ='2.2 Cut Off Individu & Komposit'!K9 -> 100 | Z4: ='2.2 Cut Off Individu & Komposit'!L9 -> 100 | AB4: ='2.2 Cut Off Individu & Komposit'!M9 -> 100 | AD4: ='2.2 Cut Off Individu & Komposit'!N9 -> 75
F5: Keterangan Indikator | G5: 1.1 Rasio konsumsi normatif per kapita thd produksi bersih pangan (padi, jagung, ubi kayu, ubi jalar, sagu, pisang) | H5: Adjustment | I5: 1.2 Rasio ketersediaan energi per kapita per hari terhadap standar kebutuhan | J5: Adjustment | K5: 1.3 Rasio ketersediaan protein hewani per kapita per hari terhadap standar kebutuhan | L5: Adjustment | M5: 1.4 Rasio cadangan pangan per kapita | N5: Adjustment | O5: 2.1 Presentase penduduk dengan tingkat kesejahteraan rendah | P5: Adjustment | Q5: 2.2 Koefisien varian (CV) harga (beras medium, daging ayam ras, telur ayam, dan minyak goreng) | R5: Adjustment | S5: 2.3 Prevalence of Undernourishment (PoU)/Prevalensi Ketidakcukupan Konsumsi Pangan | T5: Adjustment | U5: 3.1 Rata-rata Lama Sekolah Perempuan Umur 15 Tahun ke Atas | V5: Adjustment | W5: 3.2 Presentase RT Tanpa Akses ke Air Bersih | X5: Adjustment | Y5: 3.3 Persentase keamanan pangan (segar & siap saji) yang memenuhi standar terhadap total sampel | Z5: Adjustment | AA5: 3.4 Skor Pola Pangan Harapan (PPH) | AB5: Adjustment | AC5: 3.5 Presentase balita dengan tinggi badan di bawah standar (Stunting) | AD5: Adjustment
A6: No. | B6: Nama Kabupaten/Kota | C6: Kode Kab/Kota | D6: Kode Kec Kemendagri | E6: Kode Kec BPS | F6: Nama Kecamatan | G6: 1. NCPR | H6: 1. NCPR | I6: 2. ENERGY | J6: 2. ENERGY | K6: 3. ANIMAL PROTEIN | L6: 3. ANIMAL PROTEIN | M6: 4. FOOD RESERVES | N6: 4. FOOD RESERVES | O6: 5. POVERTY | P6: 5. POVERTY | Q6: 6. PRICE (CV) | R6: 6. PRICE (CV) | S6: 7. PoU | T6: 7. PoU | U6: 8. FEMALE SCHOOL | V6: 8. FEMALE SCHOOL | W6: 9. NO WATER | X6: 9. NO WATER | Y6: 10. FOOD SAFETY | Z6: 10. FOOD SAFETY | AA6: 11. PPH | AB6: 11. PPH | AC6: 12. STUNTING | AD6: 12. STUNTING
A7: =IF('[2]1.7 NCPR'!A3="","",'[2]1.7 NCPR'!A3) | B7: =IF('[2]1.7 NCPR'!B3="","",'[2]1.7 NCPR'!B3) | C7: =IF(D7="","",LEFT(D7,5)) | D7: =IF('[2]1.7 NCPR'!D3="","",'[2]1.7 NCPR'!D3) | E7: =IF('[2]1.7 NCPR'!E3="","",'[2]1.7 NCPR'!E3) | F7: =IF('[2]1.7 NCPR'!C3="","",'[2]1.7 NCPR'!C3) | G7: =IF(D7="","",IF('[2]1.7 NCPR'!P3="","",(VLOOKUP(D7,'[2]1.7 NCPR'!$D:$P,13,0)))) | H7: =IF(G7="","",IF(G7="-",H$4,IF(G7>=H$4,H$4,IF(G7<H$3,H$3,G7)))) | I7: =IF(D7="","",IF('[1]0.2 Konsumsi Energi'!O6="","",VLOOKUP(D7,'[1]0.2 Konsumsi Energi'!$D$5:$S$704,12,0))) | J7: =IF(I7="","",IF(I7>J$4,J$4,IF(I7<J$3,J$3,I7))) | K7: =IF(D7="","",IF('[1]0.3 Konsumsi Protein Hewani'!O6="","",VLOOKUP(D7,'[1]0.3 Konsumsi Protein Hewani'!$D$5:$S$704,12,0))) | L7: =IF(K7="","",IF(K7>L$4,L$4,IF(K7<L$3,L$3,K7))) | M7: =IF(D7="","",IF('[1]0.4 Stok_Cadangan'!AN6="","",VLOOKUP(D7,'[1]0.4 Stok_Cadangan'!$D$6:$AN$704,37,FALSE))) | N7: =IF(M7="","",IF(M7>N$4,N$4,IF(M7<N$3,N$3,M7))) | O7: =IF(D7="","",IF('[1]0.5 Indikator Keterjangkauan'!J6="","",VLOOKUP(D7,'[1]0.5 Indikator Keterjangkauan'!$D$6:$K$704,7,FALSE))) | P7: =IF(O7="","",IF(O7>P$4,P$4,IF(O7<P$3,P$3,O7))) | Q7: =IF(D7="","",IF('[1]0.5 Indikator Keterjangkauan'!AC6="","",VLOOKUP(D7,'[1]0.5 Indikator Keterjangkauan'!$D$6:$AD$704,26,FALSE))) | R7: =IF(Q7="","",IF(Q7>R$4,R$4,IF(Q7<R$3,R$3,Q7))) | S7: =IF(D7="","",IF('[1]0.5 Indikator Keterjangkauan'!AI6="","",VLOOKUP(D7,'[1]0.5 Indikator Keterjangkauan'!$D$6:$AK$700,32,FALSE))) | T7: =IF(S7="","",IF(S7>T$4,T$4,IF(S7<T$3,T$3,S7))) | U7: =IF(D7="","",IF('[1]0.6 Indikator Pemanfaatan'!J6="","",VLOOKUP(D7,'[1]0.6 Indikator Pemanfaatan'!$D$6:$K$704,7,FALSE))) | V7: =IF(U7="","",IF(U7>V$4,V$4,IF(U7<V$3,V$3,U7))) | W7: =IF(D7="","",IF('[1]0.6 Indikator Pemanfaatan'!P6="","",VLOOKUP(D7,'[1]0.6 Indikator Pemanfaatan'!$D$6:$R$704,13,FALSE))) | X7: =IF(W7="","",IF(W7>X$4,X$4,IF(W7<X$3,X$3,W7))) | Y7: =IF(D7="","",IF('[1]0.6 Indikator Pemanfaatan'!AA6="","",VLOOKUP(D7,'[1]0.6 Indikator Pemanfaatan'!$D$6:$AC$706,24,FALSE))) | Z7: =IF(Y7="","",IF(Y7>Z$4,Z$4,IF(Y7<Z$3,Z$3,Y7))) | AA7: =IF(D7="","",IF('[1]0.6 Indikator Pemanfaatan'!AG6="","",VLOOKUP(D7,'[1]0.6 Indikator Pemanfaatan'!$D$6:$AJ$705,30,FALSE))) | AB7: =IF(AA7="","",IF(AA7>AB$4,AB$4,IF(AA7<AB$3,AB$3,AA7))) | AC7: =IF(D7="","",IF('[1]0.6 Indikator Pemanfaatan'!AM6="","",VLOOKUP(D7,'[1]0.6 Indikator Pemanfaatan'!$D$6:$AP$705,36,FALSE))) | AD7: =IF(AC7="","",IF(AC7>AD$4,AD$4,IF(AC7<AD$3,AD$3,AC7)))
A8: =IF('[2]1.7 NCPR'!A4="","",'[2]1.7 NCPR'!A4) | B8: =IF('[2]1.7 NCPR'!B4="","",'[2]1.7 NCPR'!B4) | C8: =IF(D8="","",LEFT(D8,5)) | D8: =IF('[2]1.7 NCPR'!D4="","",'[2]1.7 NCPR'!D4) | E8: =IF('[2]1.7 NCPR'!E4="","",'[2]1.7 NCPR'!E4) | F8: =IF('[2]1.7 NCPR'!C4="","",'[2]1.7 NCPR'!C4) | G8: =IF(D8="","",IF('[2]1.7 NCPR'!P4="","",(VLOOKUP(D8,'[2]1.7 NCPR'!$D:$P,13,0)))) | H8: =IF(G8="","",IF(G8="-",H$4,IF(G8>=H$4,H$4,IF(G8<H$3,H$3,G8)))) | I8: =IF(D8="","",IF('[1]0.2 Konsumsi Energi'!O7="","",VLOOKUP(D8,'[1]0.2 Konsumsi Energi'!$D$5:$S$704,12,0))) | J8: =IF(I8="","",IF(I8>J$4,J$4,IF(I8<J$3,J$3,I8))) | K8: =IF(D8="","",IF('[1]0.3 Konsumsi Protein Hewani'!O7="","",VLOOKUP(D8,'[1]0.3 Konsumsi Protein Hewani'!$D$5:$S$704,12,0))) | L8: =IF(K8="","",IF(K8>L$4,L$4,IF(K8<L$3,L$3,K8))) | M8: =IF(D8="","",IF('[1]0.4 Stok_Cadangan'!AN7="","",VLOOKUP(D8,'[1]0.4 Stok_Cadangan'!$D$6:$AN$704,37,FALSE))) | N8: =IF(M8="","",IF(M8>N$4,N$4,IF(M8<N$3,N$3,M8))) | O8: =IF(D8="","",IF('[1]0.5 Indikator Keterjangkauan'!J7="","",VLOOKUP(D8,'[1]0.5 Indikator Keterjangkauan'!$D$6:$K$704,7,FALSE))) | P8: =IF(O8="","",IF(O8>P$4,P$4,IF(O8<P$3,P$3,O8))) | Q8: =IF(D8="","",IF('[1]0.5 Indikator Keterjangkauan'!AC7="","",VLOOKUP(D8,'[1]0.5 Indikator Keterjangkauan'!$D$6:$AD$704,26,FALSE))) | R8: =IF(Q8="","",IF(Q8>R$4,R$4,IF(Q8<R$3,R$3,Q8))) | S8: =IF(D8="","",IF('[1]0.5 Indikator Keterjangkauan'!AI7="","",VLOOKUP(D8,'[1]0.5 Indikator Keterjangkauan'!$D$6:$AK$700,32,FALSE))) | T8: =IF(S8="","",IF(S8>T$4,T$4,IF(S8<T$3,T$3,S8))) | U8: =IF(D8="","",IF('[1]0.6 Indikator Pemanfaatan'!J7="","",VLOOKUP(D8,'[1]0.6 Indikator Pemanfaatan'!$D$6:$K$704,7,FALSE))) | V8: =IF(U8="","",IF(U8>V$4,V$4,IF(U8<V$3,V$3,U8))) | W8: =IF(D8="","",IF('[1]0.6 Indikator Pemanfaatan'!P7="","",VLOOKUP(D8,'[1]0.6 Indikator Pemanfaatan'!$D$6:$R$704,13,FALSE))) | X8: =IF(W8="","",IF(W8>X$4,X$4,IF(W8<X$3,X$3,W8))) | Y8: =IF(D8="","",IF('[1]0.6 Indikator Pemanfaatan'!AA7="","",VLOOKUP(D8,'[1]0.6 Indikator Pemanfaatan'!$D$6:$AC$706,24,FALSE))) | Z8: =IF(Y8="","",IF(Y8>Z$4,Z$4,IF(Y8<Z$3,Z$3,Y8))) | AA8: =IF(D8="","",IF('[1]0.6 Indikator Pemanfaatan'!AG7="","",VLOOKUP(D8,'[1]0.6 Indikator Pemanfaatan'!$D$6:$AJ$705,30,FALSE))) | AB8: =IF(AA8="","",IF(AA8>AB$4,AB$4,IF(AA8<AB$3,AB$3,AA8))) | AC8: =IF(D8="","",IF('[1]0.6 Indikator Pemanfaatan'!AM7="","",VLOOKUP(D8,'[1]0.6 Indikator Pemanfaatan'!$D$6:$AP$705,36,FALSE))) | AD8: =IF(AC8="","",IF(AC8>AD$4,AD$4,IF(AC8<AD$3,AD$3,AC8)))
A9: =IF('[2]1.7 NCPR'!A5="","",'[2]1.7 NCPR'!A5) | B9: =IF('[2]1.7 NCPR'!B5="","",'[2]1.7 NCPR'!B5) | C9: =IF(D9="","",LEFT(D9,5)) | D9: =IF('[2]1.7 NCPR'!D5="","",'[2]1.7 NCPR'!D5) | E9: =IF('[2]1.7 NCPR'!E5="","",'[2]1.7 NCPR'!E5) | F9: =IF('[2]1.7 NCPR'!C5="","",'[2]1.7 NCPR'!C5) | G9: =IF(D9="","",IF('[2]1.7 NCPR'!P5="","",(VLOOKUP(D9,'[2]1.7 NCPR'!$D:$P,13,0)))) | H9: =IF(G9="","",IF(G9="-",H$4,IF(G9>=H$4,H$4,IF(G9<H$3,H$3,G9)))) | I9: =IF(D9="","",IF('[1]0.2 Konsumsi Energi'!O8="","",VLOOKUP(D9,'[1]0.2 Konsumsi Energi'!$D$5:$S$704,12,0))) | J9: =IF(I9="","",IF(I9>J$4,J$4,IF(I9<J$3,J$3,I9))) | K9: =IF(D9="","",IF('[1]0.3 Konsumsi Protein Hewani'!O8="","",VLOOKUP(D9,'[1]0.3 Konsumsi Protein Hewani'!$D$5:$S$704,12,0))) | L9: =IF(K9="","",IF(K9>L$4,L$4,IF(K9<L$3,L$3,K9))) | M9: =IF(D9="","",IF('[1]0.4 Stok_Cadangan'!AN8="","",VLOOKUP(D9,'[1]0.4 Stok_Cadangan'!$D$6:$AN$704,37,FALSE))) | N9: =IF(M9="","",IF(M9>N$4,N$4,IF(M9<N$3,N$3,M9))) | O9: =IF(D9="","",IF('[1]0.5 Indikator Keterjangkauan'!J8="","",VLOOKUP(D9,'[1]0.5 Indikator Keterjangkauan'!$D$6:$K$704,7,FALSE))) | P9: =IF(O9="","",IF(O9>P$4,P$4,IF(O9<P$3,P$3,O9))) | Q9: =IF(D9="","",IF('[1]0.5 Indikator Keterjangkauan'!AC8="","",VLOOKUP(D9,'[1]0.5 Indikator Keterjangkauan'!$D$6:$AD$704,26,FALSE))) | R9: =IF(Q9="","",IF(Q9>R$4,R$4,IF(Q9<R$3,R$3,Q9))) | S9: =IF(D9="","",IF('[1]0.5 Indikator Keterjangkauan'!AI8="","",VLOOKUP(D9,'[1]0.5 Indikator Keterjangkauan'!$D$6:$AK$700,32,FALSE))) | T9: =IF(S9="","",IF(S9>T$4,T$4,IF(S9<T$3,T$3,S9))) | U9: =IF(D9="","",IF('[1]0.6 Indikator Pemanfaatan'!J8="","",VLOOKUP(D9,'[1]0.6 Indikator Pemanfaatan'!$D$6:$K$704,7,FALSE))) | V9: =IF(U9="","",IF(U9>V$4,V$4,IF(U9<V$3,V$3,U9))) | W9: =IF(D9="","",IF('[1]0.6 Indikator Pemanfaatan'!P8="","",VLOOKUP(D9,'[1]0.6 Indikator Pemanfaatan'!$D$6:$R$704,13,FALSE))) | X9: =IF(W9="","",IF(W9>X$4,X$4,IF(W9<X$3,X$3,W9))) | Y9: =IF(D9="","",IF('[1]0.6 Indikator Pemanfaatan'!AA8="","",VLOOKUP(D9,'[1]0.6 Indikator Pemanfaatan'!$D$6:$AC$706,24,FALSE))) | Z9: =IF(Y9="","",IF(Y9>Z$4,Z$4,IF(Y9<Z$3,Z$3,Y9))) | AA9: =IF(D9="","",IF('[1]0.6 Indikator Pemanfaatan'!AG8="","",VLOOKUP(D9,'[1]0.6 Indikator Pemanfaatan'!$D$6:$AJ$705,30,FALSE))) | AB9: =IF(AA9="","",IF(AA9>AB$4,AB$4,IF(AA9<AB$3,AB$3,AA9))) | AC9: =IF(D9="","",IF('[1]0.6 Indikator Pemanfaatan'!AM8="","",VLOOKUP(D9,'[1]0.6 Indikator Pemanfaatan'!$D$6:$AP$705,36,FALSE))) | AD9: =IF(AC9="","",IF(AC9>AD$4,AD$4,IF(AC9<AD$3,AD$3,AC9))) | XFB9: Kecamatan di Seluruh Kab
A10: =IF('[2]1.7 NCPR'!A6="","",'[2]1.7 NCPR'!A6) | B10: =IF('[2]1.7 NCPR'!B6="","",'[2]1.7 NCPR'!B6) | C10: =IF(D10="","",LEFT(D10,5)) | D10: =IF('[2]1.7 NCPR'!D6="","",'[2]1.7 NCPR'!D6) | E10: =IF('[2]1.7 NCPR'!E6="","",'[2]1.7 NCPR'!E6) | F10: =IF('[2]1.7 NCPR'!C6="","",'[2]1.7 NCPR'!C6) | G10: =IF(D10="","",IF('[2]1.7 NCPR'!P6="","",(VLOOKUP(D10,'[2]1.7 NCPR'!$D:$P,13,0)))) | H10: =IF(G10="","",IF(G10="-",H$4,IF(G10>=H$4,H$4,IF(G10<H$3,H$3,G10)))) | I10: =IF(D10="","",IF('[1]0.2 Konsumsi Energi'!O9="","",VLOOKUP(D10,'[1]0.2 Konsumsi Energi'!$D$5:$S$704,12,0))) | J10: =IF(I10="","",IF(I10>J$4,J$4,IF(I10<J$3,J$3,I10))) | K10: =IF(D10="","",IF('[1]0.3 Konsumsi Protein Hewani'!O9="","",VLOOKUP(D10,'[1]0.3 Konsumsi Protein Hewani'!$D$5:$S$704,12,0))) | L10: =IF(K10="","",IF(K10>L$4,L$4,IF(K10<L$3,L$3,K10))) | M10: =IF(D10="","",IF('[1]0.4 Stok_Cadangan'!AN9="","",VLOOKUP(D10,'[1]0.4 Stok_Cadangan'!$D$6:$AN$704,37,FALSE))) | N10: =IF(M10="","",IF(M10>N$4,N$4,IF(M10<N$3,N$3,M10))) | O10: =IF(D10="","",IF('[1]0.5 Indikator Keterjangkauan'!J9="","",VLOOKUP(D10,'[1]0.5 Indikator Keterjangkauan'!$D$6:$K$704,7,FALSE))) | P10: =IF(O10="","",IF(O10>P$4,P$4,IF(O10<P$3,P$3,O10))) | Q10: =IF(D10="","",IF('[1]0.5 Indikator Keterjangkauan'!AC9="","",VLOOKUP(D10,'[1]0.5 Indikator Keterjangkauan'!$D$6:$AD$704,26,FALSE))) | R10: =IF(Q10="","",IF(Q10>R$4,R$4,IF(Q10<R$3,R$3,Q10))) | S10: =IF(D10="","",IF('[1]0.5 Indikator Keterjangkauan'!AI9="","",VLOOKUP(D10,'[1]0.5 Indikator Keterjangkauan'!$D$6:$AK$700,32,FALSE))) | T10: =IF(S10="","",IF(S10>T$4,T$4,IF(S10<T$3,T$3,S10))) | U10: =IF(D10="","",IF('[1]0.6 Indikator Pemanfaatan'!J9="","",VLOOKUP(D10,'[1]0.6 Indikator Pemanfaatan'!$D$6:$K$704,7,FALSE))) | V10: =IF(U10="","",IF(U10>V$4,V$4,IF(U10<V$3,V$3,U10))) | W10: =IF(D10="","",IF('[1]0.6 Indikator Pemanfaatan'!P9="","",VLOOKUP(D10,'[1]0.6 Indikator Pemanfaatan'!$D$6:$R$704,13,FALSE))) | X10: =IF(W10="","",IF(W10>X$4,X$4,IF(W10<X$3,X$3,W10))) | Y10: =IF(D10="","",IF('[1]0.6 Indikator Pemanfaatan'!AA9="","",VLOOKUP(D10,'[1]0.6 Indikator Pemanfaatan'!$D$6:$AC$706,24,FALSE))) | Z10: =IF(Y10="","",IF(Y10>Z$4,Z$4,IF(Y10<Z$3,Z$3,Y10))) | AA10: =IF(D10="","",IF('[1]0.6 Indikator Pemanfaatan'!AG9="","",VLOOKUP(D10,'[1]0.6 Indikator Pemanfaatan'!$D$6:$AJ$705,30,FALSE))) | AB10: =IF(AA10="","",IF(AA10>AB$4,AB$4,IF(AA10<AB$3,AB$3,AA10))) | AC10: =IF(D10="","",IF('[1]0.6 Indikator Pemanfaatan'!AM9="","",VLOOKUP(D10,'[1]0.6 Indikator Pemanfaatan'!$D$6:$AP$705,36,FALSE))) | AD10: =IF(AC10="","",IF(AC10>AD$4,AD$4,IF(AC10<AD$3,AD$3,AC10))) | XFB10: Kecamatan di Seluruh Kota
A11: =IF('[2]1.7 NCPR'!A7="","",'[2]1.7 NCPR'!A7) | B11: =IF('[2]1.7 NCPR'!B7="","",'[2]1.7 NCPR'!B7) | C11: =IF(D11="","",LEFT(D11,5)) | D11: =IF('[2]1.7 NCPR'!D7="","",'[2]1.7 NCPR'!D7) | E11: =IF('[2]1.7 NCPR'!E7="","",'[2]1.7 NCPR'!E7) | F11: =IF('[2]1.7 NCPR'!C7="","",'[2]1.7 NCPR'!C7) | G11: =IF(D11="","",IF('[2]1.7 NCPR'!P7="","",(VLOOKUP(D11,'[2]1.7 NCPR'!$D:$P,13,0)))) | H11: =IF(G11="","",IF(G11="-",H$4,IF(G11>=H$4,H$4,IF(G11<H$3,H$3,G11)))) | I11: =IF(D11="","",IF('[1]0.2 Konsumsi Energi'!O10="","",VLOOKUP(D11,'[1]0.2 Konsumsi Energi'!$D$5:$S$704,12,0))) | J11: =IF(I11="","",IF(I11>J$4,J$4,IF(I11<J$3,J$3,I11))) | K11: =IF(D11="","",IF('[1]0.3 Konsumsi Protein Hewani'!O10="","",VLOOKUP(D11,'[1]0.3 Konsumsi Protein Hewani'!$D$5:$S$704,12,0))) | L11: =IF(K11="","",IF(K11>L$4,L$4,IF(K11<L$3,L$3,K11))) | M11: =IF(D11="","",IF('[1]0.4 Stok_Cadangan'!AN10="","",VLOOKUP(D11,'[1]0.4 Stok_Cadangan'!$D$6:$AN$704,37,FALSE))) | N11: =IF(M11="","",IF(M11>N$4,N$4,IF(M11<N$3,N$3,M11))) | O11: =IF(D11="","",IF('[1]0.5 Indikator Keterjangkauan'!J10="","",VLOOKUP(D11,'[1]0.5 Indikator Keterjangkauan'!$D$6:$K$704,7,FALSE))) | P11: =IF(O11="","",IF(O11>P$4,P$4,IF(O11<P$3,P$3,O11))) | Q11: =IF(D11="","",IF('[1]0.5 Indikator Keterjangkauan'!AC10="","",VLOOKUP(D11,'[1]0.5 Indikator Keterjangkauan'!$D$6:$AD$704,26,FALSE))) | R11: =IF(Q11="","",IF(Q11>R$4,R$4,IF(Q11<R$3,R$3,Q11))) | S11: =IF(D11="","",IF('[1]0.5 Indikator Keterjangkauan'!AI10="","",VLOOKUP(D11,'[1]0.5 Indikator Keterjangkauan'!$D$6:$AK$700,32,FALSE))) | T11: =IF(S11="","",IF(S11>T$4,T$4,IF(S11<T$3,T$3,S11))) | U11: =IF(D11="","",IF('[1]0.6 Indikator Pemanfaatan'!J10="","",VLOOKUP(D11,'[1]0.6 Indikator Pemanfaatan'!$D$6:$K$704,7,FALSE))) | V11: =IF(U11="","",IF(U11>V$4,V$4,IF(U11<V$3,V$3,U11))) | W11: =IF(D11="","",IF('[1]0.6 Indikator Pemanfaatan'!P10="","",VLOOKUP(D11,'[1]0.6 Indikator Pemanfaatan'!$D$6:$R$704,13,FALSE))) | X11: =IF(W11="","",IF(W11>X$4,X$4,IF(W11<X$3,X$3,W11))) | Y11: =IF(D11="","",IF('[1]0.6 Indikator Pemanfaatan'!AA10="","",VLOOKUP(D11,'[1]0.6 Indikator Pemanfaatan'!$D$6:$AC$706,24,FALSE))) | Z11: =IF(Y11="","",IF(Y11>Z$4,Z$4,IF(Y11<Z$3,Z$3,Y11))) | AA11: =IF(D11="","",IF('[1]0.6 Indikator Pemanfaatan'!AG10="","",VLOOKUP(D11,'[1]0.6 Indikator Pemanfaatan'!$D$6:$AJ$705,30,FALSE))) | AB11: =IF(AA11="","",IF(AA11>AB$4,AB$4,IF(AA11<AB$3,AB$3,AA11))) | AC11: =IF(D11="","",IF('[1]0.6 Indikator Pemanfaatan'!AM10="","",VLOOKUP(D11,'[1]0.6 Indikator Pemanfaatan'!$D$6:$AP$705,36,FALSE))) | AD11: =IF(AC11="","",IF(AC11>AD$4,AD$4,IF(AC11<AD$3,AD$3,AC11))) | XFB11: Kecamatan di Seluruh Kab & Kota
A12: =IF('[2]1.7 NCPR'!A8="","",'[2]1.7 NCPR'!A8) | B12: =IF('[2]1.7 NCPR'!B8="","",'[2]1.7 NCPR'!B8) | C12: =IF(D12="","",LEFT(D12,5)) | D12: =IF('[2]1.7 NCPR'!D8="","",'[2]1.7 NCPR'!D8) | E12: =IF('[2]1.7 NCPR'!E8="","",'[2]1.7 NCPR'!E8) | F12: =IF('[2]1.7 NCPR'!C8="","",'[2]1.7 NCPR'!C8) | G12: =IF(D12="","",IF('[2]1.7 NCPR'!P8="","",(VLOOKUP(D12,'[2]1.7 NCPR'!$D:$P,13,0)))) | H12: =IF(G12="","",IF(G12="-",H$4,IF(G12>=H$4,H$4,IF(G12<H$3,H$3,G12)))) | I12: =IF(D12="","",IF('[1]0.2 Konsumsi Energi'!O11="","",VLOOKUP(D12,'[1]0.2 Konsumsi Energi'!$D$5:$S$704,12,0))) | J12: =IF(I12="","",IF(I12>J$4,J$4,IF(I12<J$3,J$3,I12))) | K12: =IF(D12="","",IF('[1]0.3 Konsumsi Protein Hewani'!O11="","",VLOOKUP(D12,'[1]0.3 Konsumsi Protein Hewani'!$D$5:$S$704,12,0))) | L12: =IF(K12="","",IF(K12>L$4,L$4,IF(K12<L$3,L$3,K12))) | M12: =IF(D12="","",IF('[1]0.4 Stok_Cadangan'!AN11="","",VLOOKUP(D12,'[1]0.4 Stok_Cadangan'!$D$6:$AN$704,37,FALSE))) | N12: =IF(M12="","",IF(M12>N$4,N$4,IF(M12<N$3,N$3,M12))) | O12: =IF(D12="","",IF('[1]0.5 Indikator Keterjangkauan'!J11="","",VLOOKUP(D12,'[1]0.5 Indikator Keterjangkauan'!$D$6:$K$704,7,FALSE))) | P12: =IF(O12="","",IF(O12>P$4,P$4,IF(O12<P$3,P$3,O12))) | Q12: =IF(D12="","",IF('[1]0.5 Indikator Keterjangkauan'!AC11="","",VLOOKUP(D12,'[1]0.5 Indikator Keterjangkauan'!$D$6:$AD$704,26,FALSE))) | R12: =IF(Q12="","",IF(Q12>R$4,R$4,IF(Q12<R$3,R$3,Q12))) | S12: =IF(D12="","",IF('[1]0.5 Indikator Keterjangkauan'!AI11="","",VLOOKUP(D12,'[1]0.5 Indikator Keterjangkauan'!$D$6:$AK$700,32,FALSE))) | T12: =IF(S12="","",IF(S12>T$4,T$4,IF(S12<T$3,T$3,S12))) | U12: =IF(D12="","",IF('[1]0.6 Indikator Pemanfaatan'!J11="","",VLOOKUP(D12,'[1]0.6 Indikator Pemanfaatan'!$D$6:$K$704,7,FALSE))) | V12: =IF(U12="","",IF(U12>V$4,V$4,IF(U12<V$3,V$3,U12))) | W12: =IF(D12="","",IF('[1]0.6 Indikator Pemanfaatan'!P11="","",VLOOKUP(D12,'[1]0.6 Indikator Pemanfaatan'!$D$6:$R$704,13,FALSE))) | X12: =IF(W12="","",IF(W12>X$4,X$4,IF(W12<X$3,X$3,W12))) | Y12: =IF(D12="","",IF('[1]0.6 Indikator Pemanfaatan'!AA11="","",VLOOKUP(D12,'[1]0.6 Indikator Pemanfaatan'!$D$6:$AC$706,24,FALSE))) | Z12: =IF(Y12="","",IF(Y12>Z$4,Z$4,IF(Y12<Z$3,Z$3,Y12))) | AA12: =IF(D12="","",IF('[1]0.6 Indikator Pemanfaatan'!AG11="","",VLOOKUP(D12,'[1]0.6 Indikator Pemanfaatan'!$D$6:$AJ$705,30,FALSE))) | AB12: =IF(AA12="","",IF(AA12>AB$4,AB$4,IF(AA12<AB$3,AB$3,AA12))) | AC12: =IF(D12="","",IF('[1]0.6 Indikator Pemanfaatan'!AM11="","",VLOOKUP(D12,'[1]0.6 Indikator Pemanfaatan'!$D$6:$AP$705,36,FALSE))) | AD12: =IF(AC12="","",IF(AC12>AD$4,AD$4,IF(AC12<AD$3,AD$3,AC12)))
A13: =IF('[2]1.7 NCPR'!A9="","",'[2]1.7 NCPR'!A9) | B13: =IF('[2]1.7 NCPR'!B9="","",'[2]1.7 NCPR'!B9) | C13: =IF(D13="","",LEFT(D13,5)) | D13: =IF('[2]1.7 NCPR'!D9="","",'[2]1.7 NCPR'!D9) | E13: =IF('[2]1.7 NCPR'!E9="","",'[2]1.7 NCPR'!E9) | F13: =IF('[2]1.7 NCPR'!C9="","",'[2]1.7 NCPR'!C9) | G13: =IF(D13="","",IF('[2]1.7 NCPR'!P9="","",(VLOOKUP(D13,'[2]1.7 NCPR'!$D:$P,13,0)))) | H13: =IF(G13="","",IF(G13="-",H$4,IF(G13>=H$4,H$4,IF(G13<H$3,H$3,G13)))) | I13: =IF(D13="","",IF('[1]0.2 Konsumsi Energi'!O12="","",VLOOKUP(D13,'[1]0.2 Konsumsi Energi'!$D$5:$S$704,12,0))) | J13: =IF(I13="","",IF(I13>J$4,J$4,IF(I13<J$3,J$3,I13))) | K13: =IF(D13="","",IF('[1]0.3 Konsumsi Protein Hewani'!O12="","",VLOOKUP(D13,'[1]0.3 Konsumsi Protein Hewani'!$D$5:$S$704,12,0))) | L13: =IF(K13="","",IF(K13>L$4,L$4,IF(K13<L$3,L$3,K13))) | M13: =IF(D13="","",IF('[1]0.4 Stok_Cadangan'!AN12="","",VLOOKUP(D13,'[1]0.4 Stok_Cadangan'!$D$6:$AN$704,37,FALSE))) | N13: =IF(M13="","",IF(M13>N$4,N$4,IF(M13<N$3,N$3,M13))) | O13: =IF(D13="","",IF('[1]0.5 Indikator Keterjangkauan'!J12="","",VLOOKUP(D13,'[1]0.5 Indikator Keterjangkauan'!$D$6:$K$704,7,FALSE))) | P13: =IF(O13="","",IF(O13>P$4,P$4,IF(O13<P$3,P$3,O13))) | Q13: =IF(D13="","",IF('[1]0.5 Indikator Keterjangkauan'!AC12="","",VLOOKUP(D13,'[1]0.5 Indikator Keterjangkauan'!$D$6:$AD$704,26,FALSE))) | R13: =IF(Q13="","",IF(Q13>R$4,R$4,IF(Q13<R$3,R$3,Q13))) | S13: =IF(D13="","",IF('[1]0.5 Indikator Keterjangkauan'!AI12="","",VLOOKUP(D13,'[1]0.5 Indikator Keterjangkauan'!$D$6:$AK$700,32,FALSE))) | T13: =IF(S13="","",IF(S13>T$4,T$4,IF(S13<T$3,T$3,S13))) | U13: =IF(D13="","",IF('[1]0.6 Indikator Pemanfaatan'!J12="","",VLOOKUP(D13,'[1]0.6 Indikator Pemanfaatan'!$D$6:$K$704,7,FALSE))) | V13: =IF(U13="","",IF(U13>V$4,V$4,IF(U13<V$3,V$3,U13))) | W13: =IF(D13="","",IF('[1]0.6 Indikator Pemanfaatan'!P12="","",VLOOKUP(D13,'[1]0.6 Indikator Pemanfaatan'!$D$6:$R$704,13,FALSE))) | X13: =IF(W13="","",IF(W13>X$4,X$4,IF(W13<X$3,X$3,W13))) | Y13: =IF(D13="","",IF('[1]0.6 Indikator Pemanfaatan'!AA12="","",VLOOKUP(D13,'[1]0.6 Indikator Pemanfaatan'!$D$6:$AC$706,24,FALSE))) | Z13: =IF(Y13="","",IF(Y13>Z$4,Z$4,IF(Y13<Z$3,Z$3,Y13))) | AA13: =IF(D13="","",IF('[1]0.6 Indikator Pemanfaatan'!AG12="","",VLOOKUP(D13,'[1]0.6 Indikator Pemanfaatan'!$D$6:$AJ$705,30,FALSE))) | AB13: =IF(AA13="","",IF(AA13>AB$4,AB$4,IF(AA13<AB$3,AB$3,AA13))) | AC13: =IF(D13="","",IF('[1]0.6 Indikator Pemanfaatan'!AM12="","",VLOOKUP(D13,'[1]0.6 Indikator Pemanfaatan'!$D$6:$AP$705,36,FALSE))) | AD13: =IF(AC13="","",IF(AC13>AD$4,AD$4,IF(AC13<AD$3,AD$3,AC13)))
A14: =IF('[2]1.7 NCPR'!A10="","",'[2]1.7 NCPR'!A10) | B14: =IF('[2]1.7 NCPR'!B10="","",'[2]1.7 NCPR'!B10) | C14: =IF(D14="","",LEFT(D14,5)) | D14: =IF('[2]1.7 NCPR'!D10="","",'[2]1.7 NCPR'!D10) | E14: =IF('[2]1.7 NCPR'!E10="","",'[2]1.7 NCPR'!E10) | F14: =IF('[2]1.7 NCPR'!C10="","",'[2]1.7 NCPR'!C10) | G14: =IF(D14="","",IF('[2]1.7 NCPR'!P10="","",(VLOOKUP(D14,'[2]1.7 NCPR'!$D:$P,13,0)))) | H14: =IF(G14="","",IF(G14="-",H$4,IF(G14>=H$4,H$4,IF(G14<H$3,H$3,G14)))) | I14: =IF(D14="","",IF('[1]0.2 Konsumsi Energi'!O13="","",VLOOKUP(D14,'[1]0.2 Konsumsi Energi'!$D$5:$S$704,12,0))) | J14: =IF(I14="","",IF(I14>J$4,J$4,IF(I14<J$3,J$3,I14))) | K14: =IF(D14="","",IF('[1]0.3 Konsumsi Protein Hewani'!O13="","",VLOOKUP(D14,'[1]0.3 Konsumsi Protein Hewani'!$D$5:$S$704,12,0))) | L14: =IF(K14="","",IF(K14>L$4,L$4,IF(K14<L$3,L$3,K14))) | M14: =IF(D14="","",IF('[1]0.4 Stok_Cadangan'!AN13="","",VLOOKUP(D14,'[1]0.4 Stok_Cadangan'!$D$6:$AN$704,37,FALSE))) | N14: =IF(M14="","",IF(M14>N$4,N$4,IF(M14<N$3,N$3,M14))) | O14: =IF(D14="","",IF('[1]0.5 Indikator Keterjangkauan'!J13="","",VLOOKUP(D14,'[1]0.5 Indikator Keterjangkauan'!$D$6:$K$704,7,FALSE))) | P14: =IF(O14="","",IF(O14>P$4,P$4,IF(O14<P$3,P$3,O14))) | Q14: =IF(D14="","",IF('[1]0.5 Indikator Keterjangkauan'!AC13="","",VLOOKUP(D14,'[1]0.5 Indikator Keterjangkauan'!$D$6:$AD$704,26,FALSE))) | R14: =IF(Q14="","",IF(Q14>R$4,R$4,IF(Q14<R$3,R$3,Q14))) | S14: =IF(D14="","",IF('[1]0.5 Indikator Keterjangkauan'!AI13="","",VLOOKUP(D14,'[1]0.5 Indikator Keterjangkauan'!$D$6:$AK$700,32,FALSE))) | T14: =IF(S14="","",IF(S14>T$4,T$4,IF(S14<T$3,T$3,S14))) | U14: =IF(D14="","",IF('[1]0.6 Indikator Pemanfaatan'!J13="","",VLOOKUP(D14,'[1]0.6 Indikator Pemanfaatan'!$D$6:$K$704,7,FALSE))) | V14: =IF(U14="","",IF(U14>V$4,V$4,IF(U14<V$3,V$3,U14))) | W14: =IF(D14="","",IF('[1]0.6 Indikator Pemanfaatan'!P13="","",VLOOKUP(D14,'[1]0.6 Indikator Pemanfaatan'!$D$6:$R$704,13,FALSE))) | X14: =IF(W14="","",IF(W14>X$4,X$4,IF(W14<X$3,X$3,W14))) | Y14: =IF(D14="","",IF('[1]0.6 Indikator Pemanfaatan'!AA13="","",VLOOKUP(D14,'[1]0.6 Indikator Pemanfaatan'!$D$6:$AC$706,24,FALSE))) | Z14: =IF(Y14="","",IF(Y14>Z$4,Z$4,IF(Y14<Z$3,Z$3,Y14))) | AA14: =IF(D14="","",IF('[1]0.6 Indikator Pemanfaatan'!AG13="","",VLOOKUP(D14,'[1]0.6 Indikator Pemanfaatan'!$D$6:$AJ$705,30,FALSE))) | AB14: =IF(AA14="","",IF(AA14>AB$4,AB$4,IF(AA14<AB$3,AB$3,AA14))) | AC14: =IF(D14="","",IF('[1]0.6 Indikator Pemanfaatan'!AM13="","",VLOOKUP(D14,'[1]0.6 Indikator Pemanfaatan'!$D$6:$AP$705,36,FALSE))) | AD14: =IF(AC14="","",IF(AC14>AD$4,AD$4,IF(AC14<AD$3,AD$3,AC14)))
A15: =IF('[2]1.7 NCPR'!A11="","",'[2]1.7 NCPR'!A11) | B15: =IF('[2]1.7 NCPR'!B11="","",'[2]1.7 NCPR'!B11) | C15: =IF(D15="","",LEFT(D15,5)) | D15: =IF('[2]1.7 NCPR'!D11="","",'[2]1.7 NCPR'!D11) | E15: =IF('[2]1.7 NCPR'!E11="","",'[2]1.7 NCPR'!E11) | F15: =IF('[2]1.7 NCPR'!C11="","",'[2]1.7 NCPR'!C11) | G15: =IF(D15="","",IF('[2]1.7 NCPR'!P11="","",(VLOOKUP(D15,'[2]1.7 NCPR'!$D:$P,13,0)))) | H15: =IF(G15="","",IF(G15="-",H$4,IF(G15>=H$4,H$4,IF(G15<H$3,H$3,G15)))) | I15: =IF(D15="","",IF('[1]0.2 Konsumsi Energi'!O14="","",VLOOKUP(D15,'[1]0.2 Konsumsi Energi'!$D$5:$S$704,12,0))) | J15: =IF(I15="","",IF(I15>J$4,J$4,IF(I15<J$3,J$3,I15))) | K15: =IF(D15="","",IF('[1]0.3 Konsumsi Protein Hewani'!O14="","",VLOOKUP(D15,'[1]0.3 Konsumsi Protein Hewani'!$D$5:$S$704,12,0))) | L15: =IF(K15="","",IF(K15>L$4,L$4,IF(K15<L$3,L$3,K15))) | M15: =IF(D15="","",IF('[1]0.4 Stok_Cadangan'!AN14="","",VLOOKUP(D15,'[1]0.4 Stok_Cadangan'!$D$6:$AN$704,37,FALSE))) | N15: =IF(M15="","",IF(M15>N$4,N$4,IF(M15<N$3,N$3,M15))) | O15: =IF(D15="","",IF('[1]0.5 Indikator Keterjangkauan'!J14="","",VLOOKUP(D15,'[1]0.5 Indikator Keterjangkauan'!$D$6:$K$704,7,FALSE))) | P15: =IF(O15="","",IF(O15>P$4,P$4,IF(O15<P$3,P$3,O15))) | Q15: =IF(D15="","",IF('[1]0.5 Indikator Keterjangkauan'!AC14="","",VLOOKUP(D15,'[1]0.5 Indikator Keterjangkauan'!$D$6:$AD$704,26,FALSE))) | R15: =IF(Q15="","",IF(Q15>R$4,R$4,IF(Q15<R$3,R$3,Q15))) | S15: =IF(D15="","",IF('[1]0.5 Indikator Keterjangkauan'!AI14="","",VLOOKUP(D15,'[1]0.5 Indikator Keterjangkauan'!$D$6:$AK$700,32,FALSE))) | T15: =IF(S15="","",IF(S15>T$4,T$4,IF(S15<T$3,T$3,S15))) | U15: =IF(D15="","",IF('[1]0.6 Indikator Pemanfaatan'!J14="","",VLOOKUP(D15,'[1]0.6 Indikator Pemanfaatan'!$D$6:$K$704,7,FALSE))) | V15: =IF(U15="","",IF(U15>V$4,V$4,IF(U15<V$3,V$3,U15))) | W15: =IF(D15="","",IF('[1]0.6 Indikator Pemanfaatan'!P14="","",VLOOKUP(D15,'[1]0.6 Indikator Pemanfaatan'!$D$6:$R$704,13,FALSE))) | X15: =IF(W15="","",IF(W15>X$4,X$4,IF(W15<X$3,X$3,W15))) | Y15: =IF(D15="","",IF('[1]0.6 Indikator Pemanfaatan'!AA14="","",VLOOKUP(D15,'[1]0.6 Indikator Pemanfaatan'!$D$6:$AC$706,24,FALSE))) | Z15: =IF(Y15="","",IF(Y15>Z$4,Z$4,IF(Y15<Z$3,Z$3,Y15))) | AA15: =IF(D15="","",IF('[1]0.6 Indikator Pemanfaatan'!AG14="","",VLOOKUP(D15,'[1]0.6 Indikator Pemanfaatan'!$D$6:$AJ$705,30,FALSE))) | AB15: =IF(AA15="","",IF(AA15>AB$4,AB$4,IF(AA15<AB$3,AB$3,AA15))) | AC15: =IF(D15="","",IF('[1]0.6 Indikator Pemanfaatan'!AM14="","",VLOOKUP(D15,'[1]0.6 Indikator Pemanfaatan'!$D$6:$AP$705,36,FALSE))) | AD15: =IF(AC15="","",IF(AC15>AD$4,AD$4,IF(AC15<AD$3,AD$3,AC15)))
A16: =IF('[2]1.7 NCPR'!A12="","",'[2]1.7 NCPR'!A12) | B16: =IF('[2]1.7 NCPR'!B12="","",'[2]1.7 NCPR'!B12) | C16: =IF(D16="","",LEFT(D16,5)) | D16: =IF('[2]1.7 NCPR'!D12="","",'[2]1.7 NCPR'!D12) | E16: =IF('[2]1.7 NCPR'!E12="","",'[2]1.7 NCPR'!E12) | F16: =IF('[2]1.7 NCPR'!C12="","",'[2]1.7 NCPR'!C12) | G16: =IF(D16="","",IF('[2]1.7 NCPR'!P12="","",(VLOOKUP(D16,'[2]1.7 NCPR'!$D:$P,13,0)))) | H16: =IF(G16="","",IF(G16="-",H$4,IF(G16>=H$4,H$4,IF(G16<H$3,H$3,G16)))) | I16: =IF(D16="","",IF('[1]0.2 Konsumsi Energi'!O15="","",VLOOKUP(D16,'[1]0.2 Konsumsi Energi'!$D$5:$S$704,12,0))) | J16: =IF(I16="","",IF(I16>J$4,J$4,IF(I16<J$3,J$3,I16))) | K16: =IF(D16="","",IF('[1]0.3 Konsumsi Protein Hewani'!O15="","",VLOOKUP(D16,'[1]0.3 Konsumsi Protein Hewani'!$D$5:$S$704,12,0))) | L16: =IF(K16="","",IF(K16>L$4,L$4,IF(K16<L$3,L$3,K16))) | M16: =IF(D16="","",IF('[1]0.4 Stok_Cadangan'!AN15="","",VLOOKUP(D16,'[1]0.4 Stok_Cadangan'!$D$6:$AN$704,37,FALSE))) | N16: =IF(M16="","",IF(M16>N$4,N$4,IF(M16<N$3,N$3,M16))) | O16: =IF(D16="","",IF('[1]0.5 Indikator Keterjangkauan'!J15="","",VLOOKUP(D16,'[1]0.5 Indikator Keterjangkauan'!$D$6:$K$704,7,FALSE))) | P16: =IF(O16="","",IF(O16>P$4,P$4,IF(O16<P$3,P$3,O16))) | Q16: =IF(D16="","",IF('[1]0.5 Indikator Keterjangkauan'!AC15="","",VLOOKUP(D16,'[1]0.5 Indikator Keterjangkauan'!$D$6:$AD$704,26,FALSE))) | R16: =IF(Q16="","",IF(Q16>R$4,R$4,IF(Q16<R$3,R$3,Q16))) | S16: =IF(D16="","",IF('[1]0.5 Indikator Keterjangkauan'!AI15="","",VLOOKUP(D16,'[1]0.5 Indikator Keterjangkauan'!$D$6:$AK$700,32,FALSE))) | T16: =IF(S16="","",IF(S16>T$4,T$4,IF(S16<T$3,T$3,S16))) | U16: =IF(D16="","",IF('[1]0.6 Indikator Pemanfaatan'!J15="","",VLOOKUP(D16,'[1]0.6 Indikator Pemanfaatan'!$D$6:$K$704,7,FALSE))) | V16: =IF(U16="","",IF(U16>V$4,V$4,IF(U16<V$3,V$3,U16))) | W16: =IF(D16="","",IF('[1]0.6 Indikator Pemanfaatan'!P15="","",VLOOKUP(D16,'[1]0.6 Indikator Pemanfaatan'!$D$6:$R$704,13,FALSE))) | X16: =IF(W16="","",IF(W16>X$4,X$4,IF(W16<X$3,X$3,W16))) | Y16: =IF(D16="","",IF('[1]0.6 Indikator Pemanfaatan'!AA15="","",VLOOKUP(D16,'[1]0.6 Indikator Pemanfaatan'!$D$6:$AC$706,24,FALSE))) | Z16: =IF(Y16="","",IF(Y16>Z$4,Z$4,IF(Y16<Z$3,Z$3,Y16))) | AA16: =IF(D16="","",IF('[1]0.6 Indikator Pemanfaatan'!AG15="","",VLOOKUP(D16,'[1]0.6 Indikator Pemanfaatan'!$D$6:$AJ$705,30,FALSE))) | AB16: =IF(AA16="","",IF(AA16>AB$4,AB$4,IF(AA16<AB$3,AB$3,AA16))) | AC16: =IF(D16="","",IF('[1]0.6 Indikator Pemanfaatan'!AM15="","",VLOOKUP(D16,'[1]0.6 Indikator Pemanfaatan'!$D$6:$AP$705,36,FALSE))) | AD16: =IF(AC16="","",IF(AC16>AD$4,AD$4,IF(AC16<AD$3,AD$3,AC16)))
A17: =IF('[2]1.7 NCPR'!A13="","",'[2]1.7 NCPR'!A13) | B17: =IF('[2]1.7 NCPR'!B13="","",'[2]1.7 NCPR'!B13) | C17: =IF(D17="","",LEFT(D17,5)) | D17: =IF('[2]1.7 NCPR'!D13="","",'[2]1.7 NCPR'!D13) | E17: =IF('[2]1.7 NCPR'!E13="","",'[2]1.7 NCPR'!E13) | F17: =IF('[2]1.7 NCPR'!C13="","",'[2]1.7 NCPR'!C13) | G17: =IF(D17="","",IF('[2]1.7 NCPR'!P13="","",(VLOOKUP(D17,'[2]1.7 NCPR'!$D:$P,13,0)))) | H17: =IF(G17="","",IF(G17="-",H$4,IF(G17>=H$4,H$4,IF(G17<H$3,H$3,G17)))) | I17: =IF(D17="","",IF('[1]0.2 Konsumsi Energi'!O16="","",VLOOKUP(D17,'[1]0.2 Konsumsi Energi'!$D$5:$S$704,12,0))) | J17: =IF(I17="","",IF(I17>J$4,J$4,IF(I17<J$3,J$3,I17))) | K17: =IF(D17="","",IF('[1]0.3 Konsumsi Protein Hewani'!O16="","",VLOOKUP(D17,'[1]0.3 Konsumsi Protein Hewani'!$D$5:$S$704,12,0))) | L17: =IF(K17="","",IF(K17>L$4,L$4,IF(K17<L$3,L$3,K17))) | M17: =IF(D17="","",IF('[1]0.4 Stok_Cadangan'!AN16="","",VLOOKUP(D17,'[1]0.4 Stok_Cadangan'!$D$6:$AN$704,37,FALSE))) | N17: =IF(M17="","",IF(M17>N$4,N$4,IF(M17<N$3,N$3,M17))) | O17: =IF(D17="","",IF('[1]0.5 Indikator Keterjangkauan'!J16="","",VLOOKUP(D17,'[1]0.5 Indikator Keterjangkauan'!$D$6:$K$704,7,FALSE))) | P17: =IF(O17="","",IF(O17>P$4,P$4,IF(O17<P$3,P$3,O17))) | Q17: =IF(D17="","",IF('[1]0.5 Indikator Keterjangkauan'!AC16="","",VLOOKUP(D17,'[1]0.5 Indikator Keterjangkauan'!$D$6:$AD$704,26,FALSE))) | R17: =IF(Q17="","",IF(Q17>R$4,R$4,IF(Q17<R$3,R$3,Q17))) | S17: =IF(D17="","",IF('[1]0.5 Indikator Keterjangkauan'!AI16="","",VLOOKUP(D17,'[1]0.5 Indikator Keterjangkauan'!$D$6:$AK$700,32,FALSE))) | T17: =IF(S17="","",IF(S17>T$4,T$4,IF(S17<T$3,T$3,S17))) | U17: =IF(D17="","",IF('[1]0.6 Indikator Pemanfaatan'!J16="","",VLOOKUP(D17,'[1]0.6 Indikator Pemanfaatan'!$D$6:$K$704,7,FALSE))) | V17: =IF(U17="","",IF(U17>V$4,V$4,IF(U17<V$3,V$3,U17))) | W17: =IF(D17="","",IF('[1]0.6 Indikator Pemanfaatan'!P16="","",VLOOKUP(D17,'[1]0.6 Indikator Pemanfaatan'!$D$6:$R$704,13,FALSE))) | X17: =IF(W17="","",IF(W17>X$4,X$4,IF(W17<X$3,X$3,W17))) | Y17: =IF(D17="","",IF('[1]0.6 Indikator Pemanfaatan'!AA16="","",VLOOKUP(D17,'[1]0.6 Indikator Pemanfaatan'!$D$6:$AC$706,24,FALSE))) | Z17: =IF(Y17="","",IF(Y17>Z$4,Z$4,IF(Y17<Z$3,Z$3,Y17))) | AA17: =IF(D17="","",IF('[1]0.6 Indikator Pemanfaatan'!AG16="","",VLOOKUP(D17,'[1]0.6 Indikator Pemanfaatan'!$D$6:$AJ$705,30,FALSE))) | AB17: =IF(AA17="","",IF(AA17>AB$4,AB$4,IF(AA17<AB$3,AB$3,AA17))) | AC17: =IF(D17="","",IF('[1]0.6 Indikator Pemanfaatan'!AM16="","",VLOOKUP(D17,'[1]0.6 Indikator Pemanfaatan'!$D$6:$AP$705,36,FALSE))) | AD17: =IF(AC17="","",IF(AC17>AD$4,AD$4,IF(AC17<AD$3,AD$3,AC17)))
A18: =IF('[2]1.7 NCPR'!A14="","",'[2]1.7 NCPR'!A14) | B18: =IF('[2]1.7 NCPR'!B14="","",'[2]1.7 NCPR'!B14) | C18: =IF(D18="","",LEFT(D18,5)) | D18: =IF('[2]1.7 NCPR'!D14="","",'[2]1.7 NCPR'!D14) | E18: =IF('[2]1.7 NCPR'!E14="","",'[2]1.7 NCPR'!E14) | F18: =IF('[2]1.7 NCPR'!C14="","",'[2]1.7 NCPR'!C14) | G18: =IF(D18="","",IF('[2]1.7 NCPR'!P14="","",(VLOOKUP(D18,'[2]1.7 NCPR'!$D:$P,13,0)))) | H18: =IF(G18="","",IF(G18="-",H$4,IF(G18>=H$4,H$4,IF(G18<H$3,H$3,G18)))) | I18: =IF(D18="","",IF('[1]0.2 Konsumsi Energi'!O17="","",VLOOKUP(D18,'[1]0.2 Konsumsi Energi'!$D$5:$S$704,12,0))) | J18: =IF(I18="","",IF(I18>J$4,J$4,IF(I18<J$3,J$3,I18))) | K18: =IF(D18="","",IF('[1]0.3 Konsumsi Protein Hewani'!O17="","",VLOOKUP(D18,'[1]0.3 Konsumsi Protein Hewani'!$D$5:$S$704,12,0))) | L18: =IF(K18="","",IF(K18>L$4,L$4,IF(K18<L$3,L$3,K18))) | M18: =IF(D18="","",IF('[1]0.4 Stok_Cadangan'!AN17="","",VLOOKUP(D18,'[1]0.4 Stok_Cadangan'!$D$6:$AN$704,37,FALSE))) | N18: =IF(M18="","",IF(M18>N$4,N$4,IF(M18<N$3,N$3,M18))) | O18: =IF(D18="","",IF('[1]0.5 Indikator Keterjangkauan'!J17="","",VLOOKUP(D18,'[1]0.5 Indikator Keterjangkauan'!$D$6:$K$704,7,FALSE))) | P18: =IF(O18="","",IF(O18>P$4,P$4,IF(O18<P$3,P$3,O18))) | Q18: =IF(D18="","",IF('[1]0.5 Indikator Keterjangkauan'!AC17="","",VLOOKUP(D18,'[1]0.5 Indikator Keterjangkauan'!$D$6:$AD$704,26,FALSE))) | R18: =IF(Q18="","",IF(Q18>R$4,R$4,IF(Q18<R$3,R$3,Q18))) | S18: =IF(D18="","",IF('[1]0.5 Indikator Keterjangkauan'!AI17="","",VLOOKUP(D18,'[1]0.5 Indikator Keterjangkauan'!$D$6:$AK$700,32,FALSE))) | T18: =IF(S18="","",IF(S18>T$4,T$4,IF(S18<T$3,T$3,S18))) | U18: =IF(D18="","",IF('[1]0.6 Indikator Pemanfaatan'!J17="","",VLOOKUP(D18,'[1]0.6 Indikator Pemanfaatan'!$D$6:$K$704,7,FALSE))) | V18: =IF(U18="","",IF(U18>V$4,V$4,IF(U18<V$3,V$3,U18))) | W18: =IF(D18="","",IF('[1]0.6 Indikator Pemanfaatan'!P17="","",VLOOKUP(D18,'[1]0.6 Indikator Pemanfaatan'!$D$6:$R$704,13,FALSE))) | X18: =IF(W18="","",IF(W18>X$4,X$4,IF(W18<X$3,X$3,W18))) | Y18: =IF(D18="","",IF('[1]0.6 Indikator Pemanfaatan'!AA17="","",VLOOKUP(D18,'[1]0.6 Indikator Pemanfaatan'!$D$6:$AC$706,24,FALSE))) | Z18: =IF(Y18="","",IF(Y18>Z$4,Z$4,IF(Y18<Z$3,Z$3,Y18))) | AA18: =IF(D18="","",IF('[1]0.6 Indikator Pemanfaatan'!AG17="","",VLOOKUP(D18,'[1]0.6 Indikator Pemanfaatan'!$D$6:$AJ$705,30,FALSE))) | AB18: =IF(AA18="","",IF(AA18>AB$4,AB$4,IF(AA18<AB$3,AB$3,AA18))) | AC18: =IF(D18="","",IF('[1]0.6 Indikator Pemanfaatan'!AM17="","",VLOOKUP(D18,'[1]0.6 Indikator Pemanfaatan'!$D$6:$AP$705,36,FALSE))) | AD18: =IF(AC18="","",IF(AC18>AD$4,AD$4,IF(AC18<AD$3,AD$3,AC18)))
A19: =IF('[2]1.7 NCPR'!A15="","",'[2]1.7 NCPR'!A15) | B19: =IF('[2]1.7 NCPR'!B15="","",'[2]1.7 NCPR'!B15) | C19: =IF(D19="","",LEFT(D19,5)) | D19: =IF('[2]1.7 NCPR'!D15="","",'[2]1.7 NCPR'!D15) | E19: =IF('[2]1.7 NCPR'!E15="","",'[2]1.7 NCPR'!E15) | F19: =IF('[2]1.7 NCPR'!C15="","",'[2]1.7 NCPR'!C15) | G19: =IF(D19="","",IF('[2]1.7 NCPR'!P15="","",(VLOOKUP(D19,'[2]1.7 NCPR'!$D:$P,13,0)))) | H19: =IF(G19="","",IF(G19="-",H$4,IF(G19>=H$4,H$4,IF(G19<H$3,H$3,G19)))) | I19: =IF(D19="","",IF('[1]0.2 Konsumsi Energi'!O18="","",VLOOKUP(D19,'[1]0.2 Konsumsi Energi'!$D$5:$S$704,12,0))) | J19: =IF(I19="","",IF(I19>J$4,J$4,IF(I19<J$3,J$3,I19))) | K19: =IF(D19="","",IF('[1]0.3 Konsumsi Protein Hewani'!O18="","",VLOOKUP(D19,'[1]0.3 Konsumsi Protein Hewani'!$D$5:$S$704,12,0))) | L19: =IF(K19="","",IF(K19>L$4,L$4,IF(K19<L$3,L$3,K19))) | M19: =IF(D19="","",IF('[1]0.4 Stok_Cadangan'!AN18="","",VLOOKUP(D19,'[1]0.4 Stok_Cadangan'!$D$6:$AN$704,37,FALSE))) | N19: =IF(M19="","",IF(M19>N$4,N$4,IF(M19<N$3,N$3,M19))) | O19: =IF(D19="","",IF('[1]0.5 Indikator Keterjangkauan'!J18="","",VLOOKUP(D19,'[1]0.5 Indikator Keterjangkauan'!$D$6:$K$704,7,FALSE))) | P19: =IF(O19="","",IF(O19>P$4,P$4,IF(O19<P$3,P$3,O19))) | Q19: =IF(D19="","",IF('[1]0.5 Indikator Keterjangkauan'!AC18="","",VLOOKUP(D19,'[1]0.5 Indikator Keterjangkauan'!$D$6:$AD$704,26,FALSE))) | R19: =IF(Q19="","",IF(Q19>R$4,R$4,IF(Q19<R$3,R$3,Q19))) | S19: =IF(D19="","",IF('[1]0.5 Indikator Keterjangkauan'!AI18="","",VLOOKUP(D19,'[1]0.5 Indikator Keterjangkauan'!$D$6:$AK$700,32,FALSE))) | T19: =IF(S19="","",IF(S19>T$4,T$4,IF(S19<T$3,T$3,S19))) | U19: =IF(D19="","",IF('[1]0.6 Indikator Pemanfaatan'!J18="","",VLOOKUP(D19,'[1]0.6 Indikator Pemanfaatan'!$D$6:$K$704,7,FALSE))) | V19: =IF(U19="","",IF(U19>V$4,V$4,IF(U19<V$3,V$3,U19))) | W19: =IF(D19="","",IF('[1]0.6 Indikator Pemanfaatan'!P18="","",VLOOKUP(D19,'[1]0.6 Indikator Pemanfaatan'!$D$6:$R$704,13,FALSE))) | X19: =IF(W19="","",IF(W19>X$4,X$4,IF(W19<X$3,X$3,W19))) | Y19: =IF(D19="","",IF('[1]0.6 Indikator Pemanfaatan'!AA18="","",VLOOKUP(D19,'[1]0.6 Indikator Pemanfaatan'!$D$6:$AC$706,24,FALSE))) | Z19: =IF(Y19="","",IF(Y19>Z$4,Z$4,IF(Y19<Z$3,Z$3,Y19))) | AA19: =IF(D19="","",IF('[1]0.6 Indikator Pemanfaatan'!AG18="","",VLOOKUP(D19,'[1]0.6 Indikator Pemanfaatan'!$D$6:$AJ$705,30,FALSE))) | AB19: =IF(AA19="","",IF(AA19>AB$4,AB$4,IF(AA19<AB$3,AB$3,AA19))) | AC19: =IF(D19="","",IF('[1]0.6 Indikator Pemanfaatan'!AM18="","",VLOOKUP(D19,'[1]0.6 Indikator Pemanfaatan'!$D$6:$AP$705,36,FALSE))) | AD19: =IF(AC19="","",IF(AC19>AD$4,AD$4,IF(AC19<AD$3,AD$3,AC19)))
A20: =IF('[2]1.7 NCPR'!A16="","",'[2]1.7 NCPR'!A16) | B20: =IF('[2]1.7 NCPR'!B16="","",'[2]1.7 NCPR'!B16) | C20: =IF(D20="","",LEFT(D20,5)) | D20: =IF('[2]1.7 NCPR'!D16="","",'[2]1.7 NCPR'!D16) | E20: =IF('[2]1.7 NCPR'!E16="","",'[2]1.7 NCPR'!E16) | F20: =IF('[2]1.7 NCPR'!C16="","",'[2]1.7 NCPR'!C16) | G20: =IF(D20="","",IF('[2]1.7 NCPR'!P16="","",(VLOOKUP(D20,'[2]1.7 NCPR'!$D:$P,13,0)))) | H20: =IF(G20="","",IF(G20="-",H$4,IF(G20>=H$4,H$4,IF(G20<H$3,H$3,G20)))) | I20: =IF(D20="","",IF('[1]0.2 Konsumsi Energi'!O19="","",VLOOKUP(D20,'[1]0.2 Konsumsi Energi'!$D$5:$S$704,12,0))) | J20: =IF(I20="","",IF(I20>J$4,J$4,IF(I20<J$3,J$3,I20))) | K20: =IF(D20="","",IF('[1]0.3 Konsumsi Protein Hewani'!O19="","",VLOOKUP(D20,'[1]0.3 Konsumsi Protein Hewani'!$D$5:$S$704,12,0))) | L20: =IF(K20="","",IF(K20>L$4,L$4,IF(K20<L$3,L$3,K20))) | M20: =IF(D20="","",IF('[1]0.4 Stok_Cadangan'!AN19="","",VLOOKUP(D20,'[1]0.4 Stok_Cadangan'!$D$6:$AN$704,37,FALSE))) | N20: =IF(M20="","",IF(M20>N$4,N$4,IF(M20<N$3,N$3,M20))) | O20: =IF(D20="","",IF('[1]0.5 Indikator Keterjangkauan'!J19="","",VLOOKUP(D20,'[1]0.5 Indikator Keterjangkauan'!$D$6:$K$704,7,FALSE))) | P20: =IF(O20="","",IF(O20>P$4,P$4,IF(O20<P$3,P$3,O20))) | Q20: =IF(D20="","",IF('[1]0.5 Indikator Keterjangkauan'!AC19="","",VLOOKUP(D20,'[1]0.5 Indikator Keterjangkauan'!$D$6:$AD$704,26,FALSE))) | R20: =IF(Q20="","",IF(Q20>R$4,R$4,IF(Q20<R$3,R$3,Q20))) | S20: =IF(D20="","",IF('[1]0.5 Indikator Keterjangkauan'!AI19="","",VLOOKUP(D20,'[1]0.5 Indikator Keterjangkauan'!$D$6:$AK$700,32,FALSE))) | T20: =IF(S20="","",IF(S20>T$4,T$4,IF(S20<T$3,T$3,S20))) | U20: =IF(D20="","",IF('[1]0.6 Indikator Pemanfaatan'!J19="","",VLOOKUP(D20,'[1]0.6 Indikator Pemanfaatan'!$D$6:$K$704,7,FALSE))) | V20: =IF(U20="","",IF(U20>V$4,V$4,IF(U20<V$3,V$3,U20))) | W20: =IF(D20="","",IF('[1]0.6 Indikator Pemanfaatan'!P19="","",VLOOKUP(D20,'[1]0.6 Indikator Pemanfaatan'!$D$6:$R$704,13,FALSE))) | X20: =IF(W20="","",IF(W20>X$4,X$4,IF(W20<X$3,X$3,W20))) | Y20: =IF(D20="","",IF('[1]0.6 Indikator Pemanfaatan'!AA19="","",VLOOKUP(D20,'[1]0.6 Indikator Pemanfaatan'!$D$6:$AC$706,24,FALSE))) | Z20: =IF(Y20="","",IF(Y20>Z$4,Z$4,IF(Y20<Z$3,Z$3,Y20))) | AA20: =IF(D20="","",IF('[1]0.6 Indikator Pemanfaatan'!AG19="","",VLOOKUP(D20,'[1]0.6 Indikator Pemanfaatan'!$D$6:$AJ$705,30,FALSE))) | AB20: =IF(AA20="","",IF(AA20>AB$4,AB$4,IF(AA20<AB$3,AB$3,AA20))) | AC20: =IF(D20="","",IF('[1]0.6 Indikator Pemanfaatan'!AM19="","",VLOOKUP(D20,'[1]0.6 Indikator Pemanfaatan'!$D$6:$AP$705,36,FALSE))) | AD20: =IF(AC20="","",IF(AC20>AD$4,AD$4,IF(AC20<AD$3,AD$3,AC20)))
A21: =IF('[2]1.7 NCPR'!A17="","",'[2]1.7 NCPR'!A17) | B21: =IF('[2]1.7 NCPR'!B17="","",'[2]1.7 NCPR'!B17) | C21: =IF(D21="","",LEFT(D21,5)) | D21: =IF('[2]1.7 NCPR'!D17="","",'[2]1.7 NCPR'!D17) | E21: =IF('[2]1.7 NCPR'!E17="","",'[2]1.7 NCPR'!E17) | F21: =IF('[2]1.7 NCPR'!C17="","",'[2]1.7 NCPR'!C17) | G21: =IF(D21="","",IF('[2]1.7 NCPR'!P17="","",(VLOOKUP(D21,'[2]1.7 NCPR'!$D:$P,13,0)))) | H21: =IF(G21="","",IF(G21="-",H$4,IF(G21>=H$4,H$4,IF(G21<H$3,H$3,G21)))) | I21: =IF(D21="","",IF('[1]0.2 Konsumsi Energi'!O20="","",VLOOKUP(D21,'[1]0.2 Konsumsi Energi'!$D$5:$S$704,12,0))) | J21: =IF(I21="","",IF(I21>J$4,J$4,IF(I21<J$3,J$3,I21))) | K21: =IF(D21="","",IF('[1]0.3 Konsumsi Protein Hewani'!O20="","",VLOOKUP(D21,'[1]0.3 Konsumsi Protein Hewani'!$D$5:$S$704,12,0))) | L21: =IF(K21="","",IF(K21>L$4,L$4,IF(K21<L$3,L$3,K21))) | M21: =IF(D21="","",IF('[1]0.4 Stok_Cadangan'!AN20="","",VLOOKUP(D21,'[1]0.4 Stok_Cadangan'!$D$6:$AN$704,37,FALSE))) | N21: =IF(M21="","",IF(M21>N$4,N$4,IF(M21<N$3,N$3,M21))) | O21: =IF(D21="","",IF('[1]0.5 Indikator Keterjangkauan'!J20="","",VLOOKUP(D21,'[1]0.5 Indikator Keterjangkauan'!$D$6:$K$704,7,FALSE))) | P21: =IF(O21="","",IF(O21>P$4,P$4,IF(O21<P$3,P$3,O21))) | Q21: =IF(D21="","",IF('[1]0.5 Indikator Keterjangkauan'!AC20="","",VLOOKUP(D21,'[1]0.5 Indikator Keterjangkauan'!$D$6:$AD$704,26,FALSE))) | R21: =IF(Q21="","",IF(Q21>R$4,R$4,IF(Q21<R$3,R$3,Q21))) | S21: =IF(D21="","",IF('[1]0.5 Indikator Keterjangkauan'!AI20="","",VLOOKUP(D21,'[1]0.5 Indikator Keterjangkauan'!$D$6:$AK$700,32,FALSE))) | T21: =IF(S21="","",IF(S21>T$4,T$4,IF(S21<T$3,T$3,S21))) | U21: =IF(D21="","",IF('[1]0.6 Indikator Pemanfaatan'!J20="","",VLOOKUP(D21,'[1]0.6 Indikator Pemanfaatan'!$D$6:$K$704,7,FALSE))) | V21: =IF(U21="","",IF(U21>V$4,V$4,IF(U21<V$3,V$3,U21))) | W21: =IF(D21="","",IF('[1]0.6 Indikator Pemanfaatan'!P20="","",VLOOKUP(D21,'[1]0.6 Indikator Pemanfaatan'!$D$6:$R$704,13,FALSE))) | X21: =IF(W21="","",IF(W21>X$4,X$4,IF(W21<X$3,X$3,W21))) | Y21: =IF(D21="","",IF('[1]0.6 Indikator Pemanfaatan'!AA20="","",VLOOKUP(D21,'[1]0.6 Indikator Pemanfaatan'!$D$6:$AC$706,24,FALSE))) | Z21: =IF(Y21="","",IF(Y21>Z$4,Z$4,IF(Y21<Z$3,Z$3,Y21))) | AA21: =IF(D21="","",IF('[1]0.6 Indikator Pemanfaatan'!AG20="","",VLOOKUP(D21,'[1]0.6 Indikator Pemanfaatan'!$D$6:$AJ$705,30,FALSE))) | AB21: =IF(AA21="","",IF(AA21>AB$4,AB$4,IF(AA21<AB$3,AB$3,AA21))) | AC21: =IF(D21="","",IF('[1]0.6 Indikator Pemanfaatan'!AM20="","",VLOOKUP(D21,'[1]0.6 Indikator Pemanfaatan'!$D$6:$AP$705,36,FALSE))) | AD21: =IF(AC21="","",IF(AC21>AD$4,AD$4,IF(AC21<AD$3,AD$3,AC21)))
A22: =IF('[2]1.7 NCPR'!A18="","",'[2]1.7 NCPR'!A18) | B22: =IF('[2]1.7 NCPR'!B18="","",'[2]1.7 NCPR'!B18) | C22: =IF(D22="","",LEFT(D22,5)) | D22: =IF('[2]1.7 NCPR'!D18="","",'[2]1.7 NCPR'!D18) | E22: =IF('[2]1.7 NCPR'!E18="","",'[2]1.7 NCPR'!E18) | F22: =IF('[2]1.7 NCPR'!C18="","",'[2]1.7 NCPR'!C18) | G22: =IF(D22="","",IF('[2]1.7 NCPR'!P18="","",(VLOOKUP(D22,'[2]1.7 NCPR'!$D:$P,13,0)))) | H22: =IF(G22="","",IF(G22="-",H$4,IF(G22>=H$4,H$4,IF(G22<H$3,H$3,G22)))) | I22: =IF(D22="","",IF('[1]0.2 Konsumsi Energi'!O21="","",VLOOKUP(D22,'[1]0.2 Konsumsi Energi'!$D$5:$S$704,12,0))) | J22: =IF(I22="","",IF(I22>J$4,J$4,IF(I22<J$3,J$3,I22))) | K22: =IF(D22="","",IF('[1]0.3 Konsumsi Protein Hewani'!O21="","",VLOOKUP(D22,'[1]0.3 Konsumsi Protein Hewani'!$D$5:$S$704,12,0))) | L22: =IF(K22="","",IF(K22>L$4,L$4,IF(K22<L$3,L$3,K22))) | M22: =IF(D22="","",IF('[1]0.4 Stok_Cadangan'!AN21="","",VLOOKUP(D22,'[1]0.4 Stok_Cadangan'!$D$6:$AN$704,37,FALSE))) | N22: =IF(M22="","",IF(M22>N$4,N$4,IF(M22<N$3,N$3,M22))) | O22: =IF(D22="","",IF('[1]0.5 Indikator Keterjangkauan'!J21="","",VLOOKUP(D22,'[1]0.5 Indikator Keterjangkauan'!$D$6:$K$704,7,FALSE))) | P22: =IF(O22="","",IF(O22>P$4,P$4,IF(O22<P$3,P$3,O22))) | Q22: =IF(D22="","",IF('[1]0.5 Indikator Keterjangkauan'!AC21="","",VLOOKUP(D22,'[1]0.5 Indikator Keterjangkauan'!$D$6:$AD$704,26,FALSE))) | R22: =IF(Q22="","",IF(Q22>R$4,R$4,IF(Q22<R$3,R$3,Q22))) | S22: =IF(D22="","",IF('[1]0.5 Indikator Keterjangkauan'!AI21="","",VLOOKUP(D22,'[1]0.5 Indikator Keterjangkauan'!$D$6:$AK$700,32,FALSE))) | T22: =IF(S22="","",IF(S22>T$4,T$4,IF(S22<T$3,T$3,S22))) | U22: =IF(D22="","",IF('[1]0.6 Indikator Pemanfaatan'!J21="","",VLOOKUP(D22,'[1]0.6 Indikator Pemanfaatan'!$D$6:$K$704,7,FALSE))) | V22: =IF(U22="","",IF(U22>V$4,V$4,IF(U22<V$3,V$3,U22))) | W22: =IF(D22="","",IF('[1]0.6 Indikator Pemanfaatan'!P21="","",VLOOKUP(D22,'[1]0.6 Indikator Pemanfaatan'!$D$6:$R$704,13,FALSE))) | X22: =IF(W22="","",IF(W22>X$4,X$4,IF(W22<X$3,X$3,W22))) | Y22: =IF(D22="","",IF('[1]0.6 Indikator Pemanfaatan'!AA21="","",VLOOKUP(D22,'[1]0.6 Indikator Pemanfaatan'!$D$6:$AC$706,24,FALSE))) | Z22: =IF(Y22="","",IF(Y22>Z$4,Z$4,IF(Y22<Z$3,Z$3,Y22))) | AA22: =IF(D22="","",IF('[1]0.6 Indikator Pemanfaatan'!AG21="","",VLOOKUP(D22,'[1]0.6 Indikator Pemanfaatan'!$D$6:$AJ$705,30,FALSE))) | AB22: =IF(AA22="","",IF(AA22>AB$4,AB$4,IF(AA22<AB$3,AB$3,AA22))) | AC22: =IF(D22="","",IF('[1]0.6 Indikator Pemanfaatan'!AM21="","",VLOOKUP(D22,'[1]0.6 Indikator Pemanfaatan'!$D$6:$AP$705,36,FALSE))) | AD22: =IF(AC22="","",IF(AC22>AD$4,AD$4,IF(AC22<AD$3,AD$3,AC22)))
A23: =IF('[2]1.7 NCPR'!A19="","",'[2]1.7 NCPR'!A19) | B23: =IF('[2]1.7 NCPR'!B19="","",'[2]1.7 NCPR'!B19) | C23: =IF(D23="","",LEFT(D23,5)) | D23: =IF('[2]1.7 NCPR'!D19="","",'[2]1.7 NCPR'!D19) | E23: =IF('[2]1.7 NCPR'!E19="","",'[2]1.7 NCPR'!E19) | F23: =IF('[2]1.7 NCPR'!C19="","",'[2]1.7 NCPR'!C19) | G23: =IF(D23="","",IF('[2]1.7 NCPR'!P19="","",(VLOOKUP(D23,'[2]1.7 NCPR'!$D:$P,13,0)))) | H23: =IF(G23="","",IF(G23="-",H$4,IF(G23>=H$4,H$4,IF(G23<H$3,H$3,G23)))) | I23: =IF(D23="","",IF('[1]0.2 Konsumsi Energi'!O22="","",VLOOKUP(D23,'[1]0.2 Konsumsi Energi'!$D$5:$S$704,12,0))) | J23: =IF(I23="","",IF(I23>J$4,J$4,IF(I23<J$3,J$3,I23))) | K23: =IF(D23="","",IF('[1]0.3 Konsumsi Protein Hewani'!O22="","",VLOOKUP(D23,'[1]0.3 Konsumsi Protein Hewani'!$D$5:$S$704,12,0))) | L23: =IF(K23="","",IF(K23>L$4,L$4,IF(K23<L$3,L$3,K23))) | M23: =IF(D23="","",IF('[1]0.4 Stok_Cadangan'!AN22="","",VLOOKUP(D23,'[1]0.4 Stok_Cadangan'!$D$6:$AN$704,37,FALSE))) | N23: =IF(M23="","",IF(M23>N$4,N$4,IF(M23<N$3,N$3,M23))) | O23: =IF(D23="","",IF('[1]0.5 Indikator Keterjangkauan'!J22="","",VLOOKUP(D23,'[1]0.5 Indikator Keterjangkauan'!$D$6:$K$704,7,FALSE))) | P23: =IF(O23="","",IF(O23>P$4,P$4,IF(O23<P$3,P$3,O23))) | Q23: =IF(D23="","",IF('[1]0.5 Indikator Keterjangkauan'!AC22="","",VLOOKUP(D23,'[1]0.5 Indikator Keterjangkauan'!$D$6:$AD$704,26,FALSE))) | R23: =IF(Q23="","",IF(Q23>R$4,R$4,IF(Q23<R$3,R$3,Q23))) | S23: =IF(D23="","",IF('[1]0.5 Indikator Keterjangkauan'!AI22="","",VLOOKUP(D23,'[1]0.5 Indikator Keterjangkauan'!$D$6:$AK$700,32,FALSE))) | T23: =IF(S23="","",IF(S23>T$4,T$4,IF(S23<T$3,T$3,S23))) | U23: =IF(D23="","",IF('[1]0.6 Indikator Pemanfaatan'!J22="","",VLOOKUP(D23,'[1]0.6 Indikator Pemanfaatan'!$D$6:$K$704,7,FALSE))) | V23: =IF(U23="","",IF(U23>V$4,V$4,IF(U23<V$3,V$3,U23))) | W23: =IF(D23="","",IF('[1]0.6 Indikator Pemanfaatan'!P22="","",VLOOKUP(D23,'[1]0.6 Indikator Pemanfaatan'!$D$6:$R$704,13,FALSE))) | X23: =IF(W23="","",IF(W23>X$4,X$4,IF(W23<X$3,X$3,W23))) | Y23: =IF(D23="","",IF('[1]0.6 Indikator Pemanfaatan'!AA22="","",VLOOKUP(D23,'[1]0.6 Indikator Pemanfaatan'!$D$6:$AC$706,24,FALSE))) | Z23: =IF(Y23="","",IF(Y23>Z$4,Z$4,IF(Y23<Z$3,Z$3,Y23))) | AA23: =IF(D23="","",IF('[1]0.6 Indikator Pemanfaatan'!AG22="","",VLOOKUP(D23,'[1]0.6 Indikator Pemanfaatan'!$D$6:$AJ$705,30,FALSE))) | AB23: =IF(AA23="","",IF(AA23>AB$4,AB$4,IF(AA23<AB$3,AB$3,AA23))) | AC23: =IF(D23="","",IF('[1]0.6 Indikator Pemanfaatan'!AM22="","",VLOOKUP(D23,'[1]0.6 Indikator Pemanfaatan'!$D$6:$AP$705,36,FALSE))) | AD23: =IF(AC23="","",IF(AC23>AD$4,AD$4,IF(AC23<AD$3,AD$3,AC23)))
... A705: =IF('[2]1.7 NCPR'!A701="","",'[2]1.7 NCPR'!A701) | B705: =IF('[2]1.7 NCPR'!B701="","",'[2]1.7 NCPR'!B701) | C705: =IF(D705="","",LEFT(D705,5)) | D705: =IF('[2]1.7 NCPR'!D701="","",'[2]1.7 NCPR'!D701) | E705: =IF('[2]1.7 NCPR'!E701="","",'[2]1.7 NCPR'!E701) | F705: =IF('[2]1.7 NCPR'!C701="","",'[2]1.7 NCPR'!C701) | G705: =IF(D705="","",IF('[2]1.7 NCPR'!P701="","",(VLOOKUP(D705,'[2]1.7 NCPR'!$D:$P,13,0)))) | H705: =IF(G705="","",IF(G705="-",H$4,IF(G705>=H$4,H$4,IF(G705<H$3,H$3,G705)))) | I705: =IF(D705="","",IF('[1]0.2 Konsumsi Energi'!O704="","",VLOOKUP(D705,'[1]0.2 Konsumsi Energi'!$D$5:$S$704,12,0))) | J705: =IF(I705="","",IF(I705>J$4,J$4,IF(I705<J$3,J$3,I705))) | K705: =IF(D705="","",IF('[1]0.3 Konsumsi Protein Hewani'!O704="","",VLOOKUP(D705,'[1]0.3 Konsumsi Protein Hewani'!$D$5:$S$704,12,0))) | L705: =IF(K705="","",IF(K705>L$4,L$4,IF(K705<L$3,L$3,K705))) | M705: =IF(D705="","",IF('[1]0.4 Stok_Cadangan'!AN704="","",VLOOKUP(D705,'[1]0.4 Stok_Cadangan'!$D$6:$AN$704,37,FALSE))) | N705: =IF(M705="","",IF(M705>N$4,N$4,IF(M705<N$3,N$3,M705))) | O705: =IF(D705="","",IF('[1]0.5 Indikator Keterjangkauan'!J704="","",VLOOKUP(D705,'[1]0.5 Indikator Keterjangkauan'!$D$6:$K$704,7,FALSE))) | P705: =IF(O705="","",IF(O705>P$4,P$4,IF(O705<P$3,P$3,O705))) | Q705: =IF(D705="","",IF('[1]0.5 Indikator Keterjangkauan'!AC704="","",VLOOKUP(D705,'[1]0.5 Indikator Keterjangkauan'!$D$6:$AD$704,26,FALSE))) | R705: =IF(Q705="","",IF(Q705>R$4,R$4,IF(Q705<R$3,R$3,Q705))) | S705: =IF(D705="","",IF('[1]0.5 Indikator Keterjangkauan'!AI704="","",VLOOKUP(D705,'[1]0.5 Indikator Keterjangkauan'!$D$6:$AK$700,32,FALSE))) | T705: =IF(S705="","",IF(S705>T$4,T$4,IF(S705<T$3,T$3,S705))) | U705: =IF(D705="","",IF('[1]0.6 Indikator Pemanfaatan'!J704="","",VLOOKUP(D705,'[1]0.6 Indikator Pemanfaatan'!$D$6:$K$704,7,FALSE))) | V705: =IF(U705="","",IF(U705>V$4,V$4,IF(U705<V$3,V$3,U705))) | W705: =IF(D705="","",IF('[1]0.6 Indikator Pemanfaatan'!P704="","",VLOOKUP(D705,'[1]0.6 Indikator Pemanfaatan'!$D$6:$R$704,13,FALSE))) | X705: =IF(W705="","",IF(W705>X$4,X$4,IF(W705<X$3,X$3,W705))) | Y705: =IF(D705="","",IF('[1]0.6 Indikator Pemanfaatan'!AA704="","",VLOOKUP(D705,'[1]0.6 Indikator Pemanfaatan'!$D$6:$AC$706,24,FALSE))) | Z705: =IF(Y705="","",IF(Y705>Z$4,Z$4,IF(Y705<Z$3,Z$3,Y705))) | AA705: =IF(D705="","",IF('[1]0.6 Indikator Pemanfaatan'!AG704="","",VLOOKUP(D705,'[1]0.6 Indikator Pemanfaatan'!$D$6:$AJ$705,30,FALSE))) | AB705: =IF(AA705="","",IF(AA705>AB$4,AB$4,IF(AA705<AB$3,AB$3,AA705))) | AC705: =IF(D705="","",IF('[1]0.6 Indikator Pemanfaatan'!AM704="","",VLOOKUP(D705,'[1]0.6 Indikator Pemanfaatan'!$D$6:$AP$705,36,FALSE))) | AD705: =IF(AC705="","",IF(AC705>AD$4,AD$4,IF(AC705<AD$3,AD$3,AC705)))

Sheet 2.2 Cut Off Individu & Komposit
B3: BAGIAN UTAMA | C3: 1. NCPR | D3: 2. ENERGY | E3: 3. ANIMAL PROTEIN | F3: 4. FOOD RESERVES | G3: 5. POVERTY | H3: 6. PRICE (CV) | I3: 7. PoU | J3: 8. FEMALE SCHOOL | K3: 9. NO WATER | L3: 10. FOOD SAFETY | M3: 11. PPH | N3: 12. STUNTING
B5: MEAN | C5: =IFERROR(AVERAGE('2.1 Data FSVA 2025 & Bobot'!H7:H704),"-") -> - | D5: =IFERROR(AVERAGE('2.1 Data FSVA 2025 & Bobot'!J7:J704),"-") -> - | E5: =IFERROR(AVERAGE('2.1 Data FSVA 2025 & Bobot'!L7:L704),"-") -> - | F5: =IFERROR(AVERAGE('2.1 Data FSVA 2025 & Bobot'!N7:N704),"-") -> - | G5: =IFERROR(AVERAGE('2.1 Data FSVA 2025 & Bobot'!P7:P704),"-") -> - | H5: =IFERROR(AVERAGE('2.1 Data FSVA 2025 & Bobot'!R7:R704),"-") -> - | I5: =IFERROR(AVERAGE('2.1 Data FSVA 2025 & Bobot'!T7:T704),"-") -> - | J5: =IFERROR(AVERAGE('2.1 Data FSVA 2025 & Bobot'!V7:V704),"-") -> - | K5: =IFERROR(AVERAGE('2.1 Data FSVA 2025 & Bobot'!X7:X704),"-") -> - | L5: =IFERROR(AVERAGE('2.1 Data FSVA 2025 & Bobot'!Z7:Z704),"-") -> - | M5: =IFERROR(AVERAGE('2.1 Data FSVA 2025 & Bobot'!AB7:AB704),"-") -> - | N5: =IFERROR(AVERAGE('2.1 Data FSVA 2025 & Bobot'!AD7:AD704),"-") -> -
B6: STANDAR DEVIASI | C6: =IFERROR(STDEV('2.1 Data FSVA 2025 & Bobot'!H7:H704),"-") -> - | D6: =IFERROR(STDEV('2.1 Data FSVA 2025 & Bobot'!J7:J704),"-") -> - | E6: =IFERROR(STDEV('2.1 Data FSVA 2025 & Bobot'!L7:L704),"-") -> - | F6: =IFERROR(STDEV('2.1 Data FSVA 2025 & Bobot'!N7:N704),"-") -> - | G6: =IFERROR(STDEV('2.1 Data FSVA 2025 & Bobot'!P7:P704),"-") -> - | H6: =IFERROR(STDEV('2.1 Data FSVA 2025 & Bobot'!R7:R704),"-") -> - | I6: =IFERROR(STDEV('2.1 Data FSVA 2025 & Bobot'!T7:T704),"-") -> - | J6: =IFERROR(STDEV('2.1 Data FSVA 2025 & Bobot'!V7:V704),"-") -> - | K6: =IFERROR(STDEV('2.1 Data FSVA 2025 & Bobot'!X7:X704),"-") -> - | L6: =IFERROR(STDEV('2.1 Data FSVA 2025 & Bobot'!Z7:Z704),"-") -> - | M6: =IFERROR(STDEV('2.1 Data FSVA 2025 & Bobot'!AB7:AB704),"-") -> - | N6: =IFERROR(STDEV('2.1 Data FSVA 2025 & Bobot'!AD7:AD704),"-") -> -
B7: RANGE | C7: =C9-C8 -> 10 | D7: =D9-D8 -> 70 | E7: =E9-E8 -> 92 | F7: =F9-F8 -> 3.5 | G7: =G9-G8 -> 50 | H7: =H9-H8 -> 18 | I7: =I9-I8 -> 75 | J7: =J9-J8 -> 11 | ... N7: =N9-N8 -> 75
B8: MIN | C8: 0 | D8: 50 | E8: 28 | F8: 0 | G8: 0 | H8: 2 | I8: 0 | J8: 1 | K8: 0 | L8: 0 | M8: 40 | N8: 0
B9: MAX | C9: 10 | D9: 120 | E9: 120 | F9: 3.5 | G9: 50 | H9: 20 | I9: 75 | J9: 12 | K9: 100 | L9: 100 | M9: 100 | N9: 75
B10: CUT OFF INDIKATOR INDIVIDU
B11: PRIORITAS
B12: Prioritas 1 | C12: 1.5 | D12: =70 -> 70 | E12: =70 -> 70 | F12: 0.25 | G12: 30 | H12: 10 | I12: 25 | J12: =6 -> 6 | K12: 70 | L12: 30 | M12: =70 -> 70 | N12: 40
B13: Prioritas 2 | C13: 1.25 | D13: =80 -> 80 | E13: =80 -> 80 | F13: 0.375 | G13: 25 | H13: 9 | I13: 20 | J13: =6.5 -> 6.5 | K13: 60 | L13: 40 | M13: =75 -> 75 | N13: 35
B14: Prioritas 3 | C14: 1 | D14: =90 -> 90 | E14: =90 -> 90 | F14: 0.5 | G14: 20 | H14: 8 | I14: 15 | J14: =7.5 -> 7.5 | K14: 50 | L14: 50 | M14: =80 -> 80 | N14: 30
B15: Prioritas 4 | C15: 0.75 | D15: =100 -> 100 | E15: =100 -> 100 | F15: 0.625 | G15: 15 | H15: 7 | I15: 10 | J15: =8.5 -> 8.5 | K15: 40 | L15: 60 | M15: =85 -> 85 | N15: 25
B16: Prioritas 5 | C16: 0.5 | D16: =110 -> 110 | E16: =110 -> 110 | F16: 0.75 | G16: 10 | H16: 6 | I16: 5 | J16: =9 -> 9 | K16: 30 | L16: 70 | M16: =90 -> 90 | N16: 20
B17: Prioritas 6 | C17: 0 | D17: 120 | E17: 120 | F17: 3.5 | G17: 0 | H17: 2 | I17: 0 | J17: 12 | K17: 0 | L17: 100 | M17: 100 | N17: 0
B18: CUT OFF INDIKATOR INDIVIDU (Min Max)
B19: PRIORITAS | C19: 1. NCPR ^ | D19: 2. ENERGY | E19: 4. ANIMAL PROTEIN | F19: 3. FOOD RESERVES | G19: 5. POVERTY ^ | H19: 6. PRICE (CV) ^ | I19: 7. PoU ^ | J19: 8. FEMALE SCHOOL | K19: 9. NO WATER ^ | L19: 10. FOOD SAFETY | M19: 11. PPH | N19: 12. STUNTING ^ | P19: CUT OFF SKOR KOMPOSIT (min max) | Q19: PRIORITAS KOMPOSIT | R19: RANGE SKOR KOMPOSIT (Min Max)
B20: Prioritas 1 | C20: =IFERROR((C$9-C12)/(C$9-C$8),"-") -> 0.85 | D20: =IFERROR((D12-D$8)/(D$9-D$8),"-") -> 0.28571429 | E20: =IFERROR((E12-E$8)/(E$9-E$8),"-") -> 0.45652174 | F20: =IFERROR((F12-F$8)/(F$9-F$8),"-") -> 0.071428571 | G20: =IFERROR((G$9-G12)/(G$9-G$8),"-") -> 0.4 | H20: =IFERROR((H$9-H12)/(H$9-H$8),"-") -> 0.55555556 | I20: =IFERROR((I$9-I12)/(I$9-I$8),"-") -> 0.66666667 | J20: =IFERROR((J12-J$8)/(J$9-J$8),"-") -> 0.45454545 | K20: =IFERROR((K$9-K12)/(K$9-K$8),"-") -> 0.3 | L20: =IFERROR((L12-L$8)/(L$9-L$8),"-") -> 0.3 | M20: =IFERROR((M12-M$8)/(M$9-M$8),"-") -> 0.5 | N20: =IFERROR((N$9-N12)/(N$9-N$8),"-") -> 0.46666667 | P20: =IFERROR(($C$27*C20)+($D$27*D20)+($F$27*F20)+($E$27*E20)+($G$27*G20)+($H$27*H20)+($I$27*I20)+($J$27*J20)+($K$27*K20)+($M$27*M20)+($N$27*N20)+($L$27*L20),"-") -> 0.45764822 | Q20: Prioritas 1 | S20: <= | T20: =IF(P20="-","",P20) -> 0.45764822
B21: Prioritas 2 | C21: =IFERROR((C$9-C13)/(C$9-C$8),"-") -> 0.875 | D21: =IFERROR((D13-D$8)/(D$9-D$8),"-") -> 0.42857143 | E21: =IFERROR((E13-E$8)/(E$9-E$8),"-") -> 0.56521739 | F21: =IFERROR((F13-F$8)/(F$9-F$8),"-") -> 0.10714286 | G21: =IFERROR((G$9-G13)/(G$9-G$8),"-") -> 0.5 | H21: =IFERROR((H$9-H13)/(H$9-H$8),"-") -> 0.61111111 | I21: =IFERROR((I$9-I13)/(I$9-I$8),"-") -> 0.73333333 | J21: =IFERROR((J13-J$8)/(J$9-J$8),"-") -> 0.5 | K21: =IFERROR((K$9-K13)/(K$9-K$8),"-") -> 0.4 | L21: =IFERROR((L13-L$8)/(L$9-L$8),"-") -> 0.4 | M21: =IFERROR((M13-M$8)/(M$9-M$8),"-") -> 0.58333333 | N21: =IFERROR((N$9-N13)/(N$9-N$8),"-") -> 0.53333333 | P21: =IFERROR(($C$27*C21)+($D$27*D21)+($F$27*F21)+($E$27*E21)+($G$27*G21)+($H$27*H21)+($I$27*I21)+($J$27*J21)+($K$27*K21)+($M$27*M21)+($N$27*N21)+($L$27*L21),"-") -> 0.53475509 | Q21: Prioritas 2 | R21: =T20 -> 0.45764822 | S21: - < | T21: =IF(P21="-","",P21) -> 0.53475509
B22: Prioritas 3 | C22: =IFERROR((C$9-C14)/(C$9-C$8),"-") -> 0.9 | D22: =IFERROR((D14-D$8)/(D$9-D$8),"-") -> 0.57142857 | E22: =IFERROR((E14-E$8)/(E$9-E$8),"-") -> 0.67391304 | F22: =IFERROR((F14-F$8)/(F$9-F$8),"-") -> 0.14285714 | G22: =IFERROR((G$9-G14)/(G$9-G$8),"-") -> 0.6 | H22: =IFERROR((H$9-H14)/(H$9-H$8),"-") -> 0.66666667 | I22: =IFERROR((I$9-I14)/(I$9-I$8),"-") -> 0.8 | J22: =IFERROR((J14-J$8)/(J$9-J$8),"-") -> 0.59090909 | K22: =IFERROR((K$9-K14)/(K$9-K$8),"-") -> 0.5 | L22: =IFERROR((L14-L$8)/(L$9-L$8),"-") -> 0.5 | M22: =IFERROR((M14-M$8)/(M$9-M$8),"-") -> 0.66666667 | N22: =IFERROR((N$9-N14)/(N$9-N$8),"-") -> 0.6 | P22: =IFERROR(($C$27*C22)+($D$27*D22)+($F$27*F22)+($E$27*E22)+($G$27*G22)+($H$27*H22)+($I$27*I22)+($J$27*J22)+($K$27*K22)+($M$27*M22)+($N$27*N22)+($L$27*L22),"-") -> 0.61413469 | Q22: Prioritas 3 | R22: =T21 -> 0.53475509 | S22: - < | T22: =IF(P22="-","",P22) -> 0.61413469
B23: Prioritas 4 | C23: =IFERROR((C$9-C15)/(C$9-C$8),"-") -> 0.925 | D23: =IFERROR((D15-D$8)/(D$9-D$8),"-") -> 0.71428571 | E23: =IFERROR((E15-E$8)/(E$9-E$8),"-") -> 0.7826087 | F23: =IFERROR((F15-F$8)/(F$9-F$8),"-") -> 0.17857143 | G23: =IFERROR((G$9-G15)/(G$9-G$8),"-") -> 0.7 | H23: =IFERROR((H$9-H15)/(H$9-H$8),"-") -> 0.72222222 | I23: =IFERROR((I$9-I15)/(I$9-I$8),"-") -> 0.86666667 | J23: =IFERROR((J15-J$8)/(J$9-J$8),"-") -> 0.68181818 | K23: =IFERROR((K$9-K15)/(K$9-K$8),"-") -> 0.6 | L23: =IFERROR((L15-L$8)/(L$9-L$8),"-") -> 0.6 | M23: =IFERROR((M15-M$8)/(M$9-M$8),"-") -> 0.75 | N23: =IFERROR((N$9-N15)/(N$9-N$8),"-") -> 0.66666667 | P23: =IFERROR(($C$27*C23)+($D$27*D23)+($F$27*F23)+($E$27*E23)+($G$27*G23)+($H$27*H23)+($I$27*I23)+($J$27*J23)+($K$27*K23)+($M$27*M23)+($N$27*N23)+($L$27*L23),"-") -> 0.69351429 | Q23: Prioritas 4 | R23: =T22 -> 0.61413469 | S23: - < | T23: =IF(P23="-","",P23) -> 0.69351429
B24: Prioritas 5 | C24: =IFERROR((C$9-C16)/(C$9-C$8),"-") -> 0.95 | D24: =IFERROR((D16-D$8)/(D$9-D$8),"-") -> 0.85714286 | E24: =IFERROR((E16-E$8)/(E$9-E$8),"-") -> 0.89130435 | F24: =IFERROR((F16-F$8)/(F$9-F$8),"-") -> 0.21428571 | G24: =IFERROR((G$9-G16)/(G$9-G$8),"-") -> 0.8 | H24: =IFERROR((H$9-H16)/(H$9-H$8),"-") -> 0.77777778 | I24: =IFERROR((I$9-I16)/(I$9-I$8),"-") -> 0.93333333 | J24: =IFERROR((J16-J$8)/(J$9-J$8),"-") -> 0.72727273 | K24: =IFERROR((K$9-K16)/(K$9-K$8),"-") -> 0.7 | L24: =IFERROR((L16-L$8)/(L$9-L$8),"-") -> 0.7 | M24: =IFERROR((M16-M$8)/(M$9-M$8),"-") -> 0.83333333 | N24: =IFERROR((N$9-N16)/(N$9-N$8),"-") -> 0.73333333 | P24: =IFERROR(($C$27*C24)+($D$27*D24)+($F$27*F24)+($E$27*E24)+($G$27*G24)+($H$27*H24)+($I$27*I24)+($J$27*J24)+($K$27*K24)+($M$27*M24)+($N$27*N24)+($L$27*L24),"-") -> 0.77062116 | Q24: Prioritas 5 | R24: =T23 -> 0.69351429 | S24: - < | T24: =IF(P24="-","",P24) -> 0.77062116
B25: Prioritas 6 | C25: =IFERROR((C$9-C17)/(C$9-C$8),"-") -> 1 | D25: =IFERROR((D17-D$8)/(D$9-D$8),"-") -> 1 | E25: =IFERROR((E17-E$8)/(E$9-E$8),"-") -> 1 | F25: =IFERROR((F17-F$8)/(F$9-F$8),"-") -> 1 | G25: =IFERROR((G$9-G17)/(G$9-G$8),"-") -> 1 | H25: =IFERROR((H$9-H17)/(H$9-H$8),"-") -> 1 | I25: =IFERROR((I$9-I17)/(I$9-I$8),"-") -> 1 | J25: =IFERROR((J17-J$8)/(J$9-J$8),"-") -> 1 | K25: =IFERROR((K$9-K17)/(K$9-K$8),"-") -> 1 | L25: =IFERROR((L17-L$8)/(L$9-L$8),"-") -> 1 | M25: =IFERROR((M17-M$8)/(M$9-M$8),"-") -> 1 | N25: =IFERROR((N$9-N17)/(N$9-N$8),"-") -> 1 | P25: =IFERROR(($C$27*C25)+($D$27*D25)+($F$27*F25)+($E$27*E25)+($G$27*G25)+($H$27*H25)+($I$27*I25)+($J$27*J25)+($K$27*K25)+($M$27*M25)+($N$27*N25)+($L$27*L25),"-") -> 1 | Q25: Prioritas 6 | S25: > | T25: =IF(P24="-","",P24) -> 0.77062116
B27: BOBOT INDIKATOR | C27: 0.095 | D27: 0.08 | E27: 0.08 | F27: 0.08 | G27: 0.118 | H27: 0.113 | I27: 0.099 | J27: 0.05 | K27: 0.075 | L27: 0.06 | M27: 0.078 | N27: 0.072

Sheet 2.3 Indeks & Cut off Komposit
G1: KETERSEDIAAN | K1: KETERJANGKAUAN | N1: PEMANFAATAN
A2: PERHITUNGAN INDEKS KETAHANAN PANGAN | F2: Bobot Indikator | G2: ='2.2 Cut Off Individu & Komposit'!C27 -> 0.095 | H2: ='2.2 Cut Off Individu & Komposit'!D27 -> 0.08 | I2: ='2.2 Cut Off Individu & Komposit'!E27 -> 0.08 | J2: ='2.2 Cut Off Individu & Komposit'!F27 -> 0.08 | K2: ='2.2 Cut Off Individu & Komposit'!G27 -> 0.118 | L2: ='2.2 Cut Off Individu & Komposit'!H27 -> 0.113 | M2: ='2.2 Cut Off Individu & Komposit'!I27 -> 0.099 | N2: ='2.2 Cut Off Individu & Komposit'!J27 -> 0.05 | ... R2: ='2.2 Cut Off Individu & Komposit'!N27 -> 0.072
