Workbook

Sheet 3.1 Cut Off Komposit_Individu 
C5: INDEKS KOMPOSIT | I5: 1. Rasio Konsumsi Normatif | O5: 2. Rasio Konsumsi Energi | U5: 3. Rasio Konsumsi Protein Hewani | AA5: 4. Rasio Cadangan Pangan per Kapita | AG5: 5. Persentase Penduduk Miskin | AM5: 6. Koefisien Varian (CV) Harga Pangan
B6: CUT OFF SKOR KOMPOSIT Z_Scale ARAH (+) | C6: PRIORITAS KOMPOSIT | D6: CUT OFF INDEKS KOMPOSIT | I6: PRIORITAS INDIVIDU | J6: CUT OFF RASIO KONSUMSI NORMATIVE TERHADAP PRODUKSI BERSIH | O6: PRIORITAS INDIVIDU | P6: CUT OFF | U6: PRIORITAS INDIVIDU | V6: CUT OFF | AA6: PRIORITAS INDIVIDU | AB6: CUT OFF | AG6: PRIORITAS INDIVIDU | AH6: CUT OFF PERSENTASE PDDUK HIDUP DIBAWAH GARIS KEMISKINAN | AM6: PRIORITAS INDIVIDU | AN6: CUT OFF
C7: Prioritas 1 | F7: <= | G7: =IF('[2]2.4 Prioritas Individu'!X7="","",'[2]2.4 Prioritas Individu'!X7) -> 45.764822 | I7: Prioritas 1 | K7: >= | M7: =IF('[2]2.4 Prioritas Individu'!Y7="","",'[2]2.4 Prioritas Individu'!Y7) -> 1.5 | O7: Prioritas 1 | Q7: < | S7: =IF('[2]2.4 Prioritas Individu'!Z7="","",'[2]2.4 Prioritas Individu'!Z7) -> 70 | U7: Prioritas 1 | W7: < | Y7: =IF('[2]2.4 Prioritas Individu'!AA7="","",'[2]2.4 Prioritas Individu'!AA7) -> 70 | AA7: Prioritas 1 | AC7: < | AE7: =IF('[2]2.4 Prioritas Individu'!AB7="","",'[2]2.4 Prioritas Individu'!AB7) -> 0.25 | AG7: Prioritas 1 | AI7: >= | AK7: =IF('[2]2.4 Prioritas Individu'!AC7="","",'[2]2.4 Prioritas Individu'!AC7) -> 30 | AM7: Prioritas 1 | AO7: >= | AQ7: =IF('[2]2.4 Prioritas Individu'!AD7="","",'[2]2.4 Prioritas Individu'!AD7) -> 10
C8: Prioritas 2 | D8: > | E8: =G7 -> 45.764822 | F8: − | G8: =IF('[2]2.4 Prioritas Individu'!X8="","",'[2]2.4 Prioritas Individu'!X8) -> 53.475509 | I8: Prioritas 2 | K8: =M9 -> 1.25 | L8: -< | M8: =IF('[2]2.4 Prioritas Individu'!Y7="","",'[2]2.4 Prioritas Individu'!Y7) -> 1.5 | O8: Prioritas 2 | P8: >- | Q8: =S7 -> 70 | R8: - | S8: =IF('[2]2.4 Prioritas Individu'!Z8="","",'[2]2.4 Prioritas Individu'!Z8) -> 80 | U8: Prioritas 2 | V8: >- | W8: =Y7 -> 70 | X8: - | Y8: =IF('[2]2.4 Prioritas Individu'!AA8="","",'[2]2.4 Prioritas Individu'!AA8) -> 80 | AA8: Prioritas 2 | AB8: >- | AC8: =AE7 -> 0.25 | AD8: - | AE8: =IF('[2]2.4 Prioritas Individu'!AB8="","",'[2]2.4 Prioritas Individu'!AB8) -> 0.375 | AG8: Prioritas 2 | AI8: =AK9 -> 25 | AJ8: -< | AK8: =IF('[2]2.4 Prioritas Individu'!AC7="","",'[2]2.4 Prioritas Individu'!AC7) -> 30 | AM8: Prioritas 2 | AO8: =AQ9 -> 9 | AP8: -< | AQ8: =IF('[2]2.4 Prioritas Individu'!AD7="","",'[2]2.4 Prioritas Individu'!AD7) -> 10
C9: Prioritas 3 | D9: > | E9: =G8 -> 53.475509 | F9: − | G9: =IF('[2]2.4 Prioritas Individu'!X9="","",'[2]2.4 Prioritas Individu'!X9) -> 61.413469 | I9: Prioritas 3 | K9: =M10 -> 1 | L9: -< | M9: =IF('[2]2.4 Prioritas Individu'!Y8="","",'[2]2.4 Prioritas Individu'!Y8) -> 1.25 | O9: Prioritas 3 | P9: >- | Q9: =S8 -> 80 | R9: - | S9: =IF('[2]2.4 Prioritas Individu'!Z9="","",'[2]2.4 Prioritas Individu'!Z9) -> 90 | U9: Prioritas 3 | V9: >- | W9: =Y8 -> 80 | X9: - | Y9: =IF('[2]2.4 Prioritas Individu'!AA9="","",'[2]2.4 Prioritas Individu'!AA9) -> 90 | AA9: Prioritas 3 | AB9: >- | AC9: =AE8 -> 0.375 | AD9: - | AE9: =IF('[2]2.4 Prioritas Individu'!AB9="","",'[2]2.4 Prioritas Individu'!AB9) -> 0.5 | AG9: Prioritas 3 | AI9: =AK10 -> 20 | AJ9: -< | AK9: =IF('[2]2.4 Prioritas Individu'!AC8="","",'[2]2.4 Prioritas Individu'!AC8) -> 25 | AM9: Prioritas 3 | AO9: =AQ10 -> 8 | AP9: -< | AQ9: =IF('[2]2.4 Prioritas Individu'!AD8="","",'[2]2.4 Prioritas Individu'!AD8) -> 9
C10: Prioritas 4 | D10: > | E10: =G9 -> 61.413469 | F10: − | G10: =IF('[2]2.4 Prioritas Individu'!X10="","",'[2]2.4 Prioritas Individu'!X10) -> 69.351429 | I10: Prioritas 4 | K10: =M11 -> 0.75 | L10: -< | M10: =IF('[2]2.4 Prioritas Individu'!Y9="","",'[2]2.4 Prioritas Individu'!Y9) -> 1 | O10: Prioritas 4 | P10: >- | Q10: =S9 -> 90 | R10: - | S10: =IF('[2]2.4 Prioritas Individu'!Z10="","",'[2]2.4 Prioritas Individu'!Z10) -> 100 | U10: Prioritas 4 | V10: >- | W10: =Y9 -> 90 | X10: - | Y10: =IF('[2]2.4 Prioritas Individu'!AA10="","",'[2]2.4 Prioritas Individu'!AA10) -> 100 | AA10: Prioritas 4 | AB10: >- | AC10: =AE9 -> 0.5 | AD10: - | AE10: =IF('[2]2.4 Prioritas Individu'!AB10="","",'[2]2.4 Prioritas Individu'!AB10) -> 0.625 | AG10: Prioritas 4 | AI10: =AK11 -> 15 | AJ10: -< | AK10: =IF('[2]2.4 Prioritas Individu'!AC9="","",'[2]2.4 Prioritas Individu'!AC9) -> 20 | AM10: Prioritas 4 | AO10: =AQ11 -> 7 | AP10: -< | AQ10: =IF('[2]2.4 Prioritas Individu'!AD9="","",'[2]2.4 Prioritas Individu'!AD9) -> 8
C11: Prioritas 5 | D11: > | E11: =G10 -> 69.351429 | F11: − | G11: =IF('[2]2.4 Prioritas Individu'!X11="","",'[2]2.4 Prioritas Individu'!X11) -> 77.062116 | I11: Prioritas 5 | K11: =M12 -> 0.5 | L11: -< | M11: =IF('[2]2.4 Prioritas Individu'!Y10="","",'[2]2.4 Prioritas Individu'!Y10) -> 0.75 | O11: Prioritas 5 | P11: >- | Q11: =S10 -> 100 | R11: - | S11: =IF('[2]2.4 Prioritas Individu'!Z11="","",'[2]2.4 Prioritas Individu'!Z11) -> 110 | U11: Prioritas 5 | V11: >- | W11: =Y10 -> 100 | X11: - | Y11: =IF('[2]2.4 Prioritas Individu'!AA11="","",'[2]2.4 Prioritas Individu'!AA11) -> 110 | AA11: Prioritas 5 | AB11: >- | AC11: =AE10 -> 0.625 | AD11: - | AE11: =IF('[2]2.4 Prioritas Individu'!AB11="","",'[2]2.4 Prioritas Individu'!AB11) -> 0.75 | AG11: Prioritas 5 | AI11: =AK12 -> 10 | AJ11: -< | AK11: =IF('[2]2.4 Prioritas Individu'!AC10="","",'[2]2.4 Prioritas Individu'!AC10) -> 15 | AM11: Prioritas 5 | AO11: =AQ12 -> 6 | AP11: -< | AQ11: =IF('[2]2.4 Prioritas Individu'!AD10="","",'[2]2.4 Prioritas Individu'!AD10) -> 7
C12: Prioritas 6 | F12: > | G12: =IF('[2]2.4 Prioritas Individu'!X11="","",'[2]2.4 Prioritas Individu'!X11) -> 77.062116 | I12: Prioritas 6 | K12: < | M12: =IF('[2]2.4 Prioritas Individu'!Y11="","",'[2]2.4 Prioritas Individu'!Y11) -> 0.5 | O12: Prioritas 6 | Q12: >= | S12: =IF('[2]2.4 Prioritas Individu'!Z11="","",'[2]2.4 Prioritas Individu'!Z11) -> 110 | U12: Prioritas 6 | W12: >= | Y12: =IF('[2]2.4 Prioritas Individu'!AA11="","",'[2]2.4 Prioritas Individu'!AA11) -> 110 | AA12: Prioritas 6 | AC12: >= | AE12: =IF('[2]2.4 Prioritas Individu'!AB11="","",'[2]2.4 Prioritas Individu'!AB11) -> 0.75 | AG12: Prioritas 6 | AI12: < | AK12: =IF('[2]2.4 Prioritas Individu'!AC11="","",'[2]2.4 Prioritas Individu'!AC11) -> 10 | AM12: Prioritas 6 | AO12: < | AQ12: =IF('[2]2.4 Prioritas Individu'!AD11="","",'[2]2.4 Prioritas Individu'!AD11) -> 6
C16: 7. Prevalence of Undernourishment (PoU) | I16: 8. Rata-rata Lama Sekolah Perempuan | O16: 9. Persentase Tanpa Air Bersih | U16: 10. Persentase Sertifikasi Keamanan Pangan (Segar dan Siap Saji) yang Memenuhi Standar | AA16: 11. Skor Pola Pangan Harapan | AG16: 12. Persentase Balita Stunting
C17: PRIORITAS INDIVIDU | D17: CUT OFF | I17: PRIORITAS INDIVIDU | J17: CUT OFF RATA-RATA LAMA SEKOLAH PEREMPUAN USIA >15 TAHUN | O17: PRIORITAS INDIVIDU | P17: CUT OFF PERSENTASE RUMAH TANGGA TANPA AKSES AIR BERSIH | U17: PRIORITAS INDIVIDU | V17: CUT OFF | AA17: PRIORITAS INDIVIDU | AB17: CUT OFF | AG17: PRIORITAS INDIVIDU | AH17: CUT OFF PERSENTASE BALITA STUNTING
C18: Prioritas 1 | E18: >= | G18: =IF('[2]2.4 Prioritas Individu'!AE7="","",'[2]2.4 Prioritas Individu'!AE7) -> 25 | I18: Prioritas 1 | K18: < | M18: =IF('[2]2.4 Prioritas Individu'!AF7="","",'[2]2.4 Prioritas Individu'!AF7) -> 6 | O18: Prioritas 1 | Q18: >= | S18: =IF('[2]2.4 Prioritas Individu'!AG7="","",'[2]2.4 Prioritas Individu'!AG7) -> 70 | U18: Prioritas 1 | W18: < | Y18: =IF('[2]2.4 Prioritas Individu'!AH7="","",'[2]2.4 Prioritas Individu'!AH7) -> 30 | AA18: Prioritas 1 | AD18: < | AE18: =IF('[2]2.4 Prioritas Individu'!AI7="","",'[2]2.4 Prioritas Individu'!AI7) -> 70 | AG18: Prioritas 1 | AI18: >= | AK18: =IF('[2]2.4 Prioritas Individu'!AJ7="","",'[2]2.4 Prioritas Individu'!AJ7) -> 40
C19: Prioritas 2 | E19: =G20 -> 20 | F19: -< | G19: =IF('[2]2.4 Prioritas Individu'!AE7="","",'[2]2.4 Prioritas Individu'!AE7) -> 25 | I19: Prioritas 2 | J19: >- | K19: =M18 -> 6 | L19: - | M19: =IF('[2]2.4 Prioritas Individu'!AF8="","",'[2]2.4 Prioritas Individu'!AF8) -> 6.5 | O19: Prioritas 2 | Q19: =S20 -> 60 | R19: -< | S19: =IF('[2]2.4 Prioritas Individu'!AG7="","",'[2]2.4 Prioritas Individu'!AG7) -> 70 | U19: Prioritas 2 | V19: >- | W19: =Y18 -> 30 | X19: - | Y19: =IF('[2]2.4 Prioritas Individu'!AH8="","",'[2]2.4 Prioritas Individu'!AH8) -> 40 | AA19: Prioritas 2 | AB19: >- | AC19: =AE18 -> 70 | AD19: - | AE19: =IF('[2]2.4 Prioritas Individu'!AI8="","",'[2]2.4 Prioritas Individu'!AI8) -> 75 | AG19: Prioritas 2 | AI19: =AK20 -> 30 | AJ19: -< | AK19: =IF('[2]2.4 Prioritas Individu'!AJ7="","",'[2]2.4 Prioritas Individu'!AJ7) -> 40
C20: Prioritas 3 | E20: =G21 -> 15 | F20: -< | G20: =IF('[2]2.4 Prioritas Individu'!AE8="","",'[2]2.4 Prioritas Individu'!AE8) -> 20 | I20: Prioritas 3 | J20: >- | K20: =M19 -> 6.5 | L20: - | M20: =IF('[2]2.4 Prioritas Individu'!AF9="","",'[2]2.4 Prioritas Individu'!AF9) -> 7.5 | O20: Prioritas 3 | Q20: =S21 -> 50 | R20: -< | S20: =IF('[2]2.4 Prioritas Individu'!AG8="","",'[2]2.4 Prioritas Individu'!AG8) -> 60 | U20: Prioritas 3 | V20: >- | W20: =Y19 -> 40 | X20: - | Y20: =IF('[2]2.4 Prioritas Individu'!AH9="","",'[2]2.4 Prioritas Individu'!AH9) -> 50 | AA20: Prioritas 3 | AB20: >- | AC20: =AE19 -> 75 | AD20: - | AE20: =IF('[2]2.4 Prioritas Individu'!AI9="","",'[2]2.4 Prioritas Individu'!AI9) -> 80 | AG20: Prioritas 3 | AI20: =AK21 -> 20 | AJ20: -< | AK20: =IF('[2]2.4 Prioritas Individu'!AJ8="","",'[2]2.4 Prioritas Individu'!AJ8) -> 30
C21: Prioritas 4 | E21: =G22 -> 10 | F21: -< | G21: =IF('[2]2.4 Prioritas Individu'!AE9="","",'[2]2.4 Prioritas Individu'!AE9) -> 15 | I21: Prioritas 4 | J21: >- | K21: =M20 -> 7.5 | L21: - | M21: =IF('[2]2.4 Prioritas Individu'!AF10="","",'[2]2.4 Prioritas Individu'!AF10) -> 8.5 | O21: Prioritas 4 | Q21: =S22 -> 40 | R21: -< | S21: =IF('[2]2.4 Prioritas Individu'!AG9="","",'[2]2.4 Prioritas Individu'!AG9) -> 50 | U21: Prioritas 4 | V21: >- | W21: =Y20 -> 50 | X21: - | Y21: =IF('[2]2.4 Prioritas Individu'!AH10="","",'[2]2.4 Prioritas Individu'!AH10) -> 60 | AA21: Prioritas 4 | AB21: >- | AC21: =AE20 -> 80 | AD21: - | AE21: =IF('[2]2.4 Prioritas Individu'!AI10="","",'[2]2.4 Prioritas Individu'!AI10) -> 85 | AG21: Prioritas 4 | AI21: < | AK21: =IF('[2]2.4 Prioritas Individu'!AJ9="","",'[2]2.4 Prioritas Individu'!AJ9) -> 20
C22: Prioritas 5 | E22: =G23 -> 5 | F22: -< | G22: =IF('[2]2.4 Prioritas Individu'!AE10="","",'[2]2.4 Prioritas Individu'!AE10) -> 10 | I22: Prioritas 5 | J22: >- | K22: =M21 -> 8.5 | L22: - | M22: =IF('[2]2.4 Prioritas Individu'!AF11="","",'[2]2.4 Prioritas Individu'!AF11) -> 9 | O22: Prioritas 5 | Q22: =S23 -> 30 | R22: -< | S22: =IF('[2]2.4 Prioritas Individu'!AG10="","",'[2]2.4 Prioritas Individu'!AG10) -> 40 | U22: Prioritas 5 | V22: >- | W22: =Y21 -> 60 | X22: - | Y22: =IF('[2]2.4 Prioritas Individu'!AH11="","",'[2]2.4 Prioritas Individu'!AH11) -> 70 | AA22: Prioritas 5 | AB22: >- | AC22: =AE21 -> 85 | AD22: - | AE22: =IF('[2]2.4 Prioritas Individu'!AI11="","",'[2]2.4 Prioritas Individu'!AI11) -> 90
C23: Prioritas 6 | E23: < | G23: =IF('[2]2.4 Prioritas Individu'!AE11="","",'[2]2.4 Prioritas Individu'!AE11) -> 5 | I23: Prioritas 6 | K23: >= | M23: =IF('[2]2.4 Prioritas Individu'!AF11="","",'[2]2.4 Prioritas Individu'!AF11) -> 9 | O23: Prioritas 6 | Q23: < | S23: =IF('[2]2.4 Prioritas Individu'!AG11="","",'[2]2.4 Prioritas Individu'!AG11) -> 30 | U23: Prioritas 6 | W23: >= | Y23: =IF('[2]2.4 Prioritas Individu'!AH11="","",'[2]2.4 Prioritas Individu'!AH11) -> 70 | AA23: Prioritas 6 | AD23: >= | AE23: =IF('[2]2.4 Prioritas Individu'!AI11="","",'[2]2.4 Prioritas Individu'!AI11) -> 90

Sheet 3.2 Data & Hasil FSVA 2025
B2: Provinsi : | C2: =IF('[1]0.1 Produksi Pangan & Penduduk'!$C$3="","",'[1]0.1 Produksi Pangan & Penduduk'!$C$3)
A5: No. | B5: Nama Kabupaten/Kota | C5: Kode Kab/Kota | D5: Kode Kec Kemendagri | E5: Kode Kec BPS | F5: Nama Kecamatan | G5: Produksi Padi (ton) | H5: Konversi Padi ke Beras | I5: Produksi Jagung (ton) | J5: Produksi Ubi Kayu (ton) | K5: Produksi Ubi Jalar (ton) | L5: Produksi Sagu (ton) | M5: Produksi Pisang (ton) | N5: Konsumsi Energi (kkal/kap/hr) | O5: Kebutuhan Energi (kkal/kap/hr) | P5: Konsumsi Protein (gr/kap/hr) | Q5: Kebutuhan Protein (gr/kap/hr) | R5: Cadangan Beras Pemerintah Prov (CBPP) (kg) | S5: Jumlah Penduduk Prov (jiwa) | T5: CBPP per kapita | U5: Cadangan Beras Pemerintah Kab/Kota (CBPK)(kg) | V5: Jumlah Penduduk Kab/Kota (jiwa) | W5: CBPK per kapita | X5: Cadangan Beras Pemerinta (CBP) Kec (kg) | Y5: Jumlah Penduduk Kec (jiwa) | Z5: CBP Kec per kapita | AA5: CV Harga Beras Medium | AB5: CV Harga Daging Ayam Ras | AC5: CV Harga Telur Ayam Ras | AD5: CV Harga Minyak Goreng Kemasan | AE5: Sertifikasi Keamanan Pangan Segar | AF5: Sertifikasi Keamanan Pangan Siap Saji | AG5: 1. Rasio konsumsi normatif per kapita thd produksi bersih pangan (padi, jagung, ubi kayu, ubi jalar, sagu, pisang) (NCPR) | AH5: 2. Rasio ketersediaan energi per kapita per hari terhadap standar kebutuhan | AI5: 3. Rasio ketersediaan protein hewani per kapita per hari terhadap standar kebutuhan | AJ5: 4. Cadangan pangan per kapita | AK5: 5. Presentase penduduk dengan tingkat kesejahteraan rendah | AL5: 6. Koefisien varian harga (beras medium, daging ayam ras, telur ayam, dan minyak goreng) | AM5: 7. Prevalence of Undernourishment (PoU)/Prevalensi Ketidakcukupan Konsumsi Pangan | AN5: 8. Rata2 lama sekolah perempuan umur 15 tahun ke atas | AO5: 9. Presentase RT tanpa akses ke air bersih | AP5: 10. Persentase keamanan pangan (segar & siap saji) yang memenuhi standar terhadap total sampel | AQ5: 11. Skor Pola Pangan Harapan (PPH) | AR5: 12. Presentase balita dengan tinggi badan di bawah standar (Stunting) | AS5: 1. Prioritas NCPR | AT5: 2. Prioritas ENERGY | AU5: 3. Prioritas ANIMAL PROTEIN | AV5: 4. Prioritas FOOD RESERVES | AW5: 5. Prioritas POVERTY | AX5: 6. Prioritas PRICE (CV) | AY5: 7. Prioritas PoU | AZ5: 8. Prioritas FEMALE SCHOOL | BA5: 9. Prioritas NO WATER | BB5: 10. Prioritas FOOD SAFETY | BC5: 11. Prioritas PPH | BD5: 12. Prioritas STUNTING | BE5: INDEKS KOMPOSIT | BF5: PERINGKAT | BG5: PRIORITAS KOMPOSIT | BH5: 1. Skor NCPR | BI5: 2. Skor ENERGY | BJ5: 3. Skor ANIMAL PROTEIN | BK5: 4. Skor FOOD RESERVES | BL5: 5. Skor POVERTY | BM5: 6. Skor PRICE (CV) | BN5: 7. Skor PoU | BO5: 8. Skor FEMALE SCHOOL | BP5: 9. Skor NO WATER | BQ5: 10.Skor FOOD SAFETY | BR5: 11. Skor PPH | BS5: 12.Skor STUNTING | BT5: INDEKS KETERSEDIAAN | BU5: INDEKS KETERJANGKAUAN | BV5: INDEKS PEMANFAATAN | BW5: INDEKS KOMPOSIT
A6: =IF('[1]0.1 Produksi Pangan & Penduduk'!A6="","",'[1]0.1 Produksi Pangan & Penduduk'!A6) | B6: =IF('[1]0.1 Produksi Pangan & Penduduk'!B6="","",'[1]0.1 Produksi Pangan & Penduduk'!B6) | C6: =IF('[1]0.1 Produksi Pangan & Penduduk'!C6="","",'[1]0.1 Produksi Pangan & Penduduk'!C6) | D6: =IF('[1]0.1 Produksi Pangan & Penduduk'!D6="","",'[1]0.1 Produksi Pangan & Penduduk'!D6) | E6: =IF('[1]0.1 Produksi Pangan & Penduduk'!E6="","",'[1]0.1 Produksi Pangan & Penduduk'!E6) | F6: =IF('[1]0.1 Produksi Pangan & Penduduk'!F6="","",'[1]0.1 Produksi Pangan & Penduduk'!F6) | G6: =IF('[1]0.1 Produksi Pangan & Penduduk'!J6="","",'[1]0.1 Produksi Pangan & Penduduk'!J6) | H6: =IF('[1]0.1 Produksi Pangan & Penduduk'!M6="","",'[1]0.1 Produksi Pangan & Penduduk'!M6) | I6: =IF('[1]0.1 Produksi Pangan & Penduduk'!S6="","",'[1]0.1 Produksi Pangan & Penduduk'!S6) | J6: =IF('[1]0.1 Produksi Pangan & Penduduk'!Y6="","",'[1]0.1 Produksi Pangan & Penduduk'!Y6) | K6: =IF('[1]0.1 Produksi Pangan & Penduduk'!AE6="","",'[1]0.1 Produksi Pangan & Penduduk'!AE6) | L6: =IF('[1]0.1 Produksi Pangan & Penduduk'!AK6="","",'[1]0.1 Produksi Pangan & Penduduk'!AK6) | M6: =IF('[1]0.1 Produksi Pangan & Penduduk'!AQ6="","",'[1]0.1 Produksi Pangan & Penduduk'!AQ6) | N6: =IF('[1]0.2 Konsumsi Energi'!J6="","",'[1]0.2 Konsumsi Energi'!J6) | O6: =IF('[1]0.2 Konsumsi Energi'!M6="","",'[1]0.2 Konsumsi Energi'!M6) -> 2100 | P6: =IF('[1]0.3 Konsumsi Protein Hewani'!J6="","",'[1]0.3 Konsumsi Protein Hewani'!J6) | Q6: =IF('[1]0.3 Konsumsi Protein Hewani'!M6="","",'[1]0.3 Konsumsi Protein Hewani'!M6) -> 25 | R6: =IF('[1]0.4 Stok_Cadangan'!J6="","",'[1]0.4 Stok_Cadangan'!J6) | S6: =IF('[1]0.4 Stok_Cadangan'!M6="","",'[1]0.4 Stok_Cadangan'!M6) | T6: =IF('[1]0.4 Stok_Cadangan'!P6="","",'[1]0.4 Stok_Cadangan'!P6) | U6: =IF('[1]0.4 Stok_Cadangan'!T6="","",'[1]0.4 Stok_Cadangan'!T6) | V6: =IF('[1]0.4 Stok_Cadangan'!W6="","",'[1]0.4 Stok_Cadangan'!W6) | W6: =IF('[1]0.4 Stok_Cadangan'!Z6="","",'[1]0.4 Stok_Cadangan'!Z6) | X6: =IF('[1]0.4 Stok_Cadangan'!AF6="","",'[1]0.4 Stok_Cadangan'!AF6) | Y6: =IF('[1]0.4 Stok_Cadangan'!AI6="","",'[1]0.4 Stok_Cadangan'!AI6) | Z6: =IF('[1]0.4 Stok_Cadangan'!AL6="","",'[1]0.4 Stok_Cadangan'!AL6) | AA6: =IF('[1]0.5 Indikator Keterjangkauan'!P6="","",'[1]0.5 Indikator Keterjangkauan'!P6) | AB6: =IF('[1]0.5 Indikator Keterjangkauan'!T6="","",'[1]0.5 Indikator Keterjangkauan'!T6) | AC6: =IF('[1]0.5 Indikator Keterjangkauan'!X6="","",'[1]0.5 Indikator Keterjangkauan'!X6) | AD6: =IF('[1]0.5 Indikator Keterjangkauan'!AB6="","",'[1]0.5 Indikator Keterjangkauan'!AB6) | AE6: =IF('[1]0.6 Indikator Pemanfaatan'!V6="","",'[1]0.6 Indikator Pemanfaatan'!V6) | AF6: =IF('[1]0.6 Indikator Pemanfaatan'!Z6="","",'[1]0.6 Indikator Pemanfaatan'!Z6) | AG6: =IF('[2]2.1 Data FSVA 2025 & Bobot'!H7="","",'[2]2.1 Data FSVA 2025 & Bobot'!H7) | AH6: =IF('[2]2.1 Data FSVA 2025 & Bobot'!J7="","",'[2]2.1 Data FSVA 2025 & Bobot'!J7) | AI6: =IF('[2]2.1 Data FSVA 2025 & Bobot'!L7="","",'[2]2.1 Data FSVA 2025 & Bobot'!L7) | AJ6: =IF('[2]2.1 Data FSVA 2025 & Bobot'!N7="","",'[2]2.1 Data FSVA 2025 & Bobot'!N7) | AK6: =IF('[2]2.1 Data FSVA 2025 & Bobot'!P7="","",'[2]2.1 Data FSVA 2025 & Bobot'!P7) | AL6: =IF('[2]2.1 Data FSVA 2025 & Bobot'!R7="","",'[2]2.1 Data FSVA 2025 & Bobot'!R7) | AM6: =IF('[2]2.1 Data FSVA 2025 & Bobot'!T7="","",'[2]2.1 Data FSVA 2025 & Bobot'!T7) | AN6: =IF('[2]2.1 Data FSVA 2025 & Bobot'!V7="","",'[2]2.1 Data FSVA 2025 & Bobot'!V7) | AO6: =IF('[2]2.1 Data FSVA 2025 & Bobot'!X7="","",'[2]2.1 Data FSVA 2025 & Bobot'!X7) | AP6: =IF('[2]2.1 Data FSVA 2025 & Bobot'!Z7="","",'[2]2.1 Data FSVA 2025 & Bobot'!Z7) | AQ6: =IF('[2]2.1 Data FSVA 2025 & Bobot'!AB7="","",'[2]2.1 Data FSVA 2025 & Bobot'!AB7) | AR6: =IF('[2]2.1 Data FSVA 2025 & Bobot'!AD7="","",'[2]2.1 Data FSVA 2025 & Bobot'!AD7) | AS6: =IF('[2]2.4 Prioritas Individu'!G7="","",'[2]2.4 Prioritas Individu'!G7) | AT6: =IF('[2]2.4 Prioritas Individu'!H7="","",'[2]2.4 Prioritas Individu'!H7) | AU6: =IF('[2]2.4 Prioritas Individu'!I7="","",'[2]2.4 Prioritas Individu'!I7) | AV6: =IF('[2]2.4 Prioritas Individu'!J7="","",'[2]2.4 Prioritas Individu'!J7) | AW6: =IF('[2]2.4 Prioritas Individu'!K7="","",'[2]2.4 Prioritas Individu'!K7) | AX6: =IF('[2]2.4 Prioritas Individu'!L7="","",'[2]2.4 Prioritas Individu'!L7) | AY6: =IF('[2]2.4 Prioritas Individu'!M7="","",'[2]2.4 Prioritas Individu'!M7) | AZ6: =IF('[2]2.4 Prioritas Individu'!N7="","",'[2]2.4 Prioritas Individu'!N7) | ... BG6: =IF('[2]2.4 Prioritas Individu'!U7="","",'[2]2.4 Prioritas Individu'!U7) -> - | BH6: =IF('[2]2.3 Indeks & Cut off Komposit'!G718="","",'[2]2.3 Indeks & Cut off Komposit'!G718) | BI6: =IF('[2]2.3 Indeks & Cut off Komposit'!H718="","",'[2]2.3 Indeks & Cut off Komposit'!H718) | BJ6: =IF('[2]2.3 Indeks & Cut off Komposit'!I718="","",'[2]2.3 Indeks & Cut off Komposit'!I718) | BK6: =IF('[2]2.3 Indeks & Cut off Komposit'!J718="","",'[2]2.3 Indeks & Cut off Komposit'!J718) | BL6: =IF('[2]2.3 Indeks & Cut off Komposit'!K718="","",'[2]2.3 Indeks & Cut off Komposit'!K718) | BM6: =IF('[2]2.3 Indeks & Cut off Komposit'!L718="","",'[2]2.3 Indeks & Cut off Komposit'!L718) | BN6: =IF('[2]2.3 Indeks & Cut off Komposit'!M718="","",'[2]2.3 Indeks & Cut off Komposit'!M718) | BO6: =IF('[2]2.3 Indeks & Cut off Komposit'!N718="","",'[2]2.3 Indeks & Cut off Komposit'!N718) | ... BW6: =IF('[2]2.3 Indeks & Cut off Komposit'!V718="","",'[2]2.3 Indeks & Cut off Komposit'!V718) -> -
A7: =IF('[1]0.1 Produksi Pangan & Penduduk'!A7="","",'[1]0.1 Produksi Pangan & Penduduk'!A7) | B7: =IF('[1]0.1 Produksi Pangan & Penduduk'!B7="","",'[1]0.1 Produksi Pangan & Penduduk'!B7) | C7: =IF('[1]0.1 Produksi Pangan & Penduduk'!C7="","",'[1]0.1 Produksi Pangan & Penduduk'!C7) | D7: =IF('[1]0.1 Produksi Pangan & Penduduk'!D7="","",'[1]0.1 Produksi Pangan & Penduduk'!D7) | E7: =IF('[1]0.1 Produksi Pangan & Penduduk'!E7="","",'[1]0.1 Produksi Pangan & Penduduk'!E7) | F7: =IF('[1]0.1 Produksi Pangan & Penduduk'!F7="","",'[1]0.1 Produksi Pangan & Penduduk'!F7) | G7: =IF('[1]0.1 Produksi Pangan & Penduduk'!J7="","",'[1]0.1 Produksi Pangan & Penduduk'!J7) | H7: =IF('[1]0.1 Produksi Pangan & Penduduk'!M7="","",'[1]0.1 Produksi Pangan & Penduduk'!M7) | I7: =IF('[1]0.1 Produksi Pangan & Penduduk'!S7="","",'[1]0.1 Produksi Pangan & Penduduk'!S7) | J7: =IF('[1]0.1 Produksi Pangan & Penduduk'!Y7="","",'[1]0.1 Produksi Pangan & Penduduk'!Y7) | K7: =IF('[1]0.1 Produksi Pangan & Penduduk'!AE7="","",'[1]0.1 Produksi Pangan & Penduduk'!AE7) | L7: =IF('[1]0.1 Produksi Pangan & Penduduk'!AK7="","",'[1]0.1 Produksi Pangan & Penduduk'!AK7) | M7: =IF('[1]0.1 Produksi Pangan & Penduduk'!AQ7="","",'[1]0.1 Produksi Pangan & Penduduk'!AQ7) | N7: =IF('[1]0.2 Konsumsi Energi'!J7="","",'[1]0.2 Konsumsi Energi'!J7) | O7: =IF('[1]0.2 Konsumsi Energi'!M7="","",'[1]0.2 Konsumsi Energi'!M7) -> 2100 | P7: =IF('[1]0.3 Konsumsi Protein Hewani'!J7="","",'[1]0.3 Konsumsi Protein Hewani'!J7) | Q7: =IF('[1]0.3 Konsumsi Protein Hewani'!M7="","",'[1]0.3 Konsumsi Protein Hewani'!M7) -> 25 | R7: =IF('[1]0.4 Stok_Cadangan'!J7="","",'[1]0.4 Stok_Cadangan'!J7) | S7: =IF('[1]0.4 Stok_Cadangan'!M7="","",'[1]0.4 Stok_Cadangan'!M7) | T7: =IF('[1]0.4 Stok_Cadangan'!P7="","",'[1]0.4 Stok_Cadangan'!P7) | U7: =IF('[1]0.4 Stok_Cadangan'!T7="","",'[1]0.4 Stok_Cadangan'!T7) | V7: =IF('[1]0.4 Stok_Cadangan'!W7="","",'[1]0.4 Stok_Cadangan'!W7) | W7: =IF('[1]0.4 Stok_Cadangan'!Z7="","",'[1]0.4 Stok_Cadangan'!Z7) | X7: =IF('[1]0.4 Stok_Cadangan'!AF7="","",'[1]0.4 Stok_Cadangan'!AF7) | Y7: =IF('[1]0.4 Stok_Cadangan'!AI7="","",'[1]0.4 Stok_Cadangan'!AI7) | Z7: =IF('[1]0.4 Stok_Cadangan'!AL7="","",'[1]0.4 Stok_Cadangan'!AL7) | AA7: =IF('[1]0.5 Indikator Keterjangkauan'!P7="","",'[1]0.5 Indikator Keterjangkauan'!P7) | AB7: =IF('[1]0.5 Indikator Keterjangkauan'!T7="","",'[1]0.5 Indikator Keterjangkauan'!T7) | AC7: =IF('[1]0.5 Indikator Keterjangkauan'!X7="","",'[1]0.5 Indikator Keterjangkauan'!X7) | AD7: =IF('[1]0.5 Indikator Keterjangkauan'!AB7="","",'[1]0.5 Indikator Keterjangkauan'!AB7) | AE7: =IF('[1]0.6 Indikator Pemanfaatan'!V7="","",'[1]0.6 Indikator Pemanfaatan'!V7) | AF7: =IF('[1]0.6 Indikator Pemanfaatan'!Z7="","",'[1]0.6 Indikator Pemanfaatan'!Z7) | AG7: =IF('[2]2.1 Data FSVA 2025 & Bobot'!H8="","",'[2]2.1 Data FSVA 2025 & Bobot'!H8) | AH7: =IF('[2]2.1 Data FSVA 2025 & Bobot'!J8="","",'[2]2.1 Data FSVA 2025 & Bobot'!J8) | AI7: =IF('[2]2.1 Data FSVA 2025 & Bobot'!L8="","",'[2]2.1 Data FSVA 2025 & Bobot'!L8) | AJ7: =IF('[2]2.1 Data FSVA 2025 & Bobot'!N8="","",'[2]2.1 Data FSVA 2025 & Bobot'!N8) | AK7: =IF('[2]2.1 Data FSVA 2025 & Bobot'!P8="","",'[2]2.1 Data FSVA 2025 & Bobot'!P8) | AL7: =IF('[2]2.1 Data FSVA 2025 & Bobot'!R8="","",'[2]2.1 Data FSVA 2025 & Bobot'!R8) | AM7: =IF('[2]2.1 Data FSVA 2025 & Bobot'!T8="","",'[2]2.1 Data FSVA 2025 & Bobot'!T8) | AN7: =IF('[2]2.1 Data FSVA 2025 & Bobot'!V8="","",'[2]2.1 Data FSVA 2025 & Bobot'!V8) | AO7: =IF('[2]2.1 Data FSVA 2025 & Bobot'!X8="","",'[2]2.1 Data FSVA 2025 & Bobot'!X8) | AP7: =IF('[2]2.1 Data FSVA 2025 & Bobot'!Z8="","",'[2]2.1 Data FSVA 2025 & Bobot'!Z8) | AQ7: =IF('[2]2.1 Data FSVA 2025 & Bobot'!AB8="","",'[2]2.1 Data FSVA 2025 & Bobot'!AB8) | AR7: =IF('[2]2.1 Data FSVA 2025 & Bobot'!AD8="","",'[2]2.1 Data FSVA 2025 & Bobot'!AD8) | AS7: =IF('[2]2.4 Prioritas Individu'!G8="","",'[2]2.4 Prioritas Individu'!G8) | AT7: =IF('[2]2.4 Prioritas Individu'!H8="","",'[2]2.4 Prioritas Individu'!H8) | AU7: =IF('[2]2.4 Prioritas Individu'!I8="","",'[2]2.4 Prioritas Individu'!I8) | AV7: =IF('[2]2.4 Prioritas Individu'!J8="","",'[2]2.4 Prioritas Individu'!J8) | AW7: =IF('[2]2.4 Prioritas Individu'!K8="","",'[2]2.4 Prioritas Individu'!K8) | AX7: =IF('[2]2.4 Prioritas Individu'!L8="","",'[2]2.4 Prioritas Individu'!L8) | AY7: =IF('[2]2.4 Prioritas Individu'!M8="","",'[2]2.4 Prioritas Individu'!M8) | AZ7: =IF('[2]2.4 Prioritas Individu'!N8="","",'[2]2.4 Prioritas Individu'!N8) | ... BG7: =IF('[2]2.4 Prioritas Individu'!U8="","",'[2]2.4 Prioritas Individu'!U8) -> - | BH7: =IF('[2]2.3 Indeks & Cut off Komposit'!G719="","",'[2]2.3 Indeks & Cut off Komposit'!G719) | BI7: =IF('[2]2.3 Indeks & Cut off Komposit'!H719="","",'[2]2.3 Indeks & Cut off Komposit'!H719) | BJ7: =IF('[2]2.3 Indeks & Cut off Komposit'!I719="","",'[2]2.3 Indeks & Cut off Komposit'!I719) | BK7: =IF('[2]2.3 Indeks & Cut off Komposit'!J719="","",'[2]2.3 Indeks & Cut off Komposit'!J719) | BL7: =IF('[2]2.3 Indeks & Cut off Komposit'!K719="","",'[2]2.3 Indeks & Cut off Komposit'!K719) | BM7: =IF('[2]2.3 Indeks & Cut off Komposit'!L719="","",'[2]2.3 Indeks & Cut off Komposit'!L719) | BN7: =IF('[2]2.3 Indeks & Cut off Komposit'!M719="","",'[2]2.3 Indeks & Cut off Komposit'!M719) | BO7: =IF('[2]2.3 Indeks & Cut off Komposit'!N719="","",'[2]2.3 Indeks & Cut off Komposit'!N719) | ... BW7: =IF('[2]2.3 Indeks & Cut off Komposit'!V719="","",'[2]2.3 Indeks & Cut off Komposit'!V719) -> -
A8: =IF('[1]0.1 Produksi Pangan & Penduduk'!A8="","",'[1]0.1 Produksi Pangan & Penduduk'!A8) | B8: =IF('[1]0.1 Produksi Pangan & Penduduk'!B8="","",'[1]0.1 Produksi Pangan & Penduduk'!B8) | C8: =IF('[1]0.1 Produksi Pangan & Penduduk'!C8="","",'[1]0.1 Produksi Pangan & Penduduk'!C8) | D8: =IF('[1]0.1 Produksi Pangan & Penduduk'!D8="","",'[1]0.1 Produksi Pangan & Penduduk'!D8) | E8: =IF('[1]0.1 Produksi Pangan & Penduduk'!E8="","",'[1]0.1 Produksi Pangan & Penduduk'!E8) | F8: =IF('[1]0.1 Produksi Pangan & Penduduk'!F8="","",'[1]0.1 Produksi Pangan & Penduduk'!F8) | G8: =IF('[1]0.1 Produksi Pangan & Penduduk'!J8="","",'[1]0.1 Produksi Pangan & Penduduk'!J8) | H8: =IF('[1]0.1 Produksi Pangan & Penduduk'!M8="","",'[1]0.1 Produksi Pangan & Penduduk'!M8) | I8: =IF('[1]0.1 Produksi Pangan & Penduduk'!S8="","",'[1]0.1 Produksi Pangan & Penduduk'!S8) | J8: =IF('[1]0.1 Produksi Pangan & Penduduk'!Y8="","",'[1]0.1 Produksi Pangan & Penduduk'!Y8) | K8: =IF('[1]0.1 Produksi Pangan & Penduduk'!AE8="","",'[1]0.1 Produksi Pangan & Penduduk'!AE8) | L8: =IF('[1]0.1 Produksi Pangan & Penduduk'!AK8="","",'[1]0.1 Produksi Pangan & Penduduk'!AK8) | M8: =IF('[1]0.1 Produksi Pangan & Penduduk'!AQ8="","",'[1]0.1 Produksi Pangan & Penduduk'!AQ8) | N8: =IF('[1]0.2 Konsumsi Energi'!J8="","",'[1]0.2 Konsumsi Energi'!J8) | O8: =IF('[1]0.2 Konsumsi Energi'!M8="","",'[1]0.2 Konsumsi Energi'!M8) -> 2100 | P8: =IF('[1]0.3 Konsumsi Protein Hewani'!J8="","",'[1]0.3 Konsumsi Protein Hewani'!J8) | Q8: =IF('[1]0.3 Konsumsi Protein Hewani'!M8="","",'[1]0.3 Konsumsi Protein Hewani'!M8) -> 25 | R8: =IF('[1]0.4 Stok_Cadangan'!J8="","",'[1]0.4 Stok_Cadangan'!J8) | S8: =IF('[1]0.4 Stok_Cadangan'!M8="","",'[1]0.4 Stok_Cadangan'!M8) | T8: =IF('[1]0.4 Stok_Cadangan'!P8="","",'[1]0.4 Stok_Cadangan'!P8) | U8: =IF('[1]0.4 Stok_Cadangan'!T8="","",'[1]0.4 Stok_Cadangan'!T8) | V8: =IF('[1]0.4 Stok_Cadangan'!W8="","",'[1]0.4 Stok_Cadangan'!W8) | W8: =IF('[1]0.4 Stok_Cadangan'!Z8="","",'[1]0.4 Stok_Cadangan'!Z8) | X8: =IF('[1]0.4 Stok_Cadangan'!AF8="","",'[1]0.4 Stok_Cadangan'!AF8) | Y8: =IF('[1]0.4 Stok_Cadangan'!AI8="","",'[1]0.4 Stok_Cadangan'!AI8) | Z8: =IF('[1]0.4 Stok_Cadangan'!AL8="","",'[1]0.4 Stok_Cadangan'!AL8) | AA8: =IF('[1]0.5 Indikator Keterjangkauan'!P8="","",'[1]0.5 Indikator Keterjangkauan'!P8) | AB8: =IF('[1]0.5 Indikator Keterjangkauan'!T8="","",'[1]0.5 Indikator Keterjangkauan'!T8) | AC8: =IF('[1]0.5 Indikator Keterjangkauan'!X8="","",'[1]0.5 Indikator Keterjangkauan'!X8) | AD8: =IF('[1]0.5 Indikator Keterjangkauan'!AB8="","",'[1]0.5 Indikator Keterjangkauan'!AB8) | AE8: =IF('[1]0.6 Indikator Pemanfaatan'!V8="","",'[1]0.6 Indikator Pemanfaatan'!V8) | AF8: =IF('[1]0.6 Indikator Pemanfaatan'!Z8="","",'[1]0.6 Indikator Pemanfaatan'!Z8) | AG8: =IF('[2]2.1 Data FSVA 2025 & Bobot'!H9="","",'[2]2.1 Data FSVA 2025 & Bobot'!H9) | AH8: =IF('[2]2.1 Data FSVA 2025 & Bobot'!J9="","",'[2]2.1 Data FSVA 2025 & Bobot'!J9) | AI8: =IF('[2]2.1 Data FSVA 2025 & Bobot'!L9="","",'[2]2.1 Data FSVA 2025 & Bobot'!L9) | AJ8: =IF('[2]2.1 Data FSVA 2025 & Bobot'!N9="","",'[2]2.1 Data FSVA 2025 & Bobot'!N9) | AK8: =IF('[2]2.1 Data FSVA 2025 & Bobot'!P9="","",'[2]2.1 Data FSVA 2025 & Bobot'!P9) | AL8: =IF('[2]2.1 Data FSVA 2025 & Bobot'!R9="","",'[2]2.1 Data FSVA 2025 & Bobot'!R9) | AM8: =IF('[2]2.1 Data FSVA 2025 & Bobot'!T9="","",'[2]2.1 Data FSVA 2025 & Bobot'!T9) | AN8: =IF('[2]2.1 Data FSVA 2025 & Bobot'!V9="","",'[2]2.1 Data FSVA 2025 & Bobot'!V9) | AO8: =IF('[2]2.1 Data FSVA 2025 & Bobot'!X9="","",'[2]2.1 Data FSVA 2025 & Bobot'!X9) | AP8: =IF('[2]2.1 Data FSVA 2025 & Bobot'!Z9="","",'[2]2.1 Data FSVA 2025 & Bobot'!Z9) | AQ8: =IF('[2]2.1 Data FSVA 2025 & Bobot'!AB9="","",'[2]2.1 Data FSVA 2025 & Bobot'!AB9) | AR8: =IF('[2]2.1 Data FSVA 2025 & Bobot'!AD9="","",'[2]2.1 Data FSVA 2025 & Bobot'!AD9) | AS8: =IF('[2]2.4 Prioritas Individu'!G9="","",'[2]2.4 Prioritas Individu'!G9) | AT8: =IF('[2]2.4 Prioritas Individu'!H9="","",'[2]2.4 Prioritas Individu'!H9) | AU8: =IF('[2]2.4 Prioritas Individu'!I9="","",'[2]2.4 Prioritas Individu'!I9) | AV8: =IF('[2]2.4 Prioritas Individu'!J9="","",'[2]2.4 Prioritas Individu'!J9) | AW8: =IF('[2]2.4 Prioritas Individu'!K9="","",'[2]2.4 Prioritas Individu'!K9) | AX8: =IF('[2]2.4 Prioritas Individu'!L9="","",'[2]2.4 Prioritas Individu'!L9) | AY8: =IF('[2]2.4 Prioritas Individu'!M9="","",'[2]2.4 Prioritas Individu'!M9) | AZ8: =IF('[2]2.4 Prioritas Individu'!N9="","",'[2]2.4 Prioritas Individu'!N9) | ... BG8: =IF('[2]2.4 Prioritas Individu'!U9="","",'[2]2.4 Prioritas Individu'!U9) -> - | BH8: =IF('[2]2.3 Indeks & Cut off Komposit'!G720="","",'[2]2.3 Indeks & Cut off Komposit'!G720) | BI8: =IF('[2]2.3 Indeks & Cut off Komposit'!H720="","",'[2]2.3 Indeks & Cut off Komposit'!H720) | BJ8: =IF('[2]2.3 Indeks & Cut off Komposit'!I720="","",'[2]2.3 Indeks & Cut off Komposit'!I720) | BK8: =IF('[2]2.3 Indeks & Cut off Komposit'!J720="","",'[2]2.3 Indeks & Cut off Komposit'!J720) | BL8: =IF('[2]2.3 Indeks & Cut off Komposit'!K720="","",'[2]2.3 Indeks & Cut off Komposit'!K720) | BM8: =IF('[2]2.3 Indeks & Cut off Komposit'!L720="","",'[2]2.3 Indeks & Cut off Komposit'!L720) | BN8: =IF('[2]2.3 Indeks & Cut off Komposit'!M720="","",'[2]2.3 Indeks & Cut off Komposit'!M720) | BO8: =IF('[2]2.3 Indeks & Cut off Komposit'!N720="","",'[2]2.3 Indeks & Cut off Komposit'!N720) | ... BW8: =IF('[2]2.3 Indeks & Cut off Komposit'!V720="","",'[2]2.3 Indeks & Cut off Komposit'!V720) -> -
A9: =IF('[1]0.1 Produksi Pangan & Penduduk'!A9="","",'[1]0.1 Produksi Pangan & Penduduk'!A9) | B9: =IF('[1]0.1 Produksi Pangan & Penduduk'!B9="","",'[1]0.1 Produksi Pangan & Penduduk'!B9) | C9: =IF('[1]0.1 Produksi Pangan & Penduduk'!C9="","",'[1]0.1 Produksi Pangan & Penduduk'!C9) | D9: =IF('[1]0.1 Produksi Pangan & Penduduk'!D9="","",'[1]0.1 Produksi Pangan & Penduduk'!D9) | E9: =IF('[1]0.1 Produksi Pangan & Penduduk'!E9="","",'[1]0.1 Produksi Pangan & Penduduk'!E9) | F9: =IF('[1]0.1 Produksi Pangan & Penduduk'!F9="","",'[1]0.1 Produksi Pangan & Penduduk'!F9) | G9: =IF('[1]0.1 Produksi Pangan & Penduduk'!J9="","",'[1]0.1 Produksi Pangan & Penduduk'!J9) | H9: =IF('[1]0.1 Produksi Pangan & Penduduk'!M9="","",'[1]0.1 Produksi Pangan & Penduduk'!M9) | I9: =IF('[1]0.1 Produksi Pangan & Penduduk'!S9="","",'[1]0.1 Produksi Pangan & Penduduk'!S9) | J9: =IF('[1]0.1 Produksi Pangan & Penduduk'!Y9="","",'[1]0.1 Produksi Pangan & Penduduk'!Y9) | K9: =IF('[1]0.1 Produksi Pangan & Penduduk'!AE9="","",'[1]0.1 Produksi Pangan & Penduduk'!AE9) | L9: =IF('[1]0.1 Produksi Pangan & Penduduk'!AK9="","",'[1]0.1 Produksi Pangan & Penduduk'!AK9) | M9: =IF('[1]0.1 Produksi Pangan & Penduduk'!AQ9="","",'[1]0.1 Produksi Pangan & Penduduk'!AQ9) | N9: =IF('[1]0.2 Konsumsi Energi'!J9="","",'[1]0.2 Konsumsi Energi'!J9) | O9: =IF('[1]0.2 Konsumsi Energi'!M9="","",'[1]0.2 Konsumsi Energi'!M9) -> 2100 | P9: =IF('[1]0.3 Konsumsi Protein Hewani'!J9="","",'[1]0.3 Konsumsi Protein Hewani'!J9) | Q9: =IF('[1]0.3 Konsumsi Protein Hewani'!M9="","",'[1]0.3 Konsumsi Protein Hewani'!M9) -> 25 | R9: =IF('[1]0.4 Stok_Cadangan'!J9="","",'[1]0.4 Stok_Cadangan'!J9) | S9: =IF('[1]0.4 Stok_Cadangan'!M9="","",'[1]0.4 Stok_Cadangan'!M9) | T9: =IF('[1]0.4 Stok_Cadangan'!P9="","",'[1]0.4 Stok_Cadangan'!P9) | U9: =IF('[1]0.4 Stok_Cadangan'!T9="","",'[1]0.4 Stok_Cadangan'!T9) | V9: =IF('[1]0.4 Stok_Cadangan'!W9="","",'[1]0.4 Stok_Cadangan'!W9) | W9: =IF('[1]0.4 Stok_Cadangan'!Z9="","",'[1]0.4 Stok_Cadangan'!Z9) | X9: =IF('[1]0.4 Stok_Cadangan'!AF9="","",'[1]0.4 Stok_Cadangan'!AF9) | Y9: =IF('[1]0.4 Stok_Cadangan'!AI9="","",'[1]0.4 Stok_Cadangan'!AI9) | Z9: =IF('[1]0.4 Stok_Cadangan'!AL9="","",'[1]0.4 Stok_Cadangan'!AL9) | AA9: =IF('[1]0.5 Indikator Keterjangkauan'!P9="","",'[1]0.5 Indikator Keterjangkauan'!P9) | AB9: =IF('[1]0.5 Indikator Keterjangkauan'!T9="","",'[1]0.5 Indikator Keterjangkauan'!T9) | AC9: =IF('[1]0.5 Indikator Keterjangkauan'!X9="","",'[1]0.5 Indikator Keterjangkauan'!X9) | AD9: =IF('[1]0.5 Indikator Keterjangkauan'!AB9="","",'[1]0.5 Indikator Keterjangkauan'!AB9) | AE9: =IF('[1]0.6 Indikator Pemanfaatan'!V9="","",'[1]0.6 Indikator Pemanfaatan'!V9) | AF9: =IF('[1]0.6 Indikator Pemanfaatan'!Z9="","",'[1]0.6 Indikator Pemanfaatan'!Z9) | AG9: =IF('[2]2.1 Data FSVA 2025 & Bobot'!H10="","",'[2]2.1 Data FSVA 2025 & Bobot'!H10) | AH9: =IF('[2]2.1 Data FSVA 2025 & Bobot'!J10="","",'[2]2.1 Data FSVA 2025 & Bobot'!J10) | AI9: =IF('[2]2.1 Data FSVA 2025 & Bobot'!L10="","",'[2]2.1 Data FSVA 2025 & Bobot'!L10) | AJ9: =IF('[2]2.1 Data FSVA 2025 & Bobot'!N10="","",'[2]2.1 Data FSVA 2025 & Bobot'!N10) | AK9: =IF('[2]2.1 Data FSVA 2025 & Bobot'!P10="","",'[2]2.1 Data FSVA 2025 & Bobot'!P10) | AL9: =IF('[2]2.1 Data FSVA 2025 & Bobot'!R10="","",'[2]2.1 Data FSVA 2025 & Bobot'!R10) | AM9: =IF('[2]2.1 Data FSVA 2025 & Bobot'!T10="","",'[2]2.1 Data FSVA 2025 & Bobot'!T10) | AN9: =IF('[2]2.1 Data FSVA 2025 & Bobot'!V10="","",'[2]2.1 Data FSVA 2025 & Bobot'!V10) | AO9: =IF('[2]2.1 Data FSVA 2025 & Bobot'!X10="","",'[2]2.1 Data FSVA 2025 & Bobot'!X10) | AP9: =IF('[2]2.1 Data FSVA 2025 & Bobot'!Z10="","",'[2]2.1 Data FSVA 2025 & Bobot'!Z10) | AQ9: =IF('[2]2.1 Data FSVA 2025 & Bobot'!AB10="","",'[2]2.1 Data FSVA 2025 & Bobot'!AB10) | AR9: =IF('[2]2.1 Data FSVA 2025 & Bobot'!AD10="","",'[2]2.1 Data FSVA 2025 & Bobot'!AD10) | AS9: =IF('[2]2.4 Prioritas Individu'!G10="","",'[2]2.4 Prioritas Individu'!G10) | AT9: =IF('[2]2.4 Prioritas Individu'!H10="","",'[2]2.4 Prioritas Individu'!H10) | AU9: =IF('[2]2.4 Prioritas Individu'!I10="","",'[2]2.4 Prioritas Individu'!I10) | AV9: =IF('[2]2.4 Prioritas Individu'!J10="","",'[2]2.4 Prioritas Individu'!J10) | AW9: =IF('[2]2.4 Prioritas Individu'!K10="","",'[2]2.4 Prioritas Individu'!K10) | AX9: =IF('[2]2.4 Prioritas Individu'!L10="","",'[2]2.4 Prioritas Individu'!L10) | AY9: =IF('[2]2.4 Prioritas Individu'!M10="","",'[2]2.4 Prioritas Individu'!M10) | AZ9: =IF('[2]2.4 Prioritas Individu'!N10="","",'[2]2.4 Prioritas Individu'!N10) | ... BG9: =IF('[2]2.4 Prioritas Individu'!U10="","",'[2]2.4 Prioritas Individu'!U10) -> - | BH9: =IF('[2]2.3 Indeks & Cut off Komposit'!G721="","",'[2]2.3 Indeks & Cut off Komposit'!G721) | BI9: =IF('[2]2.3 Indeks & Cut off Komposit'!H721="","",'[2]2.3 Indeks & Cut off Komposit'!H721) | BJ9: =IF('[2]2.3 Indeks & Cut off Komposit'!I721="","",'[2]2.3 Indeks & Cut off Komposit'!I721) | BK9: =IF('[2]2.3 Indeks & Cut off Komposit'!J721="","",'[2]2.3 Indeks & Cut off Komposit'!J721) | BL9: =IF('[2]2.3 Indeks & Cut off Komposit'!K721="","",'[2]2.3 Indeks & Cut off Komposit'!K721) | BM9: =IF('[2]2.3 Indeks & Cut off Komposit'!L721="","",'[2]2.3 Indeks & Cut off Komposit'!L721) | BN9: =IF('[2]2.3 Indeks & Cut off Komposit'!M721="","",'[2]2.3 Indeks & Cut off Komposit'!M721) | BO9: =IF('[2]2.3 Indeks & Cut off Komposit'!N721="","",'[2]2.3 Indeks & Cut off Komposit'!N721) | ... BW9: =IF('[2]2.3 Indeks & Cut off Komposit'!V721="","",'[2]2.3 Indeks & Cut off Komposit'!V721) -> -
A10: =IF('[1]0.1 Produksi Pangan & Penduduk'!A10="","",'[1]0.1 Produksi Pangan & Penduduk'!A10) | B10: =IF('[1]0.1 Produksi Pangan & Penduduk'!B10="","",'[1]0.1 Produksi Pangan & Penduduk'!B10) | C10: =IF('[1]0.1 Produksi Pangan & Penduduk'!C10="","",'[1]0.1 Produksi Pangan & Penduduk'!C10) | D10: =IF('[1]0.1 Produksi Pangan & Penduduk'!D10="","",'[1]0.1 Produksi Pangan & Penduduk'!D10) | E10: =IF('[1]0.1 Produksi Pangan & Penduduk'!E10="","",'[1]0.1 Produksi Pangan & Penduduk'!E10) | F10: =IF('[1]0.1 Produksi Pangan & Penduduk'!F10="","",'[1]0.1 Produksi Pangan & Penduduk'!F10) | G10: =IF('[1]0.1 Produksi Pangan & Penduduk'!J10="","",'[1]0.1 Produksi Pangan & Penduduk'!J10) | H10: =IF('[1]0.1 Produksi Pangan & Penduduk'!M10="","",'[1]0.1 Produksi Pangan & Penduduk'!M10) | I10: =IF('[1]0.1 Produksi Pangan & Penduduk'!S10="","",'[1]0.1 Produksi Pangan & Penduduk'!S10) | J10: =IF('[1]0.1 Produksi Pangan & Penduduk'!Y10="","",'[1]0.1 Produksi Pangan & Penduduk'!Y10) | K10: =IF('[1]0.1 Produksi Pangan & Penduduk'!AE10="","",'[1]0.1 Produksi Pangan & Penduduk'!AE10) | L10: =IF('[1]0.1 Produksi Pangan & Penduduk'!AK10="","",'[1]0.1 Produksi Pangan & Penduduk'!AK10) | M10: =IF('[1]0.1 Produksi Pangan & Penduduk'!AQ10="","",'[1]0.1 Produksi Pangan & Penduduk'!AQ10) | N10: =IF('[1]0.2 Konsumsi Energi'!J10="","",'[1]0.2 Konsumsi Energi'!J10) | O10: =IF('[1]0.2 Konsumsi Energi'!M10="","",'[1]0.2 Konsumsi Energi'!M10) -> 2100 | P10: =IF('[1]0.3 Konsumsi Protein Hewani'!J10="","",'[1]0.3 Konsumsi Protein Hewani'!J10) | Q10: =IF('[1]0.3 Konsumsi Protein Hewani'!M10="","",'[1]0.3 Konsumsi Protein Hewani'!M10) -> 25 | R10: =IF('[1]0.4 Stok_Cadangan'!J10="","",'[1]0.4 Stok_Cadangan'!J10) | S10: =IF('[1]0.4 Stok_Cadangan'!M10="","",'[1]0.4 Stok_Cadangan'!M10) | T10: =IF('[1]0.4 Stok_Cadangan'!P10="","",'[1]0.4 Stok_Cadangan'!P10) | U10: =IF('[1]0.4 Stok_Cadangan'!T10="","",'[1]0.4 Stok_Cadangan'!T10) | V10: =IF('[1]0.4 Stok_Cadangan'!W10="","",'[1]0.4 Stok_Cadangan'!W10) | W10: =IF('[1]0.4 Stok_Cadangan'!Z10="","",'[1]0.4 Stok_Cadangan'!Z10) | X10: =IF('[1]0.4 Stok_Cadangan'!AF10="","",'[1]0.4 Stok_Cadangan'!AF10) | Y10: =IF('[1]0.4 Stok_Cadangan'!AI10="","",'[1]0.4 Stok_Cadangan'!AI10) | Z10: =IF('[1]0.4 Stok_Cadangan'!AL10="","",'[1]0.4 Stok_Cadangan'!AL10) | AA10: =IF('[1]0.5 Indikator Keterjangkauan'!P10="","",'[1]0.5 Indikator Keterjangkauan'!P10) | AB10: =IF('[1]0.5 Indikator Keterjangkauan'!T10="","",'[1]0.5 Indikator Keterjangkauan'!T10) | AC10: =IF('[1]0.5 Indikator Keterjangkauan'!X10="","",'[1]0.5 Indikator Keterjangkauan'!X10) | AD10: =IF('[1]0.5 Indikator Keterjangkauan'!AB10="","",'[1]0.5 Indikator Keterjangkauan'!AB10) | AE10: =IF('[1]0.6 Indikator Pemanfaatan'!V10="","",'[1]0.6 Indikator Pemanfaatan'!V10) | AF10: =IF('[1]0.6 Indikator Pemanfaatan'!Z10="","",'[1]0.6 Indikator Pemanfaatan'!Z10) | AG10: =IF('[2]2.1 Data FSVA 2025 & Bobot'!H11="","",'[2]2.1 Data FSVA 2025 & Bobot'!H11) | AH10: =IF('[2]2.1 Data FSVA 2025 & Bobot'!J11="","",'[2]2.1 Data FSVA 2025 & Bobot'!J11) | AI10: =IF('[2]2.1 Data FSVA 2025 & Bobot'!L11="","",'[2]2.1 Data FSVA 2025 & Bobot'!L11) | AJ10: =IF('[2]2.1 Data FSVA 2025 & Bobot'!N11="","",'[2]2.1 Data FSVA 2025 & Bobot'!N11) | AK10: =IF('[2]2.1 Data FSVA 2025 & Bobot'!P11="","",'[2]2.1 Data FSVA 2025 & Bobot'!P11) | AL10: =IF('[2]2.1 Data FSVA 2025 & Bobot'!R11="","",'[2]2.1 Data FSVA 2025 & Bobot'!R11) | AM10: =IF('[2]2.1 Data FSVA 2025 & Bobot'!T11="","",'[2]2.1 Data FSVA 2025 & Bobot'!T11) | AN10: =IF('[2]2.1 Data FSVA 2025 & Bobot'!V11="","",'[2]2.1 Data FSVA 2025 & Bobot'!V11) | AO10: =IF('[2]2.1 Data FSVA 2025 & Bobot'!X11="","",'[2]2.1 Data FSVA 2025 & Bobot'!X11) | AP10: =IF('[2]2.1 Data FSVA 2025 & Bobot'!Z11="","",'[2]2.1 Data FSVA 2025 & Bobot'!Z11) | AQ10: =IF('[2]2.1 Data FSVA 2025 & Bobot'!AB11="","",'[2]2.1 Data FSVA 2025 & Bobot'!AB11) | AR10: =IF('[2]2.1 Data FSVA 2025 & Bobot'!AD11="","",'[2]2.1 Data FSVA 2025 & Bobot'!AD11) | AS10: =IF('[2]2.4 Prioritas Individu'!G11="","",'[2]2.4 Prioritas Individu'!G11) | AT10: =IF('[2]2.4 Prioritas Individu'!H11="","",'[2]2.4 Prioritas Individu'!H11) | AU10: =IF('[2]2.4 Prioritas Individu'!I11="","",'[2]2.4 Prioritas Individu'!I11) | AV10: =IF('[2]2.4 Prioritas Individu'!J11="","",'[2]2.4 Prioritas Individu'!J11) | AW10: =IF('[2]2.4 Prioritas Individu'!K11="","",'[2]2.4 Prioritas Individu'!K11) | AX10: =IF('[2]2.4 Prioritas Individu'!L11="","",'[2]2.4 Prioritas Individu'!L11) | AY10: =IF('[2]2.4 Prioritas Individu'!M11="","",'[2]2.4 Prioritas Individu'!M11) | AZ10: =IF('[2]2.4 Prioritas Individu'!N11="","",'[2]2.4 Prioritas Individu'!N11) | ... BG10: =IF('[2]2.4 Prioritas Individu'!U11="","",'[2]2.4 Prioritas Individu'!U11) -> - | BH10: =IF('[2]2.3 Indeks & Cut off Komposit'!G722="","",'[2]2.3 Indeks & Cut off Komposit'!G722) | BI10: =IF('[2]2.3 Indeks & Cut off Komposit'!H722="","",'[2]2.3 Indeks & Cut off Komposit'!H722) | BJ10: =IF('[2]2.3 Indeks & Cut off Komposit'!I722="","",'[2]2.3 Indeks & Cut off Komposit'!I722) | BK10: =IF('[2]2.3 Indeks & Cut off Komposit'!J722="","",'[2]2.3 Indeks & Cut off Komposit'!J722) | BL10: =IF('[2]2.3 Indeks & Cut off Komposit'!K722="","",'[2]2.3 Indeks & Cut off Komposit'!K722) | BM10: =IF('[2]2.3 Indeks & Cut off Komposit'!L722="","",'[2]2.3 Indeks & Cut off Komposit'!L722) | BN10: =IF('[2]2.3 Indeks & Cut off Komposit'!M722="","",'[2]2.3 Indeks & Cut off Komposit'!M722) | BO10: =IF('[2]2.3 Indeks & Cut off Komposit'!N722="","",'[2]2.3 Indeks & Cut off Komposit'!N722) | ... BW10: =IF('[2]2.3 Indeks & Cut off Komposit'!V722="","",'[2]2.3 Indeks & Cut off Komposit'!V722) -> -
A11: =IF('[1]0.1 Produksi Pangan & Penduduk'!A11="","",'[1]0.1 Produksi Pangan & Penduduk'!A11) | B11: =IF('[1]0.1 Produksi Pangan & Penduduk'!B11="","",'[1]0.1 Produksi Pangan & Penduduk'!B11) | C11: =IF('[1]0.1 Produksi Pangan & Penduduk'!C11="","",'[1]0.1 Produksi Pangan & Penduduk'!C11) | D11: =IF('[1]0.1 Produksi Pangan & Penduduk'!D11="","",'[1]0.1 Produksi Pangan & Penduduk'!D11) | E11: =IF('[1]0.1 Produksi Pangan & Penduduk'!E11="","",'[1]0.1 Produksi Pangan & Penduduk'!E11) | F11: =IF('[1]0.1 Produksi Pangan & Penduduk'!F11="","",'[1]0.1 Produksi Pangan & Penduduk'!F11) | G11: =IF('[1]0.1 Produksi Pangan & Penduduk'!J11="","",'[1]0.1 Produksi Pangan & Penduduk'!J11) | H11: =IF('[1]0.1 Produksi Pangan & Penduduk'!M11="","",'[1]0.1 Produksi Pangan & Penduduk'!M11) | I11: =IF('[1]0.1 Produksi Pangan & Penduduk'!S11="","",'[1]0.1 Produksi Pangan & Penduduk'!S11) | J11: =IF('[1]0.1 Produksi Pangan & Penduduk'!Y11="","",'[1]0.1 Produksi Pangan & Penduduk'!Y11) | K11: =IF('[1]0.1 Produksi Pangan & Penduduk'!AE11="","",'[1]0.1 Produksi Pangan & Penduduk'!AE11) | L11: =IF('[1]0.1 Produksi Pangan & Penduduk'!AK11="","",'[1]0.1 Produksi Pangan & Penduduk'!AK11) | M11: =IF('[1]0.1 Produksi Pangan & Penduduk'!AQ11="","",'[1]0.1 Produksi Pangan & Penduduk'!AQ11) | N11: =IF('[1]0.2 Konsumsi Energi'!J11="","",'[1]0.2 Konsumsi Energi'!J11) | O11: =IF('[1]0.2 Konsumsi Energi'!M11="","",'[1]0.2 Konsumsi Energi'!M11) -> 2100 | P11: =IF('[1]0.3 Konsumsi Protein Hewani'!J11="","",'[1]0.3 Konsumsi Protein Hewani'!J11) | Q11: =IF('[1]0.3 Konsumsi Protein Hewani'!M11="","",'[1]0.3 Konsumsi Protein Hewani'!M11) -> 25 | R11: =IF('[1]0.4 Stok_Cadangan'!J11="","",'[1]0.4 Stok_Cadangan'!J11) | S11: =IF('[1]0.4 Stok_Cadangan'!M11="","",'[1]0.4 Stok_Cadangan'!M11) | T11: =IF('[1]0.4 Stok_Cadangan'!P11="","",'[1]0.4 Stok_Cadangan'!P11) | U11: =IF('[1]0.4 Stok_Cadangan'!T11="","",'[1]0.4 Stok_Cadangan'!T11) | V11: =IF('[1]0.4 Stok_Cadangan'!W11="","",'[1]0.4 Stok_Cadangan'!W11) | W11: =IF('[1]0.4 Stok_Cadangan'!Z11="","",'[1]0.4 Stok_Cadangan'!Z11) | X11: =IF('[1]0.4 Stok_Cadangan'!AF11="","",'[1]0.4 Stok_Cadangan'!AF11) | Y11: =IF('[1]0.4 Stok_Cadangan'!AI11="","",'[1]0.4 Stok_Cadangan'!AI11) | Z11: =IF('[1]0.4 Stok_Cadangan'!AL11="","",'[1]0.4 Stok_Cadangan'!AL11) | AA11: =IF('[1]0.5 Indikator Keterjangkauan'!P11="","",'[1]0.5 Indikator Keterjangkauan'!P11) | AB11: =IF('[1]0.5 Indikator Keterjangkauan'!T11="","",'[1]0.5 Indikator Keterjangkauan'!T11) | AC11: =IF('[1]0.5 Indikator Keterjangkauan'!X11="","",'[1]0.5 Indikator Keterjangkauan'!X11) | AD11: =IF('[1]0.5 Indikator Keterjangkauan'!AB11="","",'[1]0.5 Indikator Keterjangkauan'!AB11) | AE11: =IF('[1]0.6 Indikator Pemanfaatan'!V11="","",'[1]0.6 Indikator Pemanfaatan'!V11) | AF11: =IF('[1]0.6 Indikator Pemanfaatan'!Z11="","",'[1]0.6 Indikator Pemanfaatan'!Z11) | AG11: =IF('[2]2.1 Data FSVA 2025 & Bobot'!H12="","",'[2]2.1 Data FSVA 2025 & Bobot'!H12) | AH11: =IF('[2]2.1 Data FSVA 2025 & Bobot'!J12="","",'[2]2.1 Data FSVA 2025 & Bobot'!J12) | AI11: =IF('[2]2.1 Data FSVA 2025 & Bobot'!L12="","",'[2]2.1 Data FSVA 2025 & Bobot'!L12) | AJ11: =IF('[2]2.1 Data FSVA 2025 & Bobot'!N12="","",'[2]2.1 Data FSVA 2025 & Bobot'!N12) | AK11: =IF('[2]2.1 Data FSVA 2025 & Bobot'!P12="","",'[2]2.1 Data FSVA 2025 & Bobot'!P12) | AL11: =IF('[2]2.1 Data FSVA 2025 & Bobot'!R12="","",'[2]2.1 Data FSVA 2025 & Bobot'!R12) | AM11: =IF('[2]2.1 Data FSVA 2025 & Bobot'!T12="","",'[2]2.1 Data FSVA 2025 & Bobot'!T12) | AN11: =IF('[2]2.1 Data FSVA 2025 & Bobot'!V12="","",'[2]2.1 Data FSVA 2025 & Bobot'!V12) | AO11: =IF('[2]2.1 Data FSVA 2025 & Bobot'!X12="","",'[2]2.1 Data FSVA 2025 & Bobot'!X12) | AP11: =IF('[2]2.1 Data FSVA 2025 & Bobot'!Z12="","",'[2]2.1 Data FSVA 2025 & Bobot'!Z12) | AQ11: =IF('[2]2.1 Data FSVA 2025 & Bobot'!AB12="","",'[2]2.1 Data FSVA 2025 & Bobot'!AB12) | AR11: =IF('[2]2.1 Data FSVA 2025 & Bobot'!AD12="","",'[2]2.1 Data FSVA 2025 & Bobot'!AD12) | AS11: =IF('[2]2.4 Prioritas Individu'!G12="","",'[2]2.4 Prioritas Individu'!G12) | AT11: =IF('[2]2.4 Prioritas Individu'!H12="","",'[2]2.4 Prioritas Individu'!H12) | AU11: =IF('[2]2.4 Prioritas Individu'!I12="","",'[2]2.4 Prioritas Individu'!I12) | AV11: =IF('[2]2.4 Prioritas Individu'!J12="","",'[2]2.4 Prioritas Individu'!J12) | AW11: =IF('[2]2.4 Prioritas Individu'!K12="","",'[2]2.4 Prioritas Individu'!K12) | AX11: =IF('[2]2.4 Prioritas Individu'!L12="","",'[2]2.4 Prioritas Individu'!L12) | AY11: =IF('[2]2.4 Prioritas Individu'!M12="","",'[2]2.4 Prioritas Individu'!M12) | AZ11: =IF('[2]2.4 Prioritas Individu'!N12="","",'[2]2.4 Prioritas Individu'!N12) | ... BG11: =IF('[2]2.4 Prioritas Individu'!U12="","",'[2]2.4 Prioritas Individu'!U12) -> - | BH11: =IF('[2]2.3 Indeks & Cut off Komposit'!G723="","",'[2]2.3 Indeks & Cut off Komposit'!G723) | BI11: =IF('[2]2.3 Indeks & Cut off Komposit'!H723="","",'[2]2.3 Indeks & Cut off Komposit'!H723) | BJ11: =IF('[2]2.3 Indeks & Cut off Komposit'!I723="","",'[2]2.3 Indeks & Cut off Komposit'!I723) | BK11: =IF('[2]2.3 Indeks & Cut off Komposit'!J723="","",'[2]2.3 Indeks & Cut off Komposit'!J723) | BL11: =IF('[2]2.3 Indeks & Cut off Komposit'!K723="","",'[2]2.3 Indeks & Cut off Komposit'!K723) | BM11: =IF('[2]2.3 Indeks & Cut off Komposit'!L723="","",'[2]2.3 Indeks & Cut off Komposit'!L723) | BN11: =IF('[2]2.3 Indeks & Cut off Komposit'!M723="","",'[2]2.3 Indeks & Cut off Komposit'!M723) | BO11: =IF('[2]2.3 Indeks & Cut off Komposit'!N723="","",'[2]2.3 Indeks & Cut off Komposit'!N723) | ... BW11: =IF('[2]2.3 Indeks & Cut off Komposit'!V723="","",'[2]2.3 Indeks & Cut off Komposit'!V723) -> -
A12: =IF('[1]0.1 Produksi Pangan & Penduduk'!A12="","",'[1]0.1 Produksi Pangan & Penduduk'!A12) | B12: =IF('[1]0.1 Produksi Pangan & Penduduk'!B12="","",'[1]0.1 Produksi Pangan & Penduduk'!B12) | C12: =IF('[1]0.1 Produksi Pangan & Penduduk'!C12="","",'[1]0.1 Produksi Pangan & Penduduk'!C12) | D12: =IF('[1]0.1 Produksi Pangan & Penduduk'!D12="","",'[1]0.1 Produksi Pangan & Penduduk'!D12) | E12: =IF('[1]0.1 Produksi Pangan & Penduduk'!E12="","",'[1]0.1 Produksi Pangan & Penduduk'!E12) | F12: =IF('[1]0.1 Produksi Pangan & Penduduk'!F12="","",'[1]0.1 Produksi Pangan & Penduduk'!F12) | G12: =IF('[1]0.1 Produksi Pangan & Penduduk'!J12="","",'[1]0.1 Produksi Pangan & Penduduk'!J12) | H12: =IF('[1]0.1 Produksi Pangan & Penduduk'!M12="","",'[1]0.1 Produksi Pangan & Penduduk'!M12) | I12: =IF('[1]0.1 Produksi Pangan & Penduduk'!S12="","",'[1]0.1 Produksi Pangan & Penduduk'!S12) | J12: =IF('[1]0.1 Produksi Pangan & Penduduk'!Y12="","",'[1]0.1 Produksi Pangan & Penduduk'!Y12) | K12: =IF('[1]0.1 Produksi Pangan & Penduduk'!AE12="","",'[1]0.1 Produksi Pangan & Penduduk'!AE12) | L12: =IF('[1]0.1 Produksi Pangan & Penduduk'!AK12="","",'[1]0.1 Produksi Pangan & Penduduk'!AK12) | M12: =IF('[1]0.1 Produksi Pangan & Penduduk'!AQ12="","",'[1]0.1 Produksi Pangan & Penduduk'!AQ12) | N12: =IF('[1]0.2 Konsumsi Energi'!J12="","",'[1]0.2 Konsumsi Energi'!J12) | O12: =IF('[1]0.2 Konsumsi Energi'!M12="","",'[1]0.2 Konsumsi Energi'!M12) -> 2100 | P12: =IF('[1]0.3 Konsumsi Protein Hewani'!J12="","",'[1]0.3 Konsumsi Protein Hewani'!J12) | Q12: =IF('[1]0.3 Konsumsi Protein Hewani'!M12="","",'[1]0.3 Konsumsi Protein Hewani'!M12) -> 25 | R12: =IF('[1]0.4 Stok_Cadangan'!J12="","",'[1]0.4 Stok_Cadangan'!J12) | S12: =IF('[1]0.4 Stok_Cadangan'!M12="","",'[1]0.4 Stok_Cadangan'!M12) | T12: =IF('[1]0.4 Stok_Cadangan'!P12="","",'[1]0.4 Stok_Cadangan'!P12) | U12: =IF('[1]0.4 Stok_Cadangan'!T12="","",'[1]0.4 Stok_Cadangan'!T12) | V12: =IF('[1]0.4 Stok_Cadangan'!W12="","",'[1]0.4 Stok_Cadangan'!W12) | W12: =IF('[1]0.4 Stok_Cadangan'!Z12="","",'[1]0.4 Stok_Cadangan'!Z12) | X12: =IF('[1]0.4 Stok_Cadangan'!AF12="","",'[1]0.4 Stok_Cadangan'!AF12) | Y12: =IF('[1]0.4 Stok_Cadangan'!AI12="","",'[1]0.4 Stok_Cadangan'!AI12) | Z12: =IF('[1]0.4 Stok_Cadangan'!AL12="","",'[1]0.4 Stok_Cadangan'!AL12) | AA12: =IF('[1]0.5 Indikator Keterjangkauan'!P12="","",'[1]0.5 Indikator Keterjangkauan'!P12) | AB12: =IF('[1]0.5 Indikator Keterjangkauan'!T12="","",'[1]0.5 Indikator Keterjangkauan'!T12) | AC12: =IF('[1]0.5 Indikator Keterjangkauan'!X12="","",'[1]0.5 Indikator Keterjangkauan'!X12) | AD12: =IF('[1]0.5 Indikator Keterjangkauan'!AB12="","",'[1]0.5 Indikator Keterjangkauan'!AB12) | AE12: =IF('[1]0.6 Indikator Pemanfaatan'!V12="","",'[1]0.6 Indikator Pemanfaatan'!V12) | AF12: =IF('[1]0.6 Indikator Pemanfaatan'!Z12="","",'[1]0.6 Indikator Pemanfaatan'!Z12) | AG12: =IF('[2]2.1 Data FSVA 2025 & Bobot'!H13="","",'[2]2.1 Data FSVA 2025 & Bobot'!H13) | AH12: =IF('[2]2.1 Data FSVA 2025 & Bobot'!J13="","",'[2]2.1 Data FSVA 2025 & Bobot'!J13) | AI12: =IF('[2]2.1 Data FSVA 2025 & Bobot'!L13="","",'[2]2.1 Data FSVA 2025 & Bobot'!L13) | AJ12: =IF('[2]2.1 Data FSVA 2025 & Bobot'!N13="","",'[2]2.1 Data FSVA 2025 & Bobot'!N13) | AK12: =IF('[2]2.1 Data FSVA 2025 & Bobot'!P13="","",'[2]2.1 Data FSVA 2025 & Bobot'!P13) | AL12: =IF('[2]2.1 Data FSVA 2025 & Bobot'!R13="","",'[2]2.1 Data FSVA 2025 & Bobot'!R13) | AM12: =IF('[2]2.1 Data FSVA 2025 & Bobot'!T13="","",'[2]2.1 Data FSVA 2025 & Bobot'!T13) | AN12: =IF('[2]2.1 Data FSVA 2025 & Bobot'!V13="","",'[2]2.1 Data FSVA 2025 & Bobot'!V13) | AO12: =IF('[2]2.1 Data FSVA 2025 & Bobot'!X13="","",'[2]2.1 Data FSVA 2025 & Bobot'!X13) | AP12: =IF('[2]2.1 Data FSVA 2025 & Bobot'!Z13="","",'[2]2.1 Data FSVA 2025 & Bobot'!Z13) | AQ12: =IF('[2]2.1 Data FSVA 2025 & Bobot'!AB13="","",'[2]2.1 Data FSVA 2025 & Bobot'!AB13) | AR12: =IF('[2]2.1 Data FSVA 2025 & Bobot'!AD13="","",'[2]2.1 Data FSVA 2025 & Bobot'!AD13) | AS12: =IF('[2]2.4 Prioritas Individu'!G13="","",'[2]2.4 Prioritas Individu'!G13) | AT12: =IF('[2]2.4 Prioritas Individu'!H13="","",'[2]2.4 Prioritas Individu'!H13) | AU12: =IF('[2]2.4 Prioritas Individu'!I13="","",'[2]2.4 Prioritas Individu'!I13) | AV12: =IF('[2]2.4 Prioritas Individu'!J13="","",'[2]2.4 Prioritas Individu'!J13) | AW12: =IF('[2]2.4 Prioritas Individu'!K13="","",'[2]2.4 Prioritas Individu'!K13) | AX12: =IF('[2]2.4 Prioritas Individu'!L13="","",'[2]2.4 Prioritas Individu'!L13) | AY12: =IF('[2]2.4 Prioritas Individu'!M13="","",'[2]2.4 Prioritas Individu'!M13) | AZ12: =IF('[2]2.4 Prioritas Individu'!N13="","",'[2]2.4 Prioritas Individu'!N13) | ... BG12: =IF('[2]2.4 Prioritas Individu'!U13="","",'[2]2.4 Prioritas Individu'!U13) -> - | BH12: =IF('[2]2.3 Indeks & Cut off Komposit'!G724="","",'[2]2.3 Indeks & Cut off Komposit'!G724) | BI12: =IF('[2]2.3 Indeks & Cut off Komposit'!H724="","",'[2]2.3 Indeks & Cut off Komposit'!H724) | BJ12: =IF('[2]2.3 Indeks & Cut off Komposit'!I724="","",'[2]2.3 Indeks & Cut off Komposit'!I724) | BK12: =IF('[2]2.3 Indeks & Cut off Komposit'!J724="","",'[2]2.3 Indeks & Cut off Komposit'!J724) | BL12: =IF('[2]2.3 Indeks & Cut off Komposit'!K724="","",'[2]2.3 Indeks & Cut off Komposit'!K724) | BM12: =IF('[2]2.3 Indeks & Cut off Komposit'!L724="","",'[2]2.3 Indeks & Cut off Komposit'!L724) | BN12: =IF('[2]2.3 Indeks & Cut off Komposit'!M724="","",'[2]2.3 Indeks & Cut off Komposit'!M724) | BO12: =IF('[2]2.3 Indeks & Cut off Komposit'!N724="","",'[2]2.3 Indeks & Cut off Komposit'!N724) | ... BW12: =IF('[2]2.3 Indeks & Cut off Komposit'!V724="","",'[2]2.3 Indeks & Cut off Komposit'!V724) -> -
A13: =IF('[1]0.1 Produksi Pangan & Penduduk'!A13="","",'[1]0.1 Produksi Pangan & Penduduk'!A13) | B13: =IF('[1]0.1 Produksi Pangan & Penduduk'!B13="","",'[1]0.1 Produksi Pangan & Penduduk'!B13) | C13: =IF('[1]0.1 Produksi Pangan & Penduduk'!C13="","",'[1]0.1 Produksi Pangan & Penduduk'!C13) | D13: =IF('[1]0.1 Produksi Pangan & Penduduk'!D13="","",'[1]0.1 Produksi Pangan & Penduduk'!D13) | E13: =IF('[1]0.1 Produksi Pangan & Penduduk'!E13="","",'[1]0.1 Produksi Pangan & Penduduk'!E13) | F13: =IF('[1]0.1 Produksi Pangan & Penduduk'!F13="","",'[1]0.1 Produksi Pangan & Penduduk'!F13) | G13: =IF('[1]0.1 Produksi Pangan & Penduduk'!J13="","",'[1]0.1 Produksi Pangan & Penduduk'!J13) | H13: =IF('[1]0.1 Produksi Pangan & Penduduk'!M13="","",'[1]0.1 Produksi Pangan & Penduduk'!M13) | I13: =IF('[1]0.1 Produksi Pangan & Penduduk'!S13="","",'[1]0.1 Produksi Pangan & Penduduk'!S13) | J13: =IF('[1]0.1 Produksi Pangan & Penduduk'!Y13="","",'[1]0.1 Produksi Pangan & Penduduk'!Y13) | K13: =IF('[1]0.1 Produksi Pangan & Penduduk'!AE13="","",'[1]0.1 Produksi Pangan & Penduduk'!AE13) | L13: =IF('[1]0.1 Produksi Pangan & Penduduk'!AK13="","",'[1]0.1 Produksi Pangan & Penduduk'!AK13) | M13: =IF('[1]0.1 Produksi Pangan & Penduduk'!AQ13="","",'[1]0.1 Produksi Pangan & Penduduk'!AQ13) | N13: =IF('[1]0.2 Konsumsi Energi'!J13="","",'[1]0.2 Konsumsi Energi'!J13) | O13: =IF('[1]0.2 Konsumsi Energi'!M13="","",'[1]0.2 Konsumsi Energi'!M13) -> 2100 | P13: =IF('[1]0.3 Konsumsi Protein Hewani'!J13="","",'[1]0.3 Konsumsi Protein Hewani'!J13) | Q13: =IF('[1]0.3 Konsumsi Protein Hewani'!M13="","",'[1]0.3 Konsumsi Protein Hewani'!M13) -> 25 | R13: =IF('[1]0.4 Stok_Cadangan'!J13="","",'[1]0.4 Stok_Cadangan'!J13) | S13: =IF('[1]0.4 Stok_Cadangan'!M13="","",'[1]0.4 Stok_Cadangan'!M13) | T13: =IF('[1]0.4 Stok_Cadangan'!P13="","",'[1]0.4 Stok_Cadangan'!P13) | U13: =IF('[1]0.4 Stok_Cadangan'!T13="","",'[1]0.4 Stok_Cadangan'!T13) | V13: =IF('[1]0.4 Stok_Cadangan'!W13="","",'[1]0.4 Stok_Cadangan'!W13) | W13: =IF('[1]0.4 Stok_Cadangan'!Z13="","",'[1]0.4 Stok_Cadangan'!Z13) | X13: =IF('[1]0.4 Stok_Cadangan'!AF13="","",'[1]0.4 Stok_Cadangan'!AF13) | Y13: =IF('[1]0.4 Stok_Cadangan'!AI13="","",'[1]0.4 Stok_Cadangan'!AI13) | Z13: =IF('[1]0.4 Stok_Cadangan'!AL13="","",'[1]0.4 Stok_Cadangan'!AL13) | AA13: =IF('[1]0.5 Indikator Keterjangkauan'!P13="","",'[1]0.5 Indikator Keterjangkauan'!P13) | AB13: =IF('[1]0.5 Indikator Keterjangkauan'!T13="","",'[1]0.5 Indikator Keterjangkauan'!T13) | AC13: =IF('[1]0.5 Indikator Keterjangkauan'!X13="","",'[1]0.5 Indikator Keterjangkauan'!X13) | AD13: =IF('[1]0.5 Indikator Keterjangkauan'!AB13="","",'[1]0.5 Indikator Keterjangkauan'!AB13) | AE13: =IF('[1]0.6 Indikator Pemanfaatan'!V13="","",'[1]0.6 Indikator Pemanfaatan'!V13) | AF13: =IF('[1]0.6 Indikator Pemanfaatan'!Z13="","",'[1]0.6 Indikator Pemanfaatan'!Z13) | AG13: =IF('[2]2.1 Data FSVA 2025 & Bobot'!H14="","",'[2]2.1 Data FSVA 2025 & Bobot'!H14) | AH13: =IF('[2]2.1 Data FSVA 2025 & Bobot'!J14="","",'[2]2.1 Data FSVA 2025 & Bobot'!J14) | AI13: =IF('[2]2.1 Data FSVA 2025 & Bobot'!L14="","",'[2]2.1 Data FSVA 2025 & Bobot'!L14) | AJ13: =IF('[2]2.1 Data FSVA 2025 & Bobot'!N14="","",'[2]2.1 Data FSVA 2025 & Bobot'!N14) | AK13: =IF('[2]2.1 Data FSVA 2025 & Bobot'!P14="","",'[2]2.1 Data FSVA 2025 & Bobot'!P14) | AL13: =IF('[2]2.1 Data FSVA 2025 & Bobot'!R14="","",'[2]2.1 Data FSVA 2025 & Bobot'!R14) | AM13: =IF('[2]2.1 Data FSVA 2025 & Bobot'!T14="","",'[2]2.1 Data FSVA 2025 & Bobot'!T14) | AN13: =IF('[2]2.1 Data FSVA 2025 & Bobot'!V14="","",'[2]2.1 Data FSVA 2025 & Bobot'!V14) | AO13: =IF('[2]2.1 Data FSVA 2025 & Bobot'!X14="","",'[2]2.1 Data FSVA 2025 & Bobot'!X14) | AP13: =IF('[2]2.1 Data FSVA 2025 & Bobot'!Z14="","",'[2]2.1 Data FSVA 2025 & Bobot'!Z14) | AQ13: =IF('[2]2.1 Data FSVA 2025 & Bobot'!AB14="","",'[2]2.1 Data FSVA 2025 & Bobot'!AB14) | AR13: =IF('[2]2.1 Data FSVA 2025 & Bobot'!AD14="","",'[2]2.1 Data FSVA 2025 & Bobot'!AD14) | AS13: =IF('[2]2.4 Prioritas Individu'!G14="","",'[2]2.4 Prioritas Individu'!G14) | AT13: =IF('[2]2.4 Prioritas Individu'!H14="","",'[2]2.4 Prioritas Individu'!H14) | AU13: =IF('[2]2.4 Prioritas Individu'!I14="","",'[2]2.4 Prioritas Individu'!I14) | AV13: =IF('[2]2.4 Prioritas Individu'!J14="","",'[2]2.4 Prioritas Individu'!J14) | AW13: =IF('[2]2.4 Prioritas Individu'!K14="","",'[2]2.4 Prioritas Individu'!K14) | AX13: =IF('[2]2.4 Prioritas Individu'!L14="","",'[2]2.4 Prioritas Individu'!L14) | AY13: =IF('[2]2.4 Prioritas Individu'!M14="","",'[2]2.4 Prioritas Individu'!M14) | AZ13: =IF('[2]2.4 Prioritas Individu'!N14="","",'[2]2.4 Prioritas Individu'!N14) | ... BG13: =IF('[2]2.4 Prioritas Individu'!U14="","",'[2]2.4 Prioritas Individu'!U14) -> - | BH13: =IF('[2]2.3 Indeks & Cut off Komposit'!G725="","",'[2]2.3 Indeks & Cut off Komposit'!G725) | BI13: =IF('[2]2.3 Indeks & Cut off Komposit'!H725="","",'[2]2.3 Indeks & Cut off Komposit'!H725) | BJ13: =IF('[2]2.3 Indeks & Cut off Komposit'!I725="","",'[2]2.3 Indeks & Cut off Komposit'!I725) | BK13: =IF('[2]2.3 Indeks & Cut off Komposit'!J725="","",'[2]2.3 Indeks & Cut off Komposit'!J725) | BL13: =IF('[2]2.3 Indeks & Cut off Komposit'!K725="","",'[2]2.3 Indeks & Cut off Komposit'!K725) | BM13: =IF('[2]2.3 Indeks & Cut off Komposit'!L725="","",'[2]2.3 Indeks & Cut off Komposit'!L725) | BN13: =IF('[2]2.3 Indeks & Cut off Komposit'!M725="","",'[2]2.3 Indeks & Cut off Komposit'!M725) | BO13: =IF('[2]2.3 Indeks & Cut off Komposit'!N725="","",'[2]2.3 Indeks & Cut off Komposit'!N725) | ... BW13: =IF('[2]2.3 Indeks & Cut off Komposit'!V725="","",'[2]2.3 Indeks & Cut off Komposit'!V725) -> -
